2023-05-23 16:11:40,437  ERROR       send_post.py  common_solver  OpenCV(4.7.0) :-1: error: (-5:Bad argument) in function 'cvtColor'
> Overload resolution failed:
>  - src is not a numpy array, neither a scalar
>  - Expected Ptr<cv::UMat> for argument 'src'

2023-05-23 16:11:40,688  ERROR       send_post.py  common_solver  OpenCV(4.7.0) :-1: error: (-5:Bad argument) in function 'cvtColor'
> Overload resolution failed:
>  - src is not a numpy array, neither a scalar
>  - Expected Ptr<cv::UMat> for argument 'src'

2023-05-23 16:11:40,980  ERROR       send_post.py  common_solver  OpenCV(4.7.0) :-1: error: (-5:Bad argument) in function 'cvtColor'
> Overload resolution failed:
>  - src is not a numpy array, neither a scalar
>  - Expected Ptr<cv::UMat> for argument 'src'

2023-05-23 16:11:41,059  ERROR       send_post.py  common_solver  OpenCV(4.7.0) :-1: error: (-5:Bad argument) in function 'cvtColor'
> Overload resolution failed:
>  - src is not a numpy array, neither a scalar
>  - Expected Ptr<cv::UMat> for argument 'src'

2023-05-23 16:11:41,260  ERROR       send_post.py  common_solver  OpenCV(4.7.0) :-1: error: (-5:Bad argument) in function 'cvtColor'
> Overload resolution failed:
>  - src is not a numpy array, neither a scalar
>  - Expected Ptr<cv::UMat> for argument 'src'

2023-05-23 16:12:32,223  ERROR       send_post.py  common_solver  OpenCV(4.7.0) :-1: error: (-5:Bad argument) in function 'cvtColor'
> Overload resolution failed:
>  - src is not a numpy array, neither a scalar
>  - Expected Ptr<cv::UMat> for argument 'src'

2023-05-23 16:12:32,471  ERROR       send_post.py  common_solver  OpenCV(4.7.0) :-1: error: (-5:Bad argument) in function 'cvtColor'
> Overload resolution failed:
>  - src is not a numpy array, neither a scalar
>  - Expected Ptr<cv::UMat> for argument 'src'

2023-05-23 16:12:32,745  ERROR       send_post.py  common_solver  OpenCV(4.7.0) :-1: error: (-5:Bad argument) in function 'cvtColor'
> Overload resolution failed:
>  - src is not a numpy array, neither a scalar
>  - Expected Ptr<cv::UMat> for argument 'src'

2023-05-23 16:12:32,807  ERROR       send_post.py  common_solver  OpenCV(4.7.0) :-1: error: (-5:Bad argument) in function 'cvtColor'
> Overload resolution failed:
>  - src is not a numpy array, neither a scalar
>  - Expected Ptr<cv::UMat> for argument 'src'

2023-05-23 16:12:33,008  ERROR       send_post.py  common_solver  OpenCV(4.7.0) :-1: error: (-5:Bad argument) in function 'cvtColor'
> Overload resolution failed:
>  - src is not a numpy array, neither a scalar
>  - Expected Ptr<cv::UMat> for argument 'src'

2023-05-23 16:25:25,657  ERROR       send_post.py  run_rtsp_gpu  frame_192.168.0.18 is not update
2023-05-23 16:25:30,665  ERROR       send_post.py  run_rtsp_gpu  frame_192.168.0.18 is not update
2023-05-23 16:26:29,249  ERROR       send_post.py  run_rtsp_gpu  frame_192.168.0.18 is not update
2023-05-23 16:26:34,257  ERROR       send_post.py  run_rtsp_gpu  frame_192.168.0.18 is not update
2023-05-23 16:27:46,042  ERROR       send_post.py  run_rtsp_gpu  frame_192.168.0.18 is not update
2023-05-23 16:27:51,050  ERROR       send_post.py  run_rtsp_gpu  frame_192.168.0.18 is not update
2023-05-23 16:28:02,210  ERROR       send_post.py  run_rtsp_gpu  frame_192.168.0.18 is not update
2023-05-23 16:28:32,913  ERROR       send_post.py  run_rtsp_gpu  frame_192.168.0.18 is not update
2023-05-23 16:29:30,454  ERROR       send_post.py  run_rtsp_gpu  frame_192.168.0.18 is not update
2023-05-23 16:30:28,887  ERROR       send_post.py  run_rtsp_gpu  frame_192.168.0.18 is not update
2023-05-23 16:30:44,196  ERROR       send_post.py  run_rtsp_gpu  frame_192.168.0.18 is not update
2023-05-23 16:39:59,529  ERROR       send_post.py  run_rtsp_gpu  frame_192.168.0.18 is not update
2023-05-23 16:40:04,536  ERROR       send_post.py  run_rtsp_gpu  frame_192.168.0.18 is not update
2023-05-23 16:40:46,672  ERROR       send_post.py  run_rtsp_gpu  frame_192.168.0.18 is not update
2023-05-23 16:41:13,131  ERROR       send_post.py  run_rtsp_gpu  frame_192.168.0.18 is not update
2023-05-23 16:42:40,377  ERROR       send_post.py  run_rtsp_gpu  frame_192.168.0.18 is not update
2023-05-23 16:49:44,822  ERROR       send_post.py  run_rtsp_gpu  Input must be bytes, bytearray, memoryview, or str: line 1 column 1 (char 0)
2023-05-23 16:49:51,247  ERROR       send_post.py  run_rtsp_gpu  frame_192.168.0.18 is not update
2023-05-23 16:49:56,255  ERROR       send_post.py  run_rtsp_gpu  frame_192.168.0.18 is not update
2023-05-23 16:50:05,130  ERROR       send_post.py  run_rtsp_gpu  frame_192.168.0.18 is not update
2023-05-23 16:51:08,038  ERROR       send_post.py  run_rtsp_gpu  frame_192.168.0.18 is not update
2023-05-24 10:41:07,676  ERROR       send_post.py  run  HTTPConnectionPool(host='0.0.0.0', port=9620): Max retries exceeded with url: /test (Caused by NewConnectionError('<urllib3.connection.HTTPConnection object at 0x7fed378bf550>: Failed to establish a new connection: [Errno 111] Connection refused'))
2023-05-24 17:01:51,435  ERROR       send_post.py  post_report  HTTPConnectionPool(host='localhost', port=8090): Max retries exceeded with url: /api/v1/result (Caused by NewConnectionError('<urllib3.connection.HTTPConnection object at 0x7f2a877e5510>: Failed to establish a new connection: [Errno 111] Connection refused'))
2023-05-24 17:01:51,464  ERROR       send_post.py  post_report  HTTPConnectionPool(host='localhost', port=8090): Max retries exceeded with url: /api/v1/result (Caused by NewConnectionError('<urllib3.connection.HTTPConnection object at 0x7f2a877e6020>: Failed to establish a new connection: [Errno 111] Connection refused'))
2023-05-24 17:01:51,768  ERROR       send_post.py  post_report  HTTPConnectionPool(host='localhost', port=8090): Max retries exceeded with url: /api/v1/result (Caused by NewConnectionError('<urllib3.connection.HTTPConnection object at 0x7f2a877e70d0>: Failed to establish a new connection: [Errno 111] Connection refused'))
2023-05-24 17:01:52,056  ERROR       send_post.py  post_report  HTTPConnectionPool(host='localhost', port=8090): Max retries exceeded with url: /api/v1/result (Caused by NewConnectionError('<urllib3.connection.HTTPConnection object at 0x7f2a877e58a0>: Failed to establish a new connection: [Errno 111] Connection refused'))
2023-05-24 17:01:52,098  ERROR       send_post.py  post_report  HTTPConnectionPool(host='localhost', port=8090): Max retries exceeded with url: /api/v1/result (Caused by NewConnectionError('<urllib3.connection.HTTPConnection object at 0x7f2a877e54e0>: Failed to establish a new connection: [Errno 111] Connection refused'))
2023-05-24 17:01:52,201  ERROR       send_post.py  post_report  HTTPConnectionPool(host='localhost', port=8090): Max retries exceeded with url: /api/v1/result (Caused by NewConnectionError('<urllib3.connection.HTTPConnection object at 0x7f2a877e5c30>: Failed to establish a new connection: [Errno 111] Connection refused'))
2023-05-24 17:01:52,647  ERROR       send_post.py  post_report  HTTPConnectionPool(host='localhost', port=8090): Max retries exceeded with url: /api/v1/result (Caused by NewConnectionError('<urllib3.connection.HTTPConnection object at 0x7f2aa08928c0>: Failed to establish a new connection: [Errno 111] Connection refused'))
2023-05-24 18:50:25,488  ERROR       send_post.py  post_report  HTTPConnectionPool(host='localhost', port=8090): Max retries exceeded with url: /api/v1/result (Caused by NewConnectionError('<urllib3.connection.HTTPConnection object at 0x7f56e5de00d0>: Failed to establish a new connection: [Errno 111] Connection refused'))
2023-05-24 18:50:25,584  ERROR       send_post.py  post_report  HTTPConnectionPool(host='localhost', port=8090): Max retries exceeded with url: /api/v1/result (Caused by NewConnectionError('<urllib3.connection.HTTPConnection object at 0x7f56e5de0ac0>: Failed to establish a new connection: [Errno 111] Connection refused'))
2023-05-24 18:50:25,634  ERROR       send_post.py  post_report  HTTPConnectionPool(host='localhost', port=8090): Max retries exceeded with url: /api/v1/result (Caused by NewConnectionError('<urllib3.connection.HTTPConnection object at 0x7f56e5de2230>: Failed to establish a new connection: [Errno 111] Connection refused'))
2023-05-24 18:50:25,674  ERROR       send_post.py  post_report  HTTPConnectionPool(host='localhost', port=8090): Max retries exceeded with url: /api/v1/result (Caused by NewConnectionError('<urllib3.connection.HTTPConnection object at 0x7f56e5de0a60>: Failed to establish a new connection: [Errno 111] Connection refused'))
2023-05-24 18:50:25,717  ERROR       send_post.py  post_report  HTTPConnectionPool(host='localhost', port=8090): Max retries exceeded with url: /api/v1/result (Caused by NewConnectionError('<urllib3.connection.HTTPConnection object at 0x7f56e5de2d70>: Failed to establish a new connection: [Errno 111] Connection refused'))
2023-05-24 18:50:25,746  ERROR       send_post.py  post_report  HTTPConnectionPool(host='localhost', port=8090): Max retries exceeded with url: /api/v1/result (Caused by NewConnectionError('<urllib3.connection.HTTPConnection object at 0x7f56e5de36a0>: Failed to establish a new connection: [Errno 111] Connection refused'))
2023-05-24 18:50:25,789  ERROR       send_post.py  post_report  HTTPConnectionPool(host='localhost', port=8090): Max retries exceeded with url: /api/v1/result (Caused by NewConnectionError('<urllib3.connection.HTTPConnection object at 0x7f56e5de1420>: Failed to establish a new connection: [Errno 111] Connection refused'))
2023-05-24 18:50:25,822  ERROR       send_post.py  post_report  HTTPConnectionPool(host='localhost', port=8090): Max retries exceeded with url: /api/v1/result (Caused by NewConnectionError('<urllib3.connection.HTTPConnection object at 0x7f56e5de3af0>: Failed to establish a new connection: [Errno 111] Connection refused'))
2023-05-24 18:50:25,949  ERROR       send_post.py  post_report  HTTPConnectionPool(host='localhost', port=8090): Max retries exceeded with url: /api/v1/result (Caused by NewConnectionError('<urllib3.connection.HTTPConnection object at 0x7f56e5de21d0>: Failed to establish a new connection: [Errno 111] Connection refused'))
2023-05-24 18:50:25,968  ERROR       send_post.py  post_report  HTTPConnectionPool(host='localhost', port=8090): Max retries exceeded with url: /api/v1/result (Caused by NewConnectionError('<urllib3.connection.HTTPConnection object at 0x7f56e5de3fd0>: Failed to establish a new connection: [Errno 111] Connection refused'))
2023-05-24 18:50:26,021  ERROR       send_post.py  post_report  HTTPConnectionPool(host='localhost', port=8090): Max retries exceeded with url: /api/v1/result (Caused by NewConnectionError('<urllib3.connection.HTTPConnection object at 0x7f56e5de0c10>: Failed to establish a new connection: [Errno 111] Connection refused'))
2023-05-24 18:50:26,065  ERROR       send_post.py  post_report  HTTPConnectionPool(host='localhost', port=8090): Max retries exceeded with url: /api/v1/result (Caused by NewConnectionError('<urllib3.connection.HTTPConnection object at 0x7f56e5de08e0>: Failed to establish a new connection: [Errno 111] Connection refused'))
2023-05-24 18:50:26,098  ERROR       send_post.py  post_report  HTTPConnectionPool(host='localhost', port=8090): Max retries exceeded with url: /api/v1/result (Caused by NewConnectionError('<urllib3.connection.HTTPConnection object at 0x7f56e5de2aa0>: Failed to establish a new connection: [Errno 111] Connection refused'))
2023-05-24 18:50:26,127  ERROR       send_post.py  post_report  HTTPConnectionPool(host='localhost', port=8090): Max retries exceeded with url: /api/v1/result (Caused by NewConnectionError('<urllib3.connection.HTTPConnection object at 0x7f56e5de1db0>: Failed to establish a new connection: [Errno 111] Connection refused'))
2023-05-24 18:50:26,154  ERROR       send_post.py  post_report  HTTPConnectionPool(host='localhost', port=8090): Max retries exceeded with url: /api/v1/result (Caused by NewConnectionError('<urllib3.connection.HTTPConnection object at 0x7f56e5de3310>: Failed to establish a new connection: [Errno 111] Connection refused'))
2023-05-24 18:50:26,206  ERROR       send_post.py  post_report  HTTPConnectionPool(host='localhost', port=8090): Max retries exceeded with url: /api/v1/result (Caused by NewConnectionError('<urllib3.connection.HTTPConnection object at 0x7f56e5de1660>: Failed to establish a new connection: [Errno 111] Connection refused'))
2023-05-24 18:50:26,232  ERROR       send_post.py  post_report  HTTPConnectionPool(host='localhost', port=8090): Max retries exceeded with url: /api/v1/result (Caused by NewConnectionError('<urllib3.connection.HTTPConnection object at 0x7f56e5de1360>: Failed to establish a new connection: [Errno 111] Connection refused'))
2023-05-24 18:50:26,281  ERROR       send_post.py  post_report  HTTPConnectionPool(host='localhost', port=8090): Max retries exceeded with url: /api/v1/result (Caused by NewConnectionError('<urllib3.connection.HTTPConnection object at 0x7f56e5de1de0>: Failed to establish a new connection: [Errno 111] Connection refused'))
2023-05-24 18:50:26,331  ERROR       send_post.py  post_report  HTTPConnectionPool(host='localhost', port=8090): Max retries exceeded with url: /api/v1/result (Caused by NewConnectionError('<urllib3.connection.HTTPConnection object at 0x7f56e5de2470>: Failed to establish a new connection: [Errno 111] Connection refused'))
2023-05-24 18:50:26,344  ERROR       send_post.py  post_report  HTTPConnectionPool(host='localhost', port=8090): Max retries exceeded with url: /api/v1/result (Caused by NewConnectionError('<urllib3.connection.HTTPConnection object at 0x7f56e5de2cb0>: Failed to establish a new connection: [Errno 111] Connection refused'))
2023-05-24 18:50:26,387  ERROR       send_post.py  post_report  HTTPConnectionPool(host='localhost', port=8090): Max retries exceeded with url: /api/v1/result (Caused by NewConnectionError('<urllib3.connection.HTTPConnection object at 0x7f56e5de24d0>: Failed to establish a new connection: [Errno 111] Connection refused'))
2023-05-24 18:50:26,414  ERROR       send_post.py  post_report  HTTPConnectionPool(host='localhost', port=8090): Max retries exceeded with url: /api/v1/result (Caused by NewConnectionError('<urllib3.connection.HTTPConnection object at 0x7f56e5de17b0>: Failed to establish a new connection: [Errno 111] Connection refused'))
2023-05-24 18:50:26,441  ERROR       send_post.py  post_report  HTTPConnectionPool(host='localhost', port=8090): Max retries exceeded with url: /api/v1/result (Caused by NewConnectionError('<urllib3.connection.HTTPConnection object at 0x7f56e5de3010>: Failed to establish a new connection: [Errno 111] Connection refused'))
2023-05-24 18:50:26,497  ERROR       send_post.py  post_report  HTTPConnectionPool(host='localhost', port=8090): Max retries exceeded with url: /api/v1/result (Caused by NewConnectionError('<urllib3.connection.HTTPConnection object at 0x7f56e5de3a00>: Failed to establish a new connection: [Errno 111] Connection refused'))
2023-05-24 18:50:26,546  ERROR       send_post.py  post_report  HTTPConnectionPool(host='localhost', port=8090): Max retries exceeded with url: /api/v1/result (Caused by NewConnectionError('<urllib3.connection.HTTPConnection object at 0x7f56e5de26b0>: Failed to establish a new connection: [Errno 111] Connection refused'))
2023-05-24 18:50:26,664  ERROR       send_post.py  post_report  HTTPConnectionPool(host='localhost', port=8090): Max retries exceeded with url: /api/v1/result (Caused by NewConnectionError('<urllib3.connection.HTTPConnection object at 0x7f56fee928c0>: Failed to establish a new connection: [Errno 111] Connection refused'))
