2023-06-05 18:31:25,212  ERROR       send_post.py  run  HTTPConnectionPool(host='0.0.0.0', port=9624): Max retries exceeded with url: /test (Caused by NewConnectionError('<urllib3.connection.HTTPConnection object at 0x7fcc491dfaf0>: Failed to establish a new connection: [Errno 111] Connection refused'))
2023-06-05 18:31:36,456  ERROR       send_post.py  main  scene is not correct
2023-06-06 10:53:54,332  ERROR       send_post.py  run_rtsp_gpu  frame_192.168.0.20 is not update
2023-06-06 10:53:59,338  ERROR       send_post.py  run_rtsp_gpu  frame_192.168.0.20 is not update
2023-06-06 10:54:04,344  ERROR       send_post.py  run_rtsp_gpu  frame_192.168.0.20 is not update
2023-06-06 10:54:09,351  ERROR       send_post.py  run_rtsp_gpu  frame_192.168.0.20 is not update
2023-06-06 10:54:14,354  ERROR       send_post.py  run_rtsp_gpu  frame_192.168.0.20 is not update
2023-06-09 18:48:21,968  ERROR       send_post.py  post_report  HTTPConnectionPool(host='localhost', port=8090): Max retries exceeded with url: /api/v1/result (Caused by NewConnectionError('<urllib3.connection.HTTPConnection object at 0x7f568fb742e0>: Failed to establish a new connection: [Errno 111] Connection refused'))
2023-06-09 18:49:36,859  ERROR       send_post.py  post_report  HTTPConnectionPool(host='localhost', port=8090): Max retries exceeded with url: /api/v1/result (Caused by NewConnectionError('<urllib3.connection.HTTPConnection object at 0x7f622d57a3d0>: Failed to establish a new connection: [Errno 111] Connection refused'))
2023-06-09 18:50:46,113  ERROR       send_post.py  post_report  HTTPConnectionPool(host='localhost', port=8090): Max retries exceeded with url: /api/v1/result (Caused by NewConnectionError('<urllib3.connection.HTTPConnection object at 0x7fef9633c3d0>: Failed to establish a new connection: [Errno 111] Connection refused'))
2023-06-12 15:13:41,360  ERROR       send_post.py  post_report  HTTPConnectionPool(host='localhost', port=8090): Max retries exceeded with url: /api/v1/result (Caused by NewConnectionError('<urllib3.connection.HTTPConnection object at 0x7fd500573190>: Failed to establish a new connection: [Errno 111] Connection refused'))
2023-06-12 15:13:41,386  ERROR       send_post.py  post_report  HTTPConnectionPool(host='localhost', port=8090): Max retries exceeded with url: /api/v1/result (Caused by NewConnectionError('<urllib3.connection.HTTPConnection object at 0x7fd500573bb0>: Failed to establish a new connection: [Errno 111] Connection refused'))
2023-06-12 15:13:41,415  ERROR       send_post.py  post_report  HTTPConnectionPool(host='localhost', port=8090): Max retries exceeded with url: /api/v1/result (Caused by NewConnectionError('<urllib3.connection.HTTPConnection object at 0x7fd500573100>: Failed to establish a new connection: [Errno 111] Connection refused'))
2023-06-12 15:13:41,442  ERROR       send_post.py  post_report  HTTPConnectionPool(host='localhost', port=8090): Max retries exceeded with url: /api/v1/result (Caused by NewConnectionError('<urllib3.connection.HTTPConnection object at 0x7fd5000f9610>: Failed to establish a new connection: [Errno 111] Connection refused'))
2023-06-12 15:13:41,468  ERROR       send_post.py  post_report  HTTPConnectionPool(host='localhost', port=8090): Max retries exceeded with url: /api/v1/result (Caused by NewConnectionError('<urllib3.connection.HTTPConnection object at 0x7fd5001040a0>: Failed to establish a new connection: [Errno 111] Connection refused'))
2023-06-12 15:13:41,495  ERROR       send_post.py  post_report  HTTPConnectionPool(host='localhost', port=8090): Max retries exceeded with url: /api/v1/result (Caused by NewConnectionError('<urllib3.connection.HTTPConnection object at 0x7fd500104a90>: Failed to establish a new connection: [Errno 111] Connection refused'))
2023-06-12 15:13:41,522  ERROR       send_post.py  post_report  HTTPConnectionPool(host='localhost', port=8090): Max retries exceeded with url: /api/v1/result (Caused by NewConnectionError('<urllib3.connection.HTTPConnection object at 0x7fd5000f91c0>: Failed to establish a new connection: [Errno 111] Connection refused'))
2023-06-12 15:13:41,549  ERROR       send_post.py  post_report  HTTPConnectionPool(host='localhost', port=8090): Max retries exceeded with url: /api/v1/result (Caused by NewConnectionError('<urllib3.connection.HTTPConnection object at 0x7fd50053ddf0>: Failed to establish a new connection: [Errno 111] Connection refused'))
2023-06-12 15:13:41,577  ERROR       send_post.py  post_report  HTTPConnectionPool(host='localhost', port=8090): Max retries exceeded with url: /api/v1/result (Caused by NewConnectionError('<urllib3.connection.HTTPConnection object at 0x7fd500573b20>: Failed to establish a new connection: [Errno 111] Connection refused'))
2023-06-12 15:13:41,616  ERROR       send_post.py  post_report  HTTPConnectionPool(host='localhost', port=8090): Max retries exceeded with url: /api/v1/result (Caused by NewConnectionError('<urllib3.connection.HTTPConnection object at 0x7fd500104c70>: Failed to establish a new connection: [Errno 111] Connection refused'))
2023-06-12 15:13:41,645  ERROR       send_post.py  post_report  HTTPConnectionPool(host='localhost', port=8090): Max retries exceeded with url: /api/v1/result (Caused by NewConnectionError('<urllib3.connection.HTTPConnection object at 0x7fd500573f40>: Failed to establish a new connection: [Errno 111] Connection refused'))
2023-06-12 15:13:41,672  ERROR       send_post.py  post_report  HTTPConnectionPool(host='localhost', port=8090): Max retries exceeded with url: /api/v1/result (Caused by NewConnectionError('<urllib3.connection.HTTPConnection object at 0x7fd5009638b0>: Failed to establish a new connection: [Errno 111] Connection refused'))
2023-06-12 15:13:41,699  ERROR       send_post.py  post_report  HTTPConnectionPool(host='localhost', port=8090): Max retries exceeded with url: /api/v1/result (Caused by NewConnectionError('<urllib3.connection.HTTPConnection object at 0x7fd5000f97f0>: Failed to establish a new connection: [Errno 111] Connection refused'))
2023-06-12 15:13:41,728  ERROR       send_post.py  post_report  HTTPConnectionPool(host='localhost', port=8090): Max retries exceeded with url: /api/v1/result (Caused by NewConnectionError('<urllib3.connection.HTTPConnection object at 0x7fd5001134c0>: Failed to establish a new connection: [Errno 111] Connection refused'))
2023-06-12 15:13:41,756  ERROR       send_post.py  post_report  HTTPConnectionPool(host='localhost', port=8090): Max retries exceeded with url: /api/v1/result (Caused by NewConnectionError('<urllib3.connection.HTTPConnection object at 0x7fd5000f96d0>: Failed to establish a new connection: [Errno 111] Connection refused'))
2023-06-12 15:14:57,917  ERROR       send_post.py  post_report  HTTPConnectionPool(host='localhost', port=8090): Max retries exceeded with url: /api/v1/result (Caused by NewConnectionError('<urllib3.connection.HTTPConnection object at 0x7f4111372190>: Failed to establish a new connection: [Errno 111] Connection refused'))
2023-06-12 15:14:57,944  ERROR       send_post.py  post_report  HTTPConnectionPool(host='localhost', port=8090): Max retries exceeded with url: /api/v1/result (Caused by NewConnectionError('<urllib3.connection.HTTPConnection object at 0x7f4111372bb0>: Failed to establish a new connection: [Errno 111] Connection refused'))
2023-06-12 15:14:57,971  ERROR       send_post.py  post_report  HTTPConnectionPool(host='localhost', port=8090): Max retries exceeded with url: /api/v1/result (Caused by NewConnectionError('<urllib3.connection.HTTPConnection object at 0x7f4111372100>: Failed to establish a new connection: [Errno 111] Connection refused'))
2023-06-12 15:14:57,999  ERROR       send_post.py  post_report  HTTPConnectionPool(host='localhost', port=8090): Max retries exceeded with url: /api/v1/result (Caused by NewConnectionError('<urllib3.connection.HTTPConnection object at 0x7f4110efa610>: Failed to establish a new connection: [Errno 111] Connection refused'))
2023-06-12 15:14:58,026  ERROR       send_post.py  post_report  HTTPConnectionPool(host='localhost', port=8090): Max retries exceeded with url: /api/v1/result (Caused by NewConnectionError('<urllib3.connection.HTTPConnection object at 0x7f4110f040a0>: Failed to establish a new connection: [Errno 111] Connection refused'))
2023-06-12 15:14:58,053  ERROR       send_post.py  post_report  HTTPConnectionPool(host='localhost', port=8090): Max retries exceeded with url: /api/v1/result (Caused by NewConnectionError('<urllib3.connection.HTTPConnection object at 0x7f4110f04a90>: Failed to establish a new connection: [Errno 111] Connection refused'))
2023-06-12 15:14:58,080  ERROR       send_post.py  post_report  HTTPConnectionPool(host='localhost', port=8090): Max retries exceeded with url: /api/v1/result (Caused by NewConnectionError('<urllib3.connection.HTTPConnection object at 0x7f4110efa3d0>: Failed to establish a new connection: [Errno 111] Connection refused'))
2023-06-12 15:14:58,110  ERROR       send_post.py  post_report  HTTPConnectionPool(host='localhost', port=8090): Max retries exceeded with url: /api/v1/result (Caused by NewConnectionError('<urllib3.connection.HTTPConnection object at 0x7f411133c610>: Failed to establish a new connection: [Errno 111] Connection refused'))
2023-06-12 15:14:58,136  ERROR       send_post.py  post_report  HTTPConnectionPool(host='localhost', port=8090): Max retries exceeded with url: /api/v1/result (Caused by NewConnectionError('<urllib3.connection.HTTPConnection object at 0x7f4111372b20>: Failed to establish a new connection: [Errno 111] Connection refused'))
2023-06-12 15:14:58,163  ERROR       send_post.py  post_report  HTTPConnectionPool(host='localhost', port=8090): Max retries exceeded with url: /api/v1/result (Caused by NewConnectionError('<urllib3.connection.HTTPConnection object at 0x7f4110f04c70>: Failed to establish a new connection: [Errno 111] Connection refused'))
2023-06-12 15:14:58,190  ERROR       send_post.py  post_report  HTTPConnectionPool(host='localhost', port=8090): Max retries exceeded with url: /api/v1/result (Caused by NewConnectionError('<urllib3.connection.HTTPConnection object at 0x7f4111372f40>: Failed to establish a new connection: [Errno 111] Connection refused'))
2023-06-12 15:14:58,220  ERROR       send_post.py  post_report  HTTPConnectionPool(host='localhost', port=8090): Max retries exceeded with url: /api/v1/result (Caused by NewConnectionError('<urllib3.connection.HTTPConnection object at 0x7f41117638b0>: Failed to establish a new connection: [Errno 111] Connection refused'))
2023-06-12 15:15:45,673  ERROR       send_post.py  post_report  HTTPConnectionPool(host='localhost', port=8090): Max retries exceeded with url: /api/v1/result (Caused by NewConnectionError('<urllib3.connection.HTTPConnection object at 0x7f2591972190>: Failed to establish a new connection: [Errno 111] Connection refused'))
2023-06-12 15:15:45,701  ERROR       send_post.py  post_report  HTTPConnectionPool(host='localhost', port=8090): Max retries exceeded with url: /api/v1/result (Caused by NewConnectionError('<urllib3.connection.HTTPConnection object at 0x7f2591972bb0>: Failed to establish a new connection: [Errno 111] Connection refused'))
2023-06-12 15:15:45,735  ERROR       send_post.py  post_report  HTTPConnectionPool(host='localhost', port=8090): Max retries exceeded with url: /api/v1/result (Caused by NewConnectionError('<urllib3.connection.HTTPConnection object at 0x7f2591972100>: Failed to establish a new connection: [Errno 111] Connection refused'))
2023-06-12 15:15:45,770  ERROR       send_post.py  post_report  HTTPConnectionPool(host='localhost', port=8090): Max retries exceeded with url: /api/v1/result (Caused by NewConnectionError('<urllib3.connection.HTTPConnection object at 0x7f25914fa610>: Failed to establish a new connection: [Errno 111] Connection refused'))
2023-06-12 15:15:45,802  ERROR       send_post.py  post_report  HTTPConnectionPool(host='localhost', port=8090): Max retries exceeded with url: /api/v1/result (Caused by NewConnectionError('<urllib3.connection.HTTPConnection object at 0x7f259150a0a0>: Failed to establish a new connection: [Errno 111] Connection refused'))
2023-06-12 15:15:45,835  ERROR       send_post.py  post_report  HTTPConnectionPool(host='localhost', port=8090): Max retries exceeded with url: /api/v1/result (Caused by NewConnectionError('<urllib3.connection.HTTPConnection object at 0x7f259150aa90>: Failed to establish a new connection: [Errno 111] Connection refused'))
2023-06-12 15:15:45,868  ERROR       send_post.py  post_report  HTTPConnectionPool(host='localhost', port=8090): Max retries exceeded with url: /api/v1/result (Caused by NewConnectionError('<urllib3.connection.HTTPConnection object at 0x7f25914fa400>: Failed to establish a new connection: [Errno 111] Connection refused'))
2023-06-12 15:15:45,897  ERROR       send_post.py  post_report  HTTPConnectionPool(host='localhost', port=8090): Max retries exceeded with url: /api/v1/result (Caused by NewConnectionError('<urllib3.connection.HTTPConnection object at 0x7f259193d610>: Failed to establish a new connection: [Errno 111] Connection refused'))
2023-06-12 15:15:45,931  ERROR       send_post.py  post_report  HTTPConnectionPool(host='localhost', port=8090): Max retries exceeded with url: /api/v1/result (Caused by NewConnectionError('<urllib3.connection.HTTPConnection object at 0x7f2591972b20>: Failed to establish a new connection: [Errno 111] Connection refused'))
2023-06-12 15:15:45,967  ERROR       send_post.py  post_report  HTTPConnectionPool(host='localhost', port=8090): Max retries exceeded with url: /api/v1/result (Caused by NewConnectionError('<urllib3.connection.HTTPConnection object at 0x7f259150ac70>: Failed to establish a new connection: [Errno 111] Connection refused'))
2023-06-12 15:15:46,002  ERROR       send_post.py  post_report  HTTPConnectionPool(host='localhost', port=8090): Max retries exceeded with url: /api/v1/result (Caused by NewConnectionError('<urllib3.connection.HTTPConnection object at 0x7f2591972f40>: Failed to establish a new connection: [Errno 111] Connection refused'))
2023-06-12 15:15:46,056  ERROR       send_post.py  post_report  HTTPConnectionPool(host='localhost', port=8090): Max retries exceeded with url: /api/v1/result (Caused by NewConnectionError('<urllib3.connection.HTTPConnection object at 0x7f2591d64b20>: Failed to establish a new connection: [Errno 111] Connection refused'))
2023-06-12 15:15:46,084  ERROR       send_post.py  post_report  HTTPConnectionPool(host='localhost', port=8090): Max retries exceeded with url: /api/v1/result (Caused by NewConnectionError('<urllib3.connection.HTTPConnection object at 0x7f25914fa7f0>: Failed to establish a new connection: [Errno 111] Connection refused'))
2023-06-12 15:15:46,114  ERROR       send_post.py  post_report  HTTPConnectionPool(host='localhost', port=8090): Max retries exceeded with url: /api/v1/result (Caused by NewConnectionError('<urllib3.connection.HTTPConnection object at 0x7f25915124c0>: Failed to establish a new connection: [Errno 111] Connection refused'))
2023-06-12 15:16:24,785  ERROR       send_post.py  post_report  HTTPConnectionPool(host='localhost', port=8090): Max retries exceeded with url: /api/v1/result (Caused by NewConnectionError('<urllib3.connection.HTTPConnection object at 0x7f7143d72190>: Failed to establish a new connection: [Errno 111] Connection refused'))
2023-06-12 15:16:24,813  ERROR       send_post.py  post_report  HTTPConnectionPool(host='localhost', port=8090): Max retries exceeded with url: /api/v1/result (Caused by NewConnectionError('<urllib3.connection.HTTPConnection object at 0x7f7143d72bb0>: Failed to establish a new connection: [Errno 111] Connection refused'))
2023-06-12 15:16:24,850  ERROR       send_post.py  post_report  HTTPConnectionPool(host='localhost', port=8090): Max retries exceeded with url: /api/v1/result (Caused by NewConnectionError('<urllib3.connection.HTTPConnection object at 0x7f7143d72100>: Failed to establish a new connection: [Errno 111] Connection refused'))
2023-06-12 15:16:24,886  ERROR       send_post.py  post_report  HTTPConnectionPool(host='localhost', port=8090): Max retries exceeded with url: /api/v1/result (Caused by NewConnectionError('<urllib3.connection.HTTPConnection object at 0x7f71438f9610>: Failed to establish a new connection: [Errno 111] Connection refused'))
2023-06-12 15:16:24,913  ERROR       send_post.py  post_report  HTTPConnectionPool(host='localhost', port=8090): Max retries exceeded with url: /api/v1/result (Caused by NewConnectionError('<urllib3.connection.HTTPConnection object at 0x7f71439040a0>: Failed to establish a new connection: [Errno 111] Connection refused'))
2023-06-12 15:16:24,940  ERROR       send_post.py  post_report  HTTPConnectionPool(host='localhost', port=8090): Max retries exceeded with url: /api/v1/result (Caused by NewConnectionError('<urllib3.connection.HTTPConnection object at 0x7f7143904a90>: Failed to establish a new connection: [Errno 111] Connection refused'))
2023-06-12 15:16:24,976  ERROR       send_post.py  post_report  HTTPConnectionPool(host='localhost', port=8090): Max retries exceeded with url: /api/v1/result (Caused by NewConnectionError('<urllib3.connection.HTTPConnection object at 0x7f71438f9400>: Failed to establish a new connection: [Errno 111] Connection refused'))
2023-07-18 14:54:40,667  ERROR       send_post.py  post_report  HTTPConnectionPool(host='localhost', port=8090): Max retries exceeded with url: /api/v1/result (Caused by NewConnectionError('<urllib3.connection.HTTPConnection object at 0x7fec4a5489a0>: Failed to establish a new connection: [Errno 111] Connection refused'))
2023-07-18 14:54:40,692  ERROR       send_post.py  post_report  HTTPConnectionPool(host='localhost', port=8090): Max retries exceeded with url: /api/v1/result (Caused by NewConnectionError('<urllib3.connection.HTTPConnection object at 0x7fec4a13d460>: Failed to establish a new connection: [Errno 111] Connection refused'))
2023-07-18 14:54:40,722  ERROR       send_post.py  post_report  HTTPConnectionPool(host='localhost', port=8090): Max retries exceeded with url: /api/v1/result (Caused by NewConnectionError('<urllib3.connection.HTTPConnection object at 0x7fec4a13d520>: Failed to establish a new connection: [Errno 111] Connection refused'))
2023-07-18 14:54:40,751  ERROR       send_post.py  post_report  HTTPConnectionPool(host='localhost', port=8090): Max retries exceeded with url: /api/v1/result (Caused by NewConnectionError('<urllib3.connection.HTTPConnection object at 0x7fec4a13de80>: Failed to establish a new connection: [Errno 111] Connection refused'))
2023-07-18 14:54:40,785  ERROR       send_post.py  post_report  HTTPConnectionPool(host='localhost', port=8090): Max retries exceeded with url: /api/v1/result (Caused by NewConnectionError('<urllib3.connection.HTTPConnection object at 0x7fec4a1438e0>: Failed to establish a new connection: [Errno 111] Connection refused'))
2023-07-18 14:54:40,816  ERROR       send_post.py  post_report  HTTPConnectionPool(host='localhost', port=8090): Max retries exceeded with url: /api/v1/result (Caused by NewConnectionError('<urllib3.connection.HTTPConnection object at 0x7fec4a159340>: Failed to establish a new connection: [Errno 111] Connection refused'))
2023-07-18 14:54:40,844  ERROR       send_post.py  post_report  HTTPConnectionPool(host='localhost', port=8090): Max retries exceeded with url: /api/v1/result (Caused by NewConnectionError('<urllib3.connection.HTTPConnection object at 0x7fec4a9378e0>: Failed to establish a new connection: [Errno 111] Connection refused'))
2023-07-18 14:54:40,876  ERROR       send_post.py  post_report  HTTPConnectionPool(host='localhost', port=8090): Max retries exceeded with url: /api/v1/result (Caused by NewConnectionError('<urllib3.connection.HTTPConnection object at 0x7fec4a548d30>: Failed to establish a new connection: [Errno 111] Connection refused'))
2023-07-18 14:54:40,904  ERROR       send_post.py  post_report  HTTPConnectionPool(host='localhost', port=8090): Max retries exceeded with url: /api/v1/result (Caused by NewConnectionError('<urllib3.connection.HTTPConnection object at 0x7fec4a13d8e0>: Failed to establish a new connection: [Errno 111] Connection refused'))
2023-07-18 14:54:40,932  ERROR       send_post.py  post_report  HTTPConnectionPool(host='localhost', port=8090): Max retries exceeded with url: /api/v1/result (Caused by NewConnectionError('<urllib3.connection.HTTPConnection object at 0x7fec4a159400>: Failed to establish a new connection: [Errno 111] Connection refused'))
2023-07-18 14:54:40,959  ERROR       send_post.py  post_report  HTTPConnectionPool(host='localhost', port=8090): Max retries exceeded with url: /api/v1/result (Caused by NewConnectionError('<urllib3.connection.HTTPConnection object at 0x7fec4a13d8b0>: Failed to establish a new connection: [Errno 111] Connection refused'))
2023-07-18 14:54:40,993  ERROR       send_post.py  post_report  HTTPConnectionPool(host='localhost', port=8090): Max retries exceeded with url: /api/v1/result (Caused by NewConnectionError('<urllib3.connection.HTTPConnection object at 0x7fec4a548790>: Failed to establish a new connection: [Errno 111] Connection refused'))
2023-07-18 14:57:52,583  ERROR       send_post.py  post_report  HTTPConnectionPool(host='localhost', port=8090): Max retries exceeded with url: /api/v1/result (Caused by NewConnectionError('<urllib3.connection.HTTPConnection object at 0x7f2da21089a0>: Failed to establish a new connection: [Errno 111] Connection refused'))
2023-07-18 14:57:52,703  ERROR       send_post.py  post_report  HTTPConnectionPool(host='localhost', port=8090): Max retries exceeded with url: /api/v1/result (Caused by NewConnectionError('<urllib3.connection.HTTPConnection object at 0x7f2da1d3d580>: Failed to establish a new connection: [Errno 111] Connection refused'))
2023-07-18 14:57:52,721  ERROR       send_post.py  post_report  HTTPConnectionPool(host='localhost', port=8090): Max retries exceeded with url: /api/v1/result (Caused by NewConnectionError('<urllib3.connection.HTTPConnection object at 0x7f2da1d3d130>: Failed to establish a new connection: [Errno 111] Connection refused'))
2023-07-18 14:57:52,739  ERROR       send_post.py  post_report  HTTPConnectionPool(host='localhost', port=8090): Max retries exceeded with url: /api/v1/result (Caused by NewConnectionError('<urllib3.connection.HTTPConnection object at 0x7f2da1d3dfa0>: Failed to establish a new connection: [Errno 111] Connection refused'))
2023-07-18 14:57:52,756  ERROR       send_post.py  post_report  HTTPConnectionPool(host='localhost', port=8090): Max retries exceeded with url: /api/v1/result (Caused by NewConnectionError('<urllib3.connection.HTTPConnection object at 0x7f2da1d488e0>: Failed to establish a new connection: [Errno 111] Connection refused'))
2023-07-18 14:57:52,773  ERROR       send_post.py  post_report  HTTPConnectionPool(host='localhost', port=8090): Max retries exceeded with url: /api/v1/result (Caused by NewConnectionError('<urllib3.connection.HTTPConnection object at 0x7f2da1d53370>: Failed to establish a new connection: [Errno 111] Connection refused'))
2023-07-18 14:57:52,788  ERROR       send_post.py  post_report  HTTPConnectionPool(host='localhost', port=8090): Max retries exceeded with url: /api/v1/result (Caused by NewConnectionError('<urllib3.connection.HTTPConnection object at 0x7f2da1d3dd90>: Failed to establish a new connection: [Errno 111] Connection refused'))
2023-07-18 14:57:52,806  ERROR       send_post.py  post_report  HTTPConnectionPool(host='localhost', port=8090): Max retries exceeded with url: /api/v1/result (Caused by NewConnectionError('<urllib3.connection.HTTPConnection object at 0x7f2da2173070>: Failed to establish a new connection: [Errno 111] Connection refused'))
2023-07-18 14:57:52,822  ERROR       send_post.py  post_report  HTTPConnectionPool(host='localhost', port=8090): Max retries exceeded with url: /api/v1/result (Caused by NewConnectionError('<urllib3.connection.HTTPConnection object at 0x7f2da1d53190>: Failed to establish a new connection: [Errno 111] Connection refused'))
2023-07-18 14:57:52,840  ERROR       send_post.py  post_report  HTTPConnectionPool(host='localhost', port=8090): Max retries exceeded with url: /api/v1/result (Caused by NewConnectionError('<urllib3.connection.HTTPConnection object at 0x7f2da1d53e80>: Failed to establish a new connection: [Errno 111] Connection refused'))
2023-07-18 14:57:52,856  ERROR       send_post.py  post_report  HTTPConnectionPool(host='localhost', port=8090): Max retries exceeded with url: /api/v1/result (Caused by NewConnectionError('<urllib3.connection.HTTPConnection object at 0x7f2da1d536a0>: Failed to establish a new connection: [Errno 111] Connection refused'))
2023-07-18 14:57:52,874  ERROR       send_post.py  post_report  HTTPConnectionPool(host='localhost', port=8090): Max retries exceeded with url: /api/v1/result (Caused by NewConnectionError('<urllib3.connection.HTTPConnection object at 0x7f2da2173340>: Failed to establish a new connection: [Errno 111] Connection refused'))
2023-07-26 09:51:10,193  ERROR       send_post.py  post_report  HTTPConnectionPool(host='localhost', port=8090): Max retries exceeded with url: /api/v1/result (Caused by NewConnectionError('<urllib3.connection.HTTPConnection object at 0x7f3fe77499a0>: Failed to establish a new connection: [Errno 111] Connection refused'))
2023-07-26 09:51:10,240  ERROR       send_post.py  post_report  HTTPConnectionPool(host='localhost', port=8090): Max retries exceeded with url: /api/v1/result (Caused by NewConnectionError('<urllib3.connection.HTTPConnection object at 0x7f3fe7703460>: Failed to establish a new connection: [Errno 111] Connection refused'))
2023-07-26 09:51:10,285  ERROR       send_post.py  post_report  HTTPConnectionPool(host='localhost', port=8090): Max retries exceeded with url: /api/v1/result (Caused by NewConnectionError('<urllib3.connection.HTTPConnection object at 0x7f3fe7703340>: Failed to establish a new connection: [Errno 111] Connection refused'))
2023-07-26 09:51:10,335  ERROR       send_post.py  post_report  HTTPConnectionPool(host='localhost', port=8090): Max retries exceeded with url: /api/v1/result (Caused by NewConnectionError('<urllib3.connection.HTTPConnection object at 0x7f3fe7703fa0>: Failed to establish a new connection: [Errno 111] Connection refused'))
2023-07-26 09:51:10,373  ERROR       send_post.py  post_report  HTTPConnectionPool(host='localhost', port=8090): Max retries exceeded with url: /api/v1/result (Caused by NewConnectionError('<urllib3.connection.HTTPConnection object at 0x7f3fe770ba00>: Failed to establish a new connection: [Errno 111] Connection refused'))
2023-07-26 09:51:10,418  ERROR       send_post.py  post_report  HTTPConnectionPool(host='localhost', port=8090): Max retries exceeded with url: /api/v1/result (Caused by NewConnectionError('<urllib3.connection.HTTPConnection object at 0x7f3fe7719370>: Failed to establish a new connection: [Errno 111] Connection refused'))
2023-07-26 09:51:10,466  ERROR       send_post.py  post_report  HTTPConnectionPool(host='localhost', port=8090): Max retries exceeded with url: /api/v1/result (Caused by NewConnectionError('<urllib3.connection.HTTPConnection object at 0x7f3fe7703a60>: Failed to establish a new connection: [Errno 111] Connection refused'))
2023-07-26 09:51:10,512  ERROR       send_post.py  post_report  HTTPConnectionPool(host='localhost', port=8090): Max retries exceeded with url: /api/v1/result (Caused by NewConnectionError('<urllib3.connection.HTTPConnection object at 0x7f3fe7a75430>: Failed to establish a new connection: [Errno 111] Connection refused'))
2023-07-26 09:51:10,558  ERROR       send_post.py  post_report  HTTPConnectionPool(host='localhost', port=8090): Max retries exceeded with url: /api/v1/result (Caused by NewConnectionError('<urllib3.connection.HTTPConnection object at 0x7f3fe7719190>: Failed to establish a new connection: [Errno 111] Connection refused'))
2023-07-26 09:54:31,589  ERROR       send_post.py  post_report  HTTPConnectionPool(host='localhost', port=8090): Max retries exceeded with url: /api/v1/result (Caused by NewConnectionError('<urllib3.connection.HTTPConnection object at 0x7f437bafb970>: Failed to establish a new connection: [Errno 111] Connection refused'))
2023-07-26 09:54:31,633  ERROR       send_post.py  post_report  HTTPConnectionPool(host='localhost', port=8090): Max retries exceeded with url: /api/v1/result (Caused by NewConnectionError('<urllib3.connection.HTTPConnection object at 0x7f437bab6580>: Failed to establish a new connection: [Errno 111] Connection refused'))
2023-07-26 09:54:31,678  ERROR       send_post.py  post_report  HTTPConnectionPool(host='localhost', port=8090): Max retries exceeded with url: /api/v1/result (Caused by NewConnectionError('<urllib3.connection.HTTPConnection object at 0x7f437bab6550>: Failed to establish a new connection: [Errno 111] Connection refused'))
2023-07-26 09:54:31,723  ERROR       send_post.py  post_report  HTTPConnectionPool(host='localhost', port=8090): Max retries exceeded with url: /api/v1/result (Caused by NewConnectionError('<urllib3.connection.HTTPConnection object at 0x7f437bab6e80>: Failed to establish a new connection: [Errno 111] Connection refused'))
2023-07-26 09:54:31,761  ERROR       send_post.py  post_report  HTTPConnectionPool(host='localhost', port=8090): Max retries exceeded with url: /api/v1/result (Caused by NewConnectionError('<urllib3.connection.HTTPConnection object at 0x7f437bac08e0>: Failed to establish a new connection: [Errno 111] Connection refused'))
2023-07-26 09:54:31,804  ERROR       send_post.py  post_report  HTTPConnectionPool(host='localhost', port=8090): Max retries exceeded with url: /api/v1/result (Caused by NewConnectionError('<urllib3.connection.HTTPConnection object at 0x7f437bacb370>: Failed to establish a new connection: [Errno 111] Connection refused'))
2023-07-26 09:54:31,850  ERROR       send_post.py  post_report  HTTPConnectionPool(host='localhost', port=8090): Max retries exceeded with url: /api/v1/result (Caused by NewConnectionError('<urllib3.connection.HTTPConnection object at 0x7f437bab6b50>: Failed to establish a new connection: [Errno 111] Connection refused'))
2023-07-26 09:54:31,894  ERROR       send_post.py  post_report  HTTPConnectionPool(host='localhost', port=8090): Max retries exceeded with url: /api/v1/result (Caused by NewConnectionError('<urllib3.connection.HTTPConnection object at 0x7f437bf6d700>: Failed to establish a new connection: [Errno 111] Connection refused'))
2023-07-26 09:54:31,940  ERROR       send_post.py  post_report  HTTPConnectionPool(host='localhost', port=8090): Max retries exceeded with url: /api/v1/result (Caused by NewConnectionError('<urllib3.connection.HTTPConnection object at 0x7f437bacb190>: Failed to establish a new connection: [Errno 111] Connection refused'))
2023-07-26 09:56:51,935  ERROR       send_post.py  post_report  HTTPConnectionPool(host='localhost', port=8090): Max retries exceeded with url: /api/v1/result (Caused by NewConnectionError('<urllib3.connection.HTTPConnection object at 0x7f3229f43970>: Failed to establish a new connection: [Errno 111] Connection refused'))
2023-07-26 09:56:52,123  ERROR       send_post.py  post_report  HTTPConnectionPool(host='localhost', port=8090): Max retries exceeded with url: /api/v1/result (Caused by NewConnectionError('<urllib3.connection.HTTPConnection object at 0x7f3229af5460>: Failed to establish a new connection: [Errno 111] Connection refused'))
2023-07-26 09:56:52,169  ERROR       send_post.py  post_report  HTTPConnectionPool(host='localhost', port=8090): Max retries exceeded with url: /api/v1/result (Caused by NewConnectionError('<urllib3.connection.HTTPConnection object at 0x7f3229af5490>: Failed to establish a new connection: [Errno 111] Connection refused'))
2023-07-26 09:56:52,215  ERROR       send_post.py  post_report  HTTPConnectionPool(host='localhost', port=8090): Max retries exceeded with url: /api/v1/result (Caused by NewConnectionError('<urllib3.connection.HTTPConnection object at 0x7f3229af5e80>: Failed to establish a new connection: [Errno 111] Connection refused'))
2023-07-26 09:56:52,315  ERROR       send_post.py  post_report  HTTPConnectionPool(host='localhost', port=8090): Max retries exceeded with url: /api/v1/result (Caused by NewConnectionError('<urllib3.connection.HTTPConnection object at 0x7f3229b008e0>: Failed to establish a new connection: [Errno 111] Connection refused'))
2023-07-26 09:56:52,409  ERROR       send_post.py  post_report  HTTPConnectionPool(host='localhost', port=8090): Max retries exceeded with url: /api/v1/result (Caused by NewConnectionError('<urllib3.connection.HTTPConnection object at 0x7f3229b0f370>: Failed to establish a new connection: [Errno 111] Connection refused'))
2023-07-26 09:56:52,455  ERROR       send_post.py  post_report  HTTPConnectionPool(host='localhost', port=8090): Max retries exceeded with url: /api/v1/result (Caused by NewConnectionError('<urllib3.connection.HTTPConnection object at 0x7f322a3737c0>: Failed to establish a new connection: [Errno 111] Connection refused'))
2023-07-26 09:58:29,235  ERROR       send_post.py  post_report  HTTPConnectionPool(host='localhost', port=8090): Max retries exceeded with url: /api/v1/result (Caused by NewConnectionError('<urllib3.connection.HTTPConnection object at 0x7f3bd2d09970>: Failed to establish a new connection: [Errno 111] Connection refused'))
2023-07-26 09:58:29,283  ERROR       send_post.py  post_report  HTTPConnectionPool(host='localhost', port=8090): Max retries exceeded with url: /api/v1/result (Caused by NewConnectionError('<urllib3.connection.HTTPConnection object at 0x7f3bd2943460>: Failed to establish a new connection: [Errno 111] Connection refused'))
2023-07-26 09:58:29,328  ERROR       send_post.py  post_report  HTTPConnectionPool(host='localhost', port=8090): Max retries exceeded with url: /api/v1/result (Caused by NewConnectionError('<urllib3.connection.HTTPConnection object at 0x7f3bd2943490>: Failed to establish a new connection: [Errno 111] Connection refused'))
2023-07-26 09:58:29,462  ERROR       send_post.py  post_report  HTTPConnectionPool(host='localhost', port=8090): Max retries exceeded with url: /api/v1/result (Caused by NewConnectionError('<urllib3.connection.HTTPConnection object at 0x7f3bd2943e80>: Failed to establish a new connection: [Errno 111] Connection refused'))
2023-07-26 09:58:29,500  ERROR       send_post.py  post_report  HTTPConnectionPool(host='localhost', port=8090): Max retries exceeded with url: /api/v1/result (Caused by NewConnectionError('<urllib3.connection.HTTPConnection object at 0x7f3bd294f8e0>: Failed to establish a new connection: [Errno 111] Connection refused'))
2023-07-26 09:58:29,545  ERROR       send_post.py  post_report  HTTPConnectionPool(host='localhost', port=8090): Max retries exceeded with url: /api/v1/result (Caused by NewConnectionError('<urllib3.connection.HTTPConnection object at 0x7f3bd2959370>: Failed to establish a new connection: [Errno 111] Connection refused'))
2023-07-26 09:58:29,593  ERROR       send_post.py  post_report  HTTPConnectionPool(host='localhost', port=8090): Max retries exceeded with url: /api/v1/result (Caused by NewConnectionError('<urllib3.connection.HTTPConnection object at 0x7f3bd2943c10>: Failed to establish a new connection: [Errno 111] Connection refused'))
2023-07-26 09:58:29,639  ERROR       send_post.py  post_report  HTTPConnectionPool(host='localhost', port=8090): Max retries exceeded with url: /api/v1/result (Caused by NewConnectionError('<urllib3.connection.HTTPConnection object at 0x7f3bd2d75a90>: Failed to establish a new connection: [Errno 111] Connection refused'))
2023-07-26 09:58:29,686  ERROR       send_post.py  post_report  HTTPConnectionPool(host='localhost', port=8090): Max retries exceeded with url: /api/v1/result (Caused by NewConnectionError('<urllib3.connection.HTTPConnection object at 0x7f3bd2959190>: Failed to establish a new connection: [Errno 111] Connection refused'))
2023-07-26 09:59:17,707  ERROR       send_post.py  post_report  HTTPConnectionPool(host='localhost', port=8090): Max retries exceeded with url: /api/v1/result (Caused by NewConnectionError('<urllib3.connection.HTTPConnection object at 0x7f7b22f099a0>: Failed to establish a new connection: [Errno 111] Connection refused'))
2023-07-26 09:59:17,815  ERROR       send_post.py  post_report  HTTPConnectionPool(host='localhost', port=8090): Max retries exceeded with url: /api/v1/result (Caused by NewConnectionError('<urllib3.connection.HTTPConnection object at 0x7f7b22b3e460>: Failed to establish a new connection: [Errno 111] Connection refused'))
2023-07-26 09:59:17,861  ERROR       send_post.py  post_report  HTTPConnectionPool(host='localhost', port=8090): Max retries exceeded with url: /api/v1/result (Caused by NewConnectionError('<urllib3.connection.HTTPConnection object at 0x7f7b22b3e190>: Failed to establish a new connection: [Errno 111] Connection refused'))
2023-07-26 09:59:17,906  ERROR       send_post.py  post_report  HTTPConnectionPool(host='localhost', port=8090): Max retries exceeded with url: /api/v1/result (Caused by NewConnectionError('<urllib3.connection.HTTPConnection object at 0x7f7b22b3efa0>: Failed to establish a new connection: [Errno 111] Connection refused'))
2023-07-26 09:59:17,954  ERROR       send_post.py  post_report  HTTPConnectionPool(host='localhost', port=8090): Max retries exceeded with url: /api/v1/result (Caused by NewConnectionError('<urllib3.connection.HTTPConnection object at 0x7f7b22b48a00>: Failed to establish a new connection: [Errno 111] Connection refused'))
2023-07-26 09:59:17,996  ERROR       send_post.py  post_report  HTTPConnectionPool(host='localhost', port=8090): Max retries exceeded with url: /api/v1/result (Caused by NewConnectionError('<urllib3.connection.HTTPConnection object at 0x7f7b22b53370>: Failed to establish a new connection: [Errno 111] Connection refused'))
2023-07-26 09:59:18,039  ERROR       send_post.py  post_report  HTTPConnectionPool(host='localhost', port=8090): Max retries exceeded with url: /api/v1/result (Caused by NewConnectionError('<urllib3.connection.HTTPConnection object at 0x7f7b22b3ed90>: Failed to establish a new connection: [Errno 111] Connection refused'))
2023-07-26 09:59:29,018  ERROR       send_post.py  post_report  HTTPConnectionPool(host='localhost', port=8090): Max retries exceeded with url: /api/v1/result (Caused by NewConnectionError('<urllib3.connection.HTTPConnection object at 0x7f7e70549970>: Failed to establish a new connection: [Errno 111] Connection refused'))
2023-07-26 09:59:29,063  ERROR       send_post.py  post_report  HTTPConnectionPool(host='localhost', port=8090): Max retries exceeded with url: /api/v1/result (Caused by NewConnectionError('<urllib3.connection.HTTPConnection object at 0x7f7e7013d460>: Failed to establish a new connection: [Errno 111] Connection refused'))
2023-07-26 09:59:29,108  ERROR       send_post.py  post_report  HTTPConnectionPool(host='localhost', port=8090): Max retries exceeded with url: /api/v1/result (Caused by NewConnectionError('<urllib3.connection.HTTPConnection object at 0x7f7e7013d490>: Failed to establish a new connection: [Errno 111] Connection refused'))
2023-07-26 09:59:29,154  ERROR       send_post.py  post_report  HTTPConnectionPool(host='localhost', port=8090): Max retries exceeded with url: /api/v1/result (Caused by NewConnectionError('<urllib3.connection.HTTPConnection object at 0x7f7e7013de80>: Failed to establish a new connection: [Errno 111] Connection refused'))
2023-07-26 09:59:29,191  ERROR       send_post.py  post_report  HTTPConnectionPool(host='localhost', port=8090): Max retries exceeded with url: /api/v1/result (Caused by NewConnectionError('<urllib3.connection.HTTPConnection object at 0x7f7e701498e0>: Failed to establish a new connection: [Errno 111] Connection refused'))
2023-07-26 09:59:29,235  ERROR       send_post.py  post_report  HTTPConnectionPool(host='localhost', port=8090): Max retries exceeded with url: /api/v1/result (Caused by NewConnectionError('<urllib3.connection.HTTPConnection object at 0x7f7e70153370>: Failed to establish a new connection: [Errno 111] Connection refused'))
2023-07-26 09:59:29,281  ERROR       send_post.py  post_report  HTTPConnectionPool(host='localhost', port=8090): Max retries exceeded with url: /api/v1/result (Caused by NewConnectionError('<urllib3.connection.HTTPConnection object at 0x7f7e7013ddc0>: Failed to establish a new connection: [Errno 111] Connection refused'))
2023-07-26 09:59:29,327  ERROR       send_post.py  post_report  HTTPConnectionPool(host='localhost', port=8090): Max retries exceeded with url: /api/v1/result (Caused by NewConnectionError('<urllib3.connection.HTTPConnection object at 0x7f7e709378e0>: Failed to establish a new connection: [Errno 111] Connection refused'))
2023-07-26 09:59:29,416  ERROR       send_post.py  post_report  HTTPConnectionPool(host='localhost', port=8090): Max retries exceeded with url: /api/v1/result (Caused by NewConnectionError('<urllib3.connection.HTTPConnection object at 0x7f7e70153190>: Failed to establish a new connection: [Errno 111] Connection refused'))
2023-07-26 15:03:07,887  ERROR       send_post.py  post_report  HTTPConnectionPool(host='localhost', port=8090): Max retries exceeded with url: /api/v1/result (Caused by NewConnectionError('<urllib3.connection.HTTPConnection object at 0x7f6b2c4fca30>: Failed to establish a new connection: [Errno 111] Connection refused'))
2023-07-26 15:03:08,046  ERROR       send_post.py  post_report  HTTPConnectionPool(host='localhost', port=8090): Max retries exceeded with url: /api/v1/result (Caused by NewConnectionError('<urllib3.connection.HTTPConnection object at 0x7f6b2c4b64f0>: Failed to establish a new connection: [Errno 111] Connection refused'))
2023-07-26 15:03:08,118  ERROR       send_post.py  post_report  HTTPConnectionPool(host='localhost', port=8090): Max retries exceeded with url: /api/v1/result (Caused by NewConnectionError('<urllib3.connection.HTTPConnection object at 0x7f6b2c4b6580>: Failed to establish a new connection: [Errno 111] Connection refused'))
2023-07-26 15:03:08,173  ERROR       send_post.py  post_report  HTTPConnectionPool(host='localhost', port=8090): Max retries exceeded with url: /api/v1/result (Caused by NewConnectionError('<urllib3.connection.HTTPConnection object at 0x7f6b2c4b6f70>: Failed to establish a new connection: [Errno 111] Connection refused'))
2023-07-26 15:03:08,234  ERROR       send_post.py  post_report  HTTPConnectionPool(host='localhost', port=8090): Max retries exceeded with url: /api/v1/result (Caused by NewConnectionError('<urllib3.connection.HTTPConnection object at 0x7f6b2c4c0970>: Failed to establish a new connection: [Errno 111] Connection refused'))
2023-07-26 15:03:08,297  ERROR       send_post.py  post_report  HTTPConnectionPool(host='localhost', port=8090): Max retries exceeded with url: /api/v1/result (Caused by NewConnectionError('<urllib3.connection.HTTPConnection object at 0x7f6b2c4d13d0>: Failed to establish a new connection: [Errno 111] Connection refused'))
2023-07-26 15:03:08,360  ERROR       send_post.py  post_report  HTTPConnectionPool(host='localhost', port=8090): Max retries exceeded with url: /api/v1/result (Caused by NewConnectionError('<urllib3.connection.HTTPConnection object at 0x7f6b2c96d850>: Failed to establish a new connection: [Errno 111] Connection refused'))
2023-07-26 15:03:08,538  ERROR       send_post.py  post_report  HTTPConnectionPool(host='localhost', port=8090): Max retries exceeded with url: /api/v1/result (Caused by NewConnectionError('<urllib3.connection.HTTPConnection object at 0x7f6b2c4fcca0>: Failed to establish a new connection: [Errno 111] Connection refused'))
2023-07-26 15:03:08,717  ERROR       send_post.py  post_report  HTTPConnectionPool(host='localhost', port=8090): Max retries exceeded with url: /api/v1/result (Caused by NewConnectionError('<urllib3.connection.HTTPConnection object at 0x7f6b2c4b6b50>: Failed to establish a new connection: [Errno 111] Connection refused'))
2023-07-26 15:03:08,782  ERROR       send_post.py  post_report  HTTPConnectionPool(host='localhost', port=8090): Max retries exceeded with url: /api/v1/result (Caused by NewConnectionError('<urllib3.connection.HTTPConnection object at 0x7f6b2c4d15e0>: Failed to establish a new connection: [Errno 111] Connection refused'))
2023-07-27 14:27:19,041  ERROR       send_post.py  post_report  HTTPConnectionPool(host='localhost', port=8090): Max retries exceeded with url: /api/v1/result (Caused by NewConnectionError('<urllib3.connection.HTTPConnection object at 0x7ff9395019d0>: Failed to establish a new connection: [Errno 111] Connection refused'))
2023-07-27 14:27:19,165  ERROR       send_post.py  post_report  HTTPConnectionPool(host='localhost', port=8090): Max retries exceeded with url: /api/v1/result (Caused by NewConnectionError('<urllib3.connection.HTTPConnection object at 0x7ff9394bb4c0>: Failed to establish a new connection: [Errno 111] Connection refused'))
2023-07-27 14:27:19,215  ERROR       send_post.py  post_report  HTTPConnectionPool(host='localhost', port=8090): Max retries exceeded with url: /api/v1/result (Caused by NewConnectionError('<urllib3.connection.HTTPConnection object at 0x7ff9394bb370>: Failed to establish a new connection: [Errno 111] Connection refused'))
2023-07-27 14:27:19,274  ERROR       send_post.py  post_report  HTTPConnectionPool(host='localhost', port=8090): Max retries exceeded with url: /api/v1/result (Caused by NewConnectionError('<urllib3.connection.HTTPConnection object at 0x7ff9394bbfd0>: Failed to establish a new connection: [Errno 111] Connection refused'))
2023-07-27 14:27:19,320  ERROR       send_post.py  post_report  HTTPConnectionPool(host='localhost', port=8090): Max retries exceeded with url: /api/v1/result (Caused by NewConnectionError('<urllib3.connection.HTTPConnection object at 0x7ff9394c5a30>: Failed to establish a new connection: [Errno 111] Connection refused'))
2023-07-27 14:27:19,394  ERROR       send_post.py  post_report  HTTPConnectionPool(host='localhost', port=8090): Max retries exceeded with url: /api/v1/result (Caused by NewConnectionError('<urllib3.connection.HTTPConnection object at 0x7ff9394f5460>: Failed to establish a new connection: [Errno 111] Connection refused'))
2023-07-27 14:27:19,485  ERROR       send_post.py  post_report  HTTPConnectionPool(host='localhost', port=8090): Max retries exceeded with url: /api/v1/result (Caused by NewConnectionError('<urllib3.connection.HTTPConnection object at 0x7ff9395018e0>: Failed to establish a new connection: [Errno 111] Connection refused'))
2023-07-27 14:27:19,542  ERROR       send_post.py  post_report  HTTPConnectionPool(host='localhost', port=8090): Max retries exceeded with url: /api/v1/result (Caused by NewConnectionError('<urllib3.connection.HTTPConnection object at 0x7ff9394bbd60>: Failed to establish a new connection: [Errno 111] Connection refused'))
2023-07-27 14:27:19,637  ERROR       send_post.py  post_report  HTTPConnectionPool(host='localhost', port=8090): Max retries exceeded with url: /api/v1/result (Caused by NewConnectionError('<urllib3.connection.HTTPConnection object at 0x7ff9394c5700>: Failed to establish a new connection: [Errno 111] Connection refused'))
2023-07-27 14:29:34,118  ERROR       send_post.py  post_report  HTTPConnectionPool(host='localhost', port=8090): Max retries exceeded with url: /api/v1/result (Caused by NewConnectionError('<urllib3.connection.HTTPConnection object at 0x7f876c349970>: Failed to establish a new connection: [Errno 111] Connection refused'))
2023-07-27 14:29:34,167  ERROR       send_post.py  post_report  HTTPConnectionPool(host='localhost', port=8090): Max retries exceeded with url: /api/v1/result (Caused by NewConnectionError('<urllib3.connection.HTTPConnection object at 0x7f876bfcb490>: Failed to establish a new connection: [Errno 111] Connection refused'))
2023-07-27 14:29:34,226  ERROR       send_post.py  post_report  HTTPConnectionPool(host='localhost', port=8090): Max retries exceeded with url: /api/v1/result (Caused by NewConnectionError('<urllib3.connection.HTTPConnection object at 0x7f876bfcb0d0>: Failed to establish a new connection: [Errno 111] Connection refused'))
2023-07-27 14:29:34,274  ERROR       send_post.py  post_report  HTTPConnectionPool(host='localhost', port=8090): Max retries exceeded with url: /api/v1/result (Caused by NewConnectionError('<urllib3.connection.HTTPConnection object at 0x7f876bfcbfa0>: Failed to establish a new connection: [Errno 111] Connection refused'))
2023-07-27 14:29:34,329  ERROR       send_post.py  post_report  HTTPConnectionPool(host='localhost', port=8090): Max retries exceeded with url: /api/v1/result (Caused by NewConnectionError('<urllib3.connection.HTTPConnection object at 0x7f876bfd6760>: Failed to establish a new connection: [Errno 111] Connection refused'))
2023-07-27 14:29:34,377  ERROR       send_post.py  post_report  HTTPConnectionPool(host='localhost', port=8090): Max retries exceeded with url: /api/v1/result (Caused by NewConnectionError('<urllib3.connection.HTTPConnection object at 0x7f876bfd65b0>: Failed to establish a new connection: [Errno 111] Connection refused'))
2023-07-27 14:29:34,431  ERROR       send_post.py  post_report  HTTPConnectionPool(host='localhost', port=8090): Max retries exceeded with url: /api/v1/result (Caused by NewConnectionError('<urllib3.connection.HTTPConnection object at 0x7f876bfcbe80>: Failed to establish a new connection: [Errno 111] Connection refused'))
2023-07-27 14:29:34,478  ERROR       send_post.py  post_report  HTTPConnectionPool(host='localhost', port=8090): Max retries exceeded with url: /api/v1/result (Caused by NewConnectionError('<urllib3.connection.HTTPConnection object at 0x7f876c349310>: Failed to establish a new connection: [Errno 111] Connection refused'))
2023-07-27 14:29:34,532  ERROR       send_post.py  post_report  HTTPConnectionPool(host='localhost', port=8090): Max retries exceeded with url: /api/v1/result (Caused by NewConnectionError('<urllib3.connection.HTTPConnection object at 0x7f876bfe4100>: Failed to establish a new connection: [Errno 111] Connection refused'))
2023-07-27 17:30:14,248  ERROR       send_post.py  post_report  HTTPConnectionPool(host='localhost', port=8090): Max retries exceeded with url: /api/v1/result (Caused by NewConnectionError('<urllib3.connection.HTTPConnection object at 0x7fe3a5dc4280>: Failed to establish a new connection: [Errno 111] Connection refused'))
2023-07-27 17:30:14,321  ERROR       send_post.py  post_report  HTTPConnectionPool(host='localhost', port=8090): Max retries exceeded with url: /api/v1/result (Caused by NewConnectionError('<urllib3.connection.HTTPConnection object at 0x7fe3a5dc45b0>: Failed to establish a new connection: [Errno 111] Connection refused'))
2023-07-27 17:30:14,386  ERROR       send_post.py  post_report  HTTPConnectionPool(host='localhost', port=8090): Max retries exceeded with url: /api/v1/result (Caused by NewConnectionError('<urllib3.connection.HTTPConnection object at 0x7fe3a5dc43d0>: Failed to establish a new connection: [Errno 111] Connection refused'))
2023-07-27 17:30:14,454  ERROR       send_post.py  post_report  HTTPConnectionPool(host='localhost', port=8090): Max retries exceeded with url: /api/v1/result (Caused by NewConnectionError('<urllib3.connection.HTTPConnection object at 0x7fe3a5dd3580>: Failed to establish a new connection: [Errno 111] Connection refused'))
2023-07-27 17:30:14,512  ERROR       send_post.py  post_report  HTTPConnectionPool(host='localhost', port=8090): Max retries exceeded with url: /api/v1/result (Caused by NewConnectionError('<urllib3.connection.HTTPConnection object at 0x7fe3a5de0190>: Failed to establish a new connection: [Errno 111] Connection refused'))
2023-07-27 17:30:14,581  ERROR       send_post.py  post_report  HTTPConnectionPool(host='localhost', port=8090): Max retries exceeded with url: /api/v1/result (Caused by NewConnectionError('<urllib3.connection.HTTPConnection object at 0x7fe3a5dd3580>: Failed to establish a new connection: [Errno 111] Connection refused'))
2023-07-27 17:30:14,646  ERROR       send_post.py  post_report  HTTPConnectionPool(host='localhost', port=8090): Max retries exceeded with url: /api/v1/result (Caused by NewConnectionError('<urllib3.connection.HTTPConnection object at 0x7fe3a5dc4c70>: Failed to establish a new connection: [Errno 111] Connection refused'))
2023-07-27 17:30:14,746  ERROR       send_post.py  post_report  HTTPConnectionPool(host='localhost', port=8090): Max retries exceeded with url: /api/v1/result (Caused by NewConnectionError('<urllib3.connection.HTTPConnection object at 0x7fe3a6143250>: Failed to establish a new connection: [Errno 111] Connection refused'))
2023-07-27 17:30:14,820  ERROR       send_post.py  post_report  HTTPConnectionPool(host='localhost', port=8090): Max retries exceeded with url: /api/v1/result (Caused by NewConnectionError('<urllib3.connection.HTTPConnection object at 0x7fe3a5de41c0>: Failed to establish a new connection: [Errno 111] Connection refused'))
2023-07-27 17:31:20,894  ERROR       send_post.py  post_report  HTTPConnectionPool(host='localhost', port=8090): Max retries exceeded with url: /api/v1/result (Caused by NewConnectionError('<urllib3.connection.HTTPConnection object at 0x7f4f64d522e0>: Failed to establish a new connection: [Errno 111] Connection refused'))
2023-07-27 17:31:20,959  ERROR       send_post.py  post_report  HTTPConnectionPool(host='localhost', port=8090): Max retries exceeded with url: /api/v1/result (Caused by NewConnectionError('<urllib3.connection.HTTPConnection object at 0x7f4f64d526d0>: Failed to establish a new connection: [Errno 111] Connection refused'))
2023-07-27 17:31:21,033  ERROR       send_post.py  post_report  HTTPConnectionPool(host='localhost', port=8090): Max retries exceeded with url: /api/v1/result (Caused by NewConnectionError('<urllib3.connection.HTTPConnection object at 0x7f4f64d52310>: Failed to establish a new connection: [Errno 111] Connection refused'))
2023-07-27 17:31:21,101  ERROR       send_post.py  post_report  HTTPConnectionPool(host='localhost', port=8090): Max retries exceeded with url: /api/v1/result (Caused by NewConnectionError('<urllib3.connection.HTTPConnection object at 0x7f4f64d0e640>: Failed to establish a new connection: [Errno 111] Connection refused'))
2023-07-27 17:31:21,165  ERROR       send_post.py  post_report  HTTPConnectionPool(host='localhost', port=8090): Max retries exceeded with url: /api/v1/result (Caused by NewConnectionError('<urllib3.connection.HTTPConnection object at 0x7f4f64d1a250>: Failed to establish a new connection: [Errno 111] Connection refused'))
2023-07-27 17:31:21,219  ERROR       send_post.py  post_report  HTTPConnectionPool(host='localhost', port=8090): Max retries exceeded with url: /api/v1/result (Caused by NewConnectionError('<urllib3.connection.HTTPConnection object at 0x7f4f64d0e370>: Failed to establish a new connection: [Errno 111] Connection refused'))
2023-07-27 17:31:21,292  ERROR       send_post.py  post_report  HTTPConnectionPool(host='localhost', port=8090): Max retries exceeded with url: /api/v1/result (Caused by NewConnectionError('<urllib3.connection.HTTPConnection object at 0x7f4f64d523d0>: Failed to establish a new connection: [Errno 111] Connection refused'))
2023-07-27 17:31:21,352  ERROR       send_post.py  post_report  HTTPConnectionPool(host='localhost', port=8090): Max retries exceeded with url: /api/v1/result (Caused by NewConnectionError('<urllib3.connection.HTTPConnection object at 0x7f4f6506aeb0>: Failed to establish a new connection: [Errno 111] Connection refused'))
2023-07-27 17:31:21,422  ERROR       send_post.py  post_report  HTTPConnectionPool(host='localhost', port=8090): Max retries exceeded with url: /api/v1/result (Caused by NewConnectionError('<urllib3.connection.HTTPConnection object at 0x7f4f64d0f250>: Failed to establish a new connection: [Errno 111] Connection refused'))
2023-07-27 17:34:40,268  ERROR       send_post.py  post_report  HTTPConnectionPool(host='localhost', port=8090): Max retries exceeded with url: /api/v1/result (Caused by NewConnectionError('<urllib3.connection.HTTPConnection object at 0x7eff799523d0>: Failed to establish a new connection: [Errno 111] Connection refused'))
2023-07-27 17:34:40,339  ERROR       send_post.py  post_report  HTTPConnectionPool(host='localhost', port=8090): Max retries exceeded with url: /api/v1/result (Caused by NewConnectionError('<urllib3.connection.HTTPConnection object at 0x7eff79952ac0>: Failed to establish a new connection: [Errno 111] Connection refused'))
2023-07-27 17:34:40,417  ERROR       send_post.py  post_report  HTTPConnectionPool(host='localhost', port=8090): Max retries exceeded with url: /api/v1/result (Caused by NewConnectionError('<urllib3.connection.HTTPConnection object at 0x7eff79952f70>: Failed to establish a new connection: [Errno 111] Connection refused'))
2023-07-27 17:34:40,485  ERROR       send_post.py  post_report  HTTPConnectionPool(host='localhost', port=8090): Max retries exceeded with url: /api/v1/result (Caused by NewConnectionError('<urllib3.connection.HTTPConnection object at 0x7eff7990e9d0>: Failed to establish a new connection: [Errno 111] Connection refused'))
2023-07-27 17:34:40,555  ERROR       send_post.py  post_report  HTTPConnectionPool(host='localhost', port=8090): Max retries exceeded with url: /api/v1/result (Caused by NewConnectionError('<urllib3.connection.HTTPConnection object at 0x7eff7991a340>: Failed to establish a new connection: [Errno 111] Connection refused'))
2023-07-27 17:34:40,616  ERROR       send_post.py  post_report  HTTPConnectionPool(host='localhost', port=8090): Max retries exceeded with url: /api/v1/result (Caused by NewConnectionError('<urllib3.connection.HTTPConnection object at 0x7eff7990e5e0>: Failed to establish a new connection: [Errno 111] Connection refused'))
2023-07-27 17:34:40,693  ERROR       send_post.py  post_report  HTTPConnectionPool(host='localhost', port=8090): Max retries exceeded with url: /api/v1/result (Caused by NewConnectionError('<urllib3.connection.HTTPConnection object at 0x7eff799527f0>: Failed to establish a new connection: [Errno 111] Connection refused'))
2023-07-27 17:34:40,766  ERROR       send_post.py  post_report  HTTPConnectionPool(host='localhost', port=8090): Max retries exceeded with url: /api/v1/result (Caused by NewConnectionError('<urllib3.connection.HTTPConnection object at 0x7eff79c68f70>: Failed to establish a new connection: [Errno 111] Connection refused'))
2023-07-27 17:34:40,842  ERROR       send_post.py  post_report  HTTPConnectionPool(host='localhost', port=8090): Max retries exceeded with url: /api/v1/result (Caused by NewConnectionError('<urllib3.connection.HTTPConnection object at 0x7eff798fd340>: Failed to establish a new connection: [Errno 111] Connection refused'))
2023-07-27 17:36:34,542  ERROR       send_post.py  post_report  HTTPConnectionPool(host='localhost', port=8090): Max retries exceeded with url: /api/v1/result (Caused by NewConnectionError('<urllib3.connection.HTTPConnection object at 0x7f13f734c3a0>: Failed to establish a new connection: [Errno 111] Connection refused'))
2023-07-27 17:36:34,620  ERROR       send_post.py  post_report  HTTPConnectionPool(host='localhost', port=8090): Max retries exceeded with url: /api/v1/result (Caused by NewConnectionError('<urllib3.connection.HTTPConnection object at 0x7f13f734ca90>: Failed to establish a new connection: [Errno 111] Connection refused'))
2023-07-27 17:36:34,698  ERROR       send_post.py  post_report  HTTPConnectionPool(host='localhost', port=8090): Max retries exceeded with url: /api/v1/result (Caused by NewConnectionError('<urllib3.connection.HTTPConnection object at 0x7f13f734cf40>: Failed to establish a new connection: [Errno 111] Connection refused'))
2023-07-27 17:36:34,804  ERROR       send_post.py  post_report  HTTPConnectionPool(host='localhost', port=8090): Max retries exceeded with url: /api/v1/result (Caused by NewConnectionError('<urllib3.connection.HTTPConnection object at 0x7f13f6f009a0>: Failed to establish a new connection: [Errno 111] Connection refused'))
2023-07-27 17:36:34,873  ERROR       send_post.py  post_report  HTTPConnectionPool(host='localhost', port=8090): Max retries exceeded with url: /api/v1/result (Caused by NewConnectionError('<urllib3.connection.HTTPConnection object at 0x7f13f6f0d310>: Failed to establish a new connection: [Errno 111] Connection refused'))
2023-07-27 17:36:34,945  ERROR       send_post.py  post_report  HTTPConnectionPool(host='localhost', port=8090): Max retries exceeded with url: /api/v1/result (Caused by NewConnectionError('<urllib3.connection.HTTPConnection object at 0x7f13f6f00700>: Failed to establish a new connection: [Errno 111] Connection refused'))
2023-07-27 17:36:35,021  ERROR       send_post.py  post_report  HTTPConnectionPool(host='localhost', port=8090): Max retries exceeded with url: /api/v1/result (Caused by NewConnectionError('<urllib3.connection.HTTPConnection object at 0x7f13f734c460>: Failed to establish a new connection: [Errno 111] Connection refused'))
2023-07-27 17:36:35,092  ERROR       send_post.py  post_report  HTTPConnectionPool(host='localhost', port=8090): Max retries exceeded with url: /api/v1/result (Caused by NewConnectionError('<urllib3.connection.HTTPConnection object at 0x7f13f77665e0>: Failed to establish a new connection: [Errno 111] Connection refused'))
2023-07-27 17:36:35,166  ERROR       send_post.py  post_report  HTTPConnectionPool(host='localhost', port=8090): Max retries exceeded with url: /api/v1/result (Caused by NewConnectionError('<urllib3.connection.HTTPConnection object at 0x7f13f6eef310>: Failed to establish a new connection: [Errno 111] Connection refused'))
2023-07-27 17:39:22,362  ERROR       send_post.py  post_report  HTTPConnectionPool(host='localhost', port=8090): Max retries exceeded with url: /api/v1/result (Caused by NewConnectionError('<urllib3.connection.HTTPConnection object at 0x7f784d1123a0>: Failed to establish a new connection: [Errno 111] Connection refused'))
2023-07-27 17:39:22,454  ERROR       send_post.py  post_report  HTTPConnectionPool(host='localhost', port=8090): Max retries exceeded with url: /api/v1/result (Caused by NewConnectionError('<urllib3.connection.HTTPConnection object at 0x7f784d112a30>: Failed to establish a new connection: [Errno 111] Connection refused'))
2023-07-27 17:39:22,521  ERROR       send_post.py  post_report  HTTPConnectionPool(host='localhost', port=8090): Max retries exceeded with url: /api/v1/result (Caused by NewConnectionError('<urllib3.connection.HTTPConnection object at 0x7f784d112f40>: Failed to establish a new connection: [Errno 111] Connection refused'))
2023-07-27 17:39:22,579  ERROR       send_post.py  post_report  HTTPConnectionPool(host='localhost', port=8090): Max retries exceeded with url: /api/v1/result (Caused by NewConnectionError('<urllib3.connection.HTTPConnection object at 0x7f784cd489a0>: Failed to establish a new connection: [Errno 111] Connection refused'))
2023-07-27 17:39:22,650  ERROR       send_post.py  post_report  HTTPConnectionPool(host='localhost', port=8090): Max retries exceeded with url: /api/v1/result (Caused by NewConnectionError('<urllib3.connection.HTTPConnection object at 0x7f784cd57310>: Failed to establish a new connection: [Errno 111] Connection refused'))
2023-07-27 17:39:22,704  ERROR       send_post.py  post_report  HTTPConnectionPool(host='localhost', port=8090): Max retries exceeded with url: /api/v1/result (Caused by NewConnectionError('<urllib3.connection.HTTPConnection object at 0x7f784cd48700>: Failed to establish a new connection: [Errno 111] Connection refused'))
2023-07-27 17:47:18,636  ERROR       send_post.py  post_report  HTTPConnectionPool(host='localhost', port=8090): Max retries exceeded with url: /api/v1/result (Caused by NewConnectionError('<urllib3.connection.HTTPConnection object at 0x7f46577523a0>: Failed to establish a new connection: [Errno 111] Connection refused'))
2023-07-27 17:47:18,709  ERROR       send_post.py  post_report  HTTPConnectionPool(host='localhost', port=8090): Max retries exceeded with url: /api/v1/result (Caused by NewConnectionError('<urllib3.connection.HTTPConnection object at 0x7f4657752a30>: Failed to establish a new connection: [Errno 111] Connection refused'))
2023-07-27 17:47:18,788  ERROR       send_post.py  post_report  HTTPConnectionPool(host='localhost', port=8090): Max retries exceeded with url: /api/v1/result (Caused by NewConnectionError('<urllib3.connection.HTTPConnection object at 0x7f4657752f40>: Failed to establish a new connection: [Errno 111] Connection refused'))
2023-07-27 17:47:18,859  ERROR       send_post.py  post_report  HTTPConnectionPool(host='localhost', port=8090): Max retries exceeded with url: /api/v1/result (Caused by NewConnectionError('<urllib3.connection.HTTPConnection object at 0x7f465770f9a0>: Failed to establish a new connection: [Errno 111] Connection refused'))
2023-07-27 17:47:18,926  ERROR       send_post.py  post_report  HTTPConnectionPool(host='localhost', port=8090): Max retries exceeded with url: /api/v1/result (Caused by NewConnectionError('<urllib3.connection.HTTPConnection object at 0x7f46577182e0>: Failed to establish a new connection: [Errno 111] Connection refused'))
2023-07-27 17:47:18,992  ERROR       send_post.py  post_report  HTTPConnectionPool(host='localhost', port=8090): Max retries exceeded with url: /api/v1/result (Caused by NewConnectionError('<urllib3.connection.HTTPConnection object at 0x7f465770f7c0>: Failed to establish a new connection: [Errno 111] Connection refused'))
2023-07-27 17:47:19,069  ERROR       send_post.py  post_report  HTTPConnectionPool(host='localhost', port=8090): Max retries exceeded with url: /api/v1/result (Caused by NewConnectionError('<urllib3.connection.HTTPConnection object at 0x7f4657752f10>: Failed to establish a new connection: [Errno 111] Connection refused'))
2023-07-27 17:47:19,137  ERROR       send_post.py  post_report  HTTPConnectionPool(host='localhost', port=8090): Max retries exceeded with url: /api/v1/result (Caused by NewConnectionError('<urllib3.connection.HTTPConnection object at 0x7f4657a68af0>: Failed to establish a new connection: [Errno 111] Connection refused'))
2023-07-27 17:47:19,215  ERROR       send_post.py  post_report  HTTPConnectionPool(host='localhost', port=8090): Max retries exceeded with url: /api/v1/result (Caused by NewConnectionError('<urllib3.connection.HTTPConnection object at 0x7f4657719310>: Failed to establish a new connection: [Errno 111] Connection refused'))
2023-07-27 18:01:57,447  ERROR       send_post.py  post_report  HTTPConnectionPool(host='localhost', port=8090): Max retries exceeded with url: /api/v1/result (Caused by NewConnectionError('<urllib3.connection.HTTPConnection object at 0x7fbf8374c370>: Failed to establish a new connection: [Errno 111] Connection refused'))
2023-07-27 18:01:57,513  ERROR       send_post.py  post_report  HTTPConnectionPool(host='localhost', port=8090): Max retries exceeded with url: /api/v1/result (Caused by NewConnectionError('<urllib3.connection.HTTPConnection object at 0x7fbf8374c760>: Failed to establish a new connection: [Errno 111] Connection refused'))
2023-07-27 18:01:57,584  ERROR       send_post.py  post_report  HTTPConnectionPool(host='localhost', port=8090): Max retries exceeded with url: /api/v1/result (Caused by NewConnectionError('<urllib3.connection.HTTPConnection object at 0x7fbf8374c370>: Failed to establish a new connection: [Errno 111] Connection refused'))
2023-07-27 18:01:57,648  ERROR       send_post.py  post_report  HTTPConnectionPool(host='localhost', port=8090): Max retries exceeded with url: /api/v1/result (Caused by NewConnectionError('<urllib3.connection.HTTPConnection object at 0x7fbf833006d0>: Failed to establish a new connection: [Errno 111] Connection refused'))
2023-07-27 18:01:57,713  ERROR       send_post.py  post_report  HTTPConnectionPool(host='localhost', port=8090): Max retries exceeded with url: /api/v1/result (Caused by NewConnectionError('<urllib3.connection.HTTPConnection object at 0x7fbf8330f2e0>: Failed to establish a new connection: [Errno 111] Connection refused'))
2023-07-27 18:01:57,773  ERROR       send_post.py  post_report  HTTPConnectionPool(host='localhost', port=8090): Max retries exceeded with url: /api/v1/result (Caused by NewConnectionError('<urllib3.connection.HTTPConnection object at 0x7fbf83300430>: Failed to establish a new connection: [Errno 111] Connection refused'))
2023-07-27 18:01:57,845  ERROR       send_post.py  post_report  HTTPConnectionPool(host='localhost', port=8090): Max retries exceeded with url: /api/v1/result (Caused by NewConnectionError('<urllib3.connection.HTTPConnection object at 0x7fbf8374cd90>: Failed to establish a new connection: [Errno 111] Connection refused'))
2023-07-27 18:01:57,910  ERROR       send_post.py  post_report  HTTPConnectionPool(host='localhost', port=8090): Max retries exceeded with url: /api/v1/result (Caused by NewConnectionError('<urllib3.connection.HTTPConnection object at 0x7fbf83b66dc0>: Failed to establish a new connection: [Errno 111] Connection refused'))
2023-07-27 18:01:57,980  ERROR       send_post.py  post_report  HTTPConnectionPool(host='localhost', port=8090): Max retries exceeded with url: /api/v1/result (Caused by NewConnectionError('<urllib3.connection.HTTPConnection object at 0x7fbf832ef2e0>: Failed to establish a new connection: [Errno 111] Connection refused'))
2023-07-27 18:04:18,711  ERROR       send_post.py  post_report  HTTPConnectionPool(host='localhost', port=8090): Max retries exceeded with url: /api/v1/result (Caused by NewConnectionError('<urllib3.connection.HTTPConnection object at 0x7ff418152370>: Failed to establish a new connection: [Errno 111] Connection refused'))
2023-07-27 18:04:18,790  ERROR       send_post.py  post_report  HTTPConnectionPool(host='localhost', port=8090): Max retries exceeded with url: /api/v1/result (Caused by NewConnectionError('<urllib3.connection.HTTPConnection object at 0x7ff418152a00>: Failed to establish a new connection: [Errno 111] Connection refused'))
2023-07-27 18:04:18,861  ERROR       send_post.py  post_report  HTTPConnectionPool(host='localhost', port=8090): Max retries exceeded with url: /api/v1/result (Caused by NewConnectionError('<urllib3.connection.HTTPConnection object at 0x7ff418152f10>: Failed to establish a new connection: [Errno 111] Connection refused'))
2023-07-27 18:04:18,936  ERROR       send_post.py  post_report  HTTPConnectionPool(host='localhost', port=8090): Max retries exceeded with url: /api/v1/result (Caused by NewConnectionError('<urllib3.connection.HTTPConnection object at 0x7ff417d48970>: Failed to establish a new connection: [Errno 111] Connection refused'))
2023-07-27 18:04:18,998  ERROR       send_post.py  post_report  HTTPConnectionPool(host='localhost', port=8090): Max retries exceeded with url: /api/v1/result (Caused by NewConnectionError('<urllib3.connection.HTTPConnection object at 0x7ff417d542e0>: Failed to establish a new connection: [Errno 111] Connection refused'))
2023-07-27 18:04:19,065  ERROR       send_post.py  post_report  HTTPConnectionPool(host='localhost', port=8090): Max retries exceeded with url: /api/v1/result (Caused by NewConnectionError('<urllib3.connection.HTTPConnection object at 0x7ff417d48040>: Failed to establish a new connection: [Errno 111] Connection refused'))
2023-07-27 18:04:19,139  ERROR       send_post.py  post_report  HTTPConnectionPool(host='localhost', port=8090): Max retries exceeded with url: /api/v1/result (Caused by NewConnectionError('<urllib3.connection.HTTPConnection object at 0x7ff4181520d0>: Failed to establish a new connection: [Errno 111] Connection refused'))
2023-07-27 18:04:19,211  ERROR       send_post.py  post_report  HTTPConnectionPool(host='localhost', port=8090): Max retries exceeded with url: /api/v1/result (Caused by NewConnectionError('<urllib3.connection.HTTPConnection object at 0x7ff41852c430>: Failed to establish a new connection: [Errno 111] Connection refused'))
2023-07-27 18:04:19,282  ERROR       send_post.py  post_report  HTTPConnectionPool(host='localhost', port=8090): Max retries exceeded with url: /api/v1/result (Caused by NewConnectionError('<urllib3.connection.HTTPConnection object at 0x7ff417d442e0>: Failed to establish a new connection: [Errno 111] Connection refused'))
