2023-06-05 18:31:25,212  ERROR       send_post.py  run  HTTPConnectionPool(host='0.0.0.0', port=9624): Max retries exceeded with url: /test (Caused by NewConnectionError('<urllib3.connection.HTTPConnection object at 0x7fcc491dfaf0>: Failed to establish a new connection: [Errno 111] Connection refused'))
2023-06-05 18:31:36,456  ERROR       send_post.py  main  scene is not correct
2023-06-06 10:53:54,332  ERROR       send_post.py  run_rtsp_gpu  frame_192.168.0.20 is not update
2023-06-06 10:53:59,338  ERROR       send_post.py  run_rtsp_gpu  frame_192.168.0.20 is not update
2023-06-06 10:54:04,344  ERROR       send_post.py  run_rtsp_gpu  frame_192.168.0.20 is not update
2023-06-06 10:54:09,351  ERROR       send_post.py  run_rtsp_gpu  frame_192.168.0.20 is not update
2023-06-06 10:54:14,354  ERROR       send_post.py  run_rtsp_gpu  frame_192.168.0.20 is not update
2023-06-09 18:48:21,968  ERROR       send_post.py  post_report  HTTPConnectionPool(host='localhost', port=8090): Max retries exceeded with url: /api/v1/result (Caused by NewConnectionError('<urllib3.connection.HTTPConnection object at 0x7f568fb742e0>: Failed to establish a new connection: [Errno 111] Connection refused'))
2023-06-09 18:49:36,859  ERROR       send_post.py  post_report  HTTPConnectionPool(host='localhost', port=8090): Max retries exceeded with url: /api/v1/result (Caused by NewConnectionError('<urllib3.connection.HTTPConnection object at 0x7f622d57a3d0>: Failed to establish a new connection: [Errno 111] Connection refused'))
2023-06-09 18:50:46,113  ERROR       send_post.py  post_report  HTTPConnectionPool(host='localhost', port=8090): Max retries exceeded with url: /api/v1/result (Caused by NewConnectionError('<urllib3.connection.HTTPConnection object at 0x7fef9633c3d0>: Failed to establish a new connection: [Errno 111] Connection refused'))
2023-06-12 15:13:41,360  ERROR       send_post.py  post_report  HTTPConnectionPool(host='localhost', port=8090): Max retries exceeded with url: /api/v1/result (Caused by NewConnectionError('<urllib3.connection.HTTPConnection object at 0x7fd500573190>: Failed to establish a new connection: [Errno 111] Connection refused'))
2023-06-12 15:13:41,386  ERROR       send_post.py  post_report  HTTPConnectionPool(host='localhost', port=8090): Max retries exceeded with url: /api/v1/result (Caused by NewConnectionError('<urllib3.connection.HTTPConnection object at 0x7fd500573bb0>: Failed to establish a new connection: [Errno 111] Connection refused'))
2023-06-12 15:13:41,415  ERROR       send_post.py  post_report  HTTPConnectionPool(host='localhost', port=8090): Max retries exceeded with url: /api/v1/result (Caused by NewConnectionError('<urllib3.connection.HTTPConnection object at 0x7fd500573100>: Failed to establish a new connection: [Errno 111] Connection refused'))
2023-06-12 15:13:41,442  ERROR       send_post.py  post_report  HTTPConnectionPool(host='localhost', port=8090): Max retries exceeded with url: /api/v1/result (Caused by NewConnectionError('<urllib3.connection.HTTPConnection object at 0x7fd5000f9610>: Failed to establish a new connection: [Errno 111] Connection refused'))
2023-06-12 15:13:41,468  ERROR       send_post.py  post_report  HTTPConnectionPool(host='localhost', port=8090): Max retries exceeded with url: /api/v1/result (Caused by NewConnectionError('<urllib3.connection.HTTPConnection object at 0x7fd5001040a0>: Failed to establish a new connection: [Errno 111] Connection refused'))
2023-06-12 15:13:41,495  ERROR       send_post.py  post_report  HTTPConnectionPool(host='localhost', port=8090): Max retries exceeded with url: /api/v1/result (Caused by NewConnectionError('<urllib3.connection.HTTPConnection object at 0x7fd500104a90>: Failed to establish a new connection: [Errno 111] Connection refused'))
2023-06-12 15:13:41,522  ERROR       send_post.py  post_report  HTTPConnectionPool(host='localhost', port=8090): Max retries exceeded with url: /api/v1/result (Caused by NewConnectionError('<urllib3.connection.HTTPConnection object at 0x7fd5000f91c0>: Failed to establish a new connection: [Errno 111] Connection refused'))
2023-06-12 15:13:41,549  ERROR       send_post.py  post_report  HTTPConnectionPool(host='localhost', port=8090): Max retries exceeded with url: /api/v1/result (Caused by NewConnectionError('<urllib3.connection.HTTPConnection object at 0x7fd50053ddf0>: Failed to establish a new connection: [Errno 111] Connection refused'))
2023-06-12 15:13:41,577  ERROR       send_post.py  post_report  HTTPConnectionPool(host='localhost', port=8090): Max retries exceeded with url: /api/v1/result (Caused by NewConnectionError('<urllib3.connection.HTTPConnection object at 0x7fd500573b20>: Failed to establish a new connection: [Errno 111] Connection refused'))
2023-06-12 15:13:41,616  ERROR       send_post.py  post_report  HTTPConnectionPool(host='localhost', port=8090): Max retries exceeded with url: /api/v1/result (Caused by NewConnectionError('<urllib3.connection.HTTPConnection object at 0x7fd500104c70>: Failed to establish a new connection: [Errno 111] Connection refused'))
2023-06-12 15:13:41,645  ERROR       send_post.py  post_report  HTTPConnectionPool(host='localhost', port=8090): Max retries exceeded with url: /api/v1/result (Caused by NewConnectionError('<urllib3.connection.HTTPConnection object at 0x7fd500573f40>: Failed to establish a new connection: [Errno 111] Connection refused'))
2023-06-12 15:13:41,672  ERROR       send_post.py  post_report  HTTPConnectionPool(host='localhost', port=8090): Max retries exceeded with url: /api/v1/result (Caused by NewConnectionError('<urllib3.connection.HTTPConnection object at 0x7fd5009638b0>: Failed to establish a new connection: [Errno 111] Connection refused'))
2023-06-12 15:13:41,699  ERROR       send_post.py  post_report  HTTPConnectionPool(host='localhost', port=8090): Max retries exceeded with url: /api/v1/result (Caused by NewConnectionError('<urllib3.connection.HTTPConnection object at 0x7fd5000f97f0>: Failed to establish a new connection: [Errno 111] Connection refused'))
2023-06-12 15:13:41,728  ERROR       send_post.py  post_report  HTTPConnectionPool(host='localhost', port=8090): Max retries exceeded with url: /api/v1/result (Caused by NewConnectionError('<urllib3.connection.HTTPConnection object at 0x7fd5001134c0>: Failed to establish a new connection: [Errno 111] Connection refused'))
2023-06-12 15:13:41,756  ERROR       send_post.py  post_report  HTTPConnectionPool(host='localhost', port=8090): Max retries exceeded with url: /api/v1/result (Caused by NewConnectionError('<urllib3.connection.HTTPConnection object at 0x7fd5000f96d0>: Failed to establish a new connection: [Errno 111] Connection refused'))
2023-06-12 15:14:57,917  ERROR       send_post.py  post_report  HTTPConnectionPool(host='localhost', port=8090): Max retries exceeded with url: /api/v1/result (Caused by NewConnectionError('<urllib3.connection.HTTPConnection object at 0x7f4111372190>: Failed to establish a new connection: [Errno 111] Connection refused'))
2023-06-12 15:14:57,944  ERROR       send_post.py  post_report  HTTPConnectionPool(host='localhost', port=8090): Max retries exceeded with url: /api/v1/result (Caused by NewConnectionError('<urllib3.connection.HTTPConnection object at 0x7f4111372bb0>: Failed to establish a new connection: [Errno 111] Connection refused'))
2023-06-12 15:14:57,971  ERROR       send_post.py  post_report  HTTPConnectionPool(host='localhost', port=8090): Max retries exceeded with url: /api/v1/result (Caused by NewConnectionError('<urllib3.connection.HTTPConnection object at 0x7f4111372100>: Failed to establish a new connection: [Errno 111] Connection refused'))
2023-06-12 15:14:57,999  ERROR       send_post.py  post_report  HTTPConnectionPool(host='localhost', port=8090): Max retries exceeded with url: /api/v1/result (Caused by NewConnectionError('<urllib3.connection.HTTPConnection object at 0x7f4110efa610>: Failed to establish a new connection: [Errno 111] Connection refused'))
2023-06-12 15:14:58,026  ERROR       send_post.py  post_report  HTTPConnectionPool(host='localhost', port=8090): Max retries exceeded with url: /api/v1/result (Caused by NewConnectionError('<urllib3.connection.HTTPConnection object at 0x7f4110f040a0>: Failed to establish a new connection: [Errno 111] Connection refused'))
2023-06-12 15:14:58,053  ERROR       send_post.py  post_report  HTTPConnectionPool(host='localhost', port=8090): Max retries exceeded with url: /api/v1/result (Caused by NewConnectionError('<urllib3.connection.HTTPConnection object at 0x7f4110f04a90>: Failed to establish a new connection: [Errno 111] Connection refused'))
2023-06-12 15:14:58,080  ERROR       send_post.py  post_report  HTTPConnectionPool(host='localhost', port=8090): Max retries exceeded with url: /api/v1/result (Caused by NewConnectionError('<urllib3.connection.HTTPConnection object at 0x7f4110efa3d0>: Failed to establish a new connection: [Errno 111] Connection refused'))
2023-06-12 15:14:58,110  ERROR       send_post.py  post_report  HTTPConnectionPool(host='localhost', port=8090): Max retries exceeded with url: /api/v1/result (Caused by NewConnectionError('<urllib3.connection.HTTPConnection object at 0x7f411133c610>: Failed to establish a new connection: [Errno 111] Connection refused'))
2023-06-12 15:14:58,136  ERROR       send_post.py  post_report  HTTPConnectionPool(host='localhost', port=8090): Max retries exceeded with url: /api/v1/result (Caused by NewConnectionError('<urllib3.connection.HTTPConnection object at 0x7f4111372b20>: Failed to establish a new connection: [Errno 111] Connection refused'))
2023-06-12 15:14:58,163  ERROR       send_post.py  post_report  HTTPConnectionPool(host='localhost', port=8090): Max retries exceeded with url: /api/v1/result (Caused by NewConnectionError('<urllib3.connection.HTTPConnection object at 0x7f4110f04c70>: Failed to establish a new connection: [Errno 111] Connection refused'))
2023-06-12 15:14:58,190  ERROR       send_post.py  post_report  HTTPConnectionPool(host='localhost', port=8090): Max retries exceeded with url: /api/v1/result (Caused by NewConnectionError('<urllib3.connection.HTTPConnection object at 0x7f4111372f40>: Failed to establish a new connection: [Errno 111] Connection refused'))
2023-06-12 15:14:58,220  ERROR       send_post.py  post_report  HTTPConnectionPool(host='localhost', port=8090): Max retries exceeded with url: /api/v1/result (Caused by NewConnectionError('<urllib3.connection.HTTPConnection object at 0x7f41117638b0>: Failed to establish a new connection: [Errno 111] Connection refused'))
2023-06-12 15:15:45,673  ERROR       send_post.py  post_report  HTTPConnectionPool(host='localhost', port=8090): Max retries exceeded with url: /api/v1/result (Caused by NewConnectionError('<urllib3.connection.HTTPConnection object at 0x7f2591972190>: Failed to establish a new connection: [Errno 111] Connection refused'))
2023-06-12 15:15:45,701  ERROR       send_post.py  post_report  HTTPConnectionPool(host='localhost', port=8090): Max retries exceeded with url: /api/v1/result (Caused by NewConnectionError('<urllib3.connection.HTTPConnection object at 0x7f2591972bb0>: Failed to establish a new connection: [Errno 111] Connection refused'))
2023-06-12 15:15:45,735  ERROR       send_post.py  post_report  HTTPConnectionPool(host='localhost', port=8090): Max retries exceeded with url: /api/v1/result (Caused by NewConnectionError('<urllib3.connection.HTTPConnection object at 0x7f2591972100>: Failed to establish a new connection: [Errno 111] Connection refused'))
2023-06-12 15:15:45,770  ERROR       send_post.py  post_report  HTTPConnectionPool(host='localhost', port=8090): Max retries exceeded with url: /api/v1/result (Caused by NewConnectionError('<urllib3.connection.HTTPConnection object at 0x7f25914fa610>: Failed to establish a new connection: [Errno 111] Connection refused'))
2023-06-12 15:15:45,802  ERROR       send_post.py  post_report  HTTPConnectionPool(host='localhost', port=8090): Max retries exceeded with url: /api/v1/result (Caused by NewConnectionError('<urllib3.connection.HTTPConnection object at 0x7f259150a0a0>: Failed to establish a new connection: [Errno 111] Connection refused'))
2023-06-12 15:15:45,835  ERROR       send_post.py  post_report  HTTPConnectionPool(host='localhost', port=8090): Max retries exceeded with url: /api/v1/result (Caused by NewConnectionError('<urllib3.connection.HTTPConnection object at 0x7f259150aa90>: Failed to establish a new connection: [Errno 111] Connection refused'))
2023-06-12 15:15:45,868  ERROR       send_post.py  post_report  HTTPConnectionPool(host='localhost', port=8090): Max retries exceeded with url: /api/v1/result (Caused by NewConnectionError('<urllib3.connection.HTTPConnection object at 0x7f25914fa400>: Failed to establish a new connection: [Errno 111] Connection refused'))
2023-06-12 15:15:45,897  ERROR       send_post.py  post_report  HTTPConnectionPool(host='localhost', port=8090): Max retries exceeded with url: /api/v1/result (Caused by NewConnectionError('<urllib3.connection.HTTPConnection object at 0x7f259193d610>: Failed to establish a new connection: [Errno 111] Connection refused'))
2023-06-12 15:15:45,931  ERROR       send_post.py  post_report  HTTPConnectionPool(host='localhost', port=8090): Max retries exceeded with url: /api/v1/result (Caused by NewConnectionError('<urllib3.connection.HTTPConnection object at 0x7f2591972b20>: Failed to establish a new connection: [Errno 111] Connection refused'))
2023-06-12 15:15:45,967  ERROR       send_post.py  post_report  HTTPConnectionPool(host='localhost', port=8090): Max retries exceeded with url: /api/v1/result (Caused by NewConnectionError('<urllib3.connection.HTTPConnection object at 0x7f259150ac70>: Failed to establish a new connection: [Errno 111] Connection refused'))
2023-06-12 15:15:46,002  ERROR       send_post.py  post_report  HTTPConnectionPool(host='localhost', port=8090): Max retries exceeded with url: /api/v1/result (Caused by NewConnectionError('<urllib3.connection.HTTPConnection object at 0x7f2591972f40>: Failed to establish a new connection: [Errno 111] Connection refused'))
2023-06-12 15:15:46,056  ERROR       send_post.py  post_report  HTTPConnectionPool(host='localhost', port=8090): Max retries exceeded with url: /api/v1/result (Caused by NewConnectionError('<urllib3.connection.HTTPConnection object at 0x7f2591d64b20>: Failed to establish a new connection: [Errno 111] Connection refused'))
2023-06-12 15:15:46,084  ERROR       send_post.py  post_report  HTTPConnectionPool(host='localhost', port=8090): Max retries exceeded with url: /api/v1/result (Caused by NewConnectionError('<urllib3.connection.HTTPConnection object at 0x7f25914fa7f0>: Failed to establish a new connection: [Errno 111] Connection refused'))
2023-06-12 15:15:46,114  ERROR       send_post.py  post_report  HTTPConnectionPool(host='localhost', port=8090): Max retries exceeded with url: /api/v1/result (Caused by NewConnectionError('<urllib3.connection.HTTPConnection object at 0x7f25915124c0>: Failed to establish a new connection: [Errno 111] Connection refused'))
2023-06-12 15:16:24,785  ERROR       send_post.py  post_report  HTTPConnectionPool(host='localhost', port=8090): Max retries exceeded with url: /api/v1/result (Caused by NewConnectionError('<urllib3.connection.HTTPConnection object at 0x7f7143d72190>: Failed to establish a new connection: [Errno 111] Connection refused'))
2023-06-12 15:16:24,813  ERROR       send_post.py  post_report  HTTPConnectionPool(host='localhost', port=8090): Max retries exceeded with url: /api/v1/result (Caused by NewConnectionError('<urllib3.connection.HTTPConnection object at 0x7f7143d72bb0>: Failed to establish a new connection: [Errno 111] Connection refused'))
2023-06-12 15:16:24,850  ERROR       send_post.py  post_report  HTTPConnectionPool(host='localhost', port=8090): Max retries exceeded with url: /api/v1/result (Caused by NewConnectionError('<urllib3.connection.HTTPConnection object at 0x7f7143d72100>: Failed to establish a new connection: [Errno 111] Connection refused'))
2023-06-12 15:16:24,886  ERROR       send_post.py  post_report  HTTPConnectionPool(host='localhost', port=8090): Max retries exceeded with url: /api/v1/result (Caused by NewConnectionError('<urllib3.connection.HTTPConnection object at 0x7f71438f9610>: Failed to establish a new connection: [Errno 111] Connection refused'))
2023-06-12 15:16:24,913  ERROR       send_post.py  post_report  HTTPConnectionPool(host='localhost', port=8090): Max retries exceeded with url: /api/v1/result (Caused by NewConnectionError('<urllib3.connection.HTTPConnection object at 0x7f71439040a0>: Failed to establish a new connection: [Errno 111] Connection refused'))
2023-06-12 15:16:24,940  ERROR       send_post.py  post_report  HTTPConnectionPool(host='localhost', port=8090): Max retries exceeded with url: /api/v1/result (Caused by NewConnectionError('<urllib3.connection.HTTPConnection object at 0x7f7143904a90>: Failed to establish a new connection: [Errno 111] Connection refused'))
2023-06-12 15:16:24,976  ERROR       send_post.py  post_report  HTTPConnectionPool(host='localhost', port=8090): Max retries exceeded with url: /api/v1/result (Caused by NewConnectionError('<urllib3.connection.HTTPConnection object at 0x7f71438f9400>: Failed to establish a new connection: [Errno 111] Connection refused'))
2023-07-18 14:54:40,667  ERROR       send_post.py  post_report  HTTPConnectionPool(host='localhost', port=8090): Max retries exceeded with url: /api/v1/result (Caused by NewConnectionError('<urllib3.connection.HTTPConnection object at 0x7fec4a5489a0>: Failed to establish a new connection: [Errno 111] Connection refused'))
2023-07-18 14:54:40,692  ERROR       send_post.py  post_report  HTTPConnectionPool(host='localhost', port=8090): Max retries exceeded with url: /api/v1/result (Caused by NewConnectionError('<urllib3.connection.HTTPConnection object at 0x7fec4a13d460>: Failed to establish a new connection: [Errno 111] Connection refused'))
2023-07-18 14:54:40,722  ERROR       send_post.py  post_report  HTTPConnectionPool(host='localhost', port=8090): Max retries exceeded with url: /api/v1/result (Caused by NewConnectionError('<urllib3.connection.HTTPConnection object at 0x7fec4a13d520>: Failed to establish a new connection: [Errno 111] Connection refused'))
2023-07-18 14:54:40,751  ERROR       send_post.py  post_report  HTTPConnectionPool(host='localhost', port=8090): Max retries exceeded with url: /api/v1/result (Caused by NewConnectionError('<urllib3.connection.HTTPConnection object at 0x7fec4a13de80>: Failed to establish a new connection: [Errno 111] Connection refused'))
2023-07-18 14:54:40,785  ERROR       send_post.py  post_report  HTTPConnectionPool(host='localhost', port=8090): Max retries exceeded with url: /api/v1/result (Caused by NewConnectionError('<urllib3.connection.HTTPConnection object at 0x7fec4a1438e0>: Failed to establish a new connection: [Errno 111] Connection refused'))
2023-07-18 14:54:40,816  ERROR       send_post.py  post_report  HTTPConnectionPool(host='localhost', port=8090): Max retries exceeded with url: /api/v1/result (Caused by NewConnectionError('<urllib3.connection.HTTPConnection object at 0x7fec4a159340>: Failed to establish a new connection: [Errno 111] Connection refused'))
2023-07-18 14:54:40,844  ERROR       send_post.py  post_report  HTTPConnectionPool(host='localhost', port=8090): Max retries exceeded with url: /api/v1/result (Caused by NewConnectionError('<urllib3.connection.HTTPConnection object at 0x7fec4a9378e0>: Failed to establish a new connection: [Errno 111] Connection refused'))
2023-07-18 14:54:40,876  ERROR       send_post.py  post_report  HTTPConnectionPool(host='localhost', port=8090): Max retries exceeded with url: /api/v1/result (Caused by NewConnectionError('<urllib3.connection.HTTPConnection object at 0x7fec4a548d30>: Failed to establish a new connection: [Errno 111] Connection refused'))
2023-07-18 14:54:40,904  ERROR       send_post.py  post_report  HTTPConnectionPool(host='localhost', port=8090): Max retries exceeded with url: /api/v1/result (Caused by NewConnectionError('<urllib3.connection.HTTPConnection object at 0x7fec4a13d8e0>: Failed to establish a new connection: [Errno 111] Connection refused'))
2023-07-18 14:54:40,932  ERROR       send_post.py  post_report  HTTPConnectionPool(host='localhost', port=8090): Max retries exceeded with url: /api/v1/result (Caused by NewConnectionError('<urllib3.connection.HTTPConnection object at 0x7fec4a159400>: Failed to establish a new connection: [Errno 111] Connection refused'))
2023-07-18 14:54:40,959  ERROR       send_post.py  post_report  HTTPConnectionPool(host='localhost', port=8090): Max retries exceeded with url: /api/v1/result (Caused by NewConnectionError('<urllib3.connection.HTTPConnection object at 0x7fec4a13d8b0>: Failed to establish a new connection: [Errno 111] Connection refused'))
2023-07-18 14:54:40,993  ERROR       send_post.py  post_report  HTTPConnectionPool(host='localhost', port=8090): Max retries exceeded with url: /api/v1/result (Caused by NewConnectionError('<urllib3.connection.HTTPConnection object at 0x7fec4a548790>: Failed to establish a new connection: [Errno 111] Connection refused'))
2023-07-18 14:57:52,583  ERROR       send_post.py  post_report  HTTPConnectionPool(host='localhost', port=8090): Max retries exceeded with url: /api/v1/result (Caused by NewConnectionError('<urllib3.connection.HTTPConnection object at 0x7f2da21089a0>: Failed to establish a new connection: [Errno 111] Connection refused'))
2023-07-18 14:57:52,703  ERROR       send_post.py  post_report  HTTPConnectionPool(host='localhost', port=8090): Max retries exceeded with url: /api/v1/result (Caused by NewConnectionError('<urllib3.connection.HTTPConnection object at 0x7f2da1d3d580>: Failed to establish a new connection: [Errno 111] Connection refused'))
2023-07-18 14:57:52,721  ERROR       send_post.py  post_report  HTTPConnectionPool(host='localhost', port=8090): Max retries exceeded with url: /api/v1/result (Caused by NewConnectionError('<urllib3.connection.HTTPConnection object at 0x7f2da1d3d130>: Failed to establish a new connection: [Errno 111] Connection refused'))
2023-07-18 14:57:52,739  ERROR       send_post.py  post_report  HTTPConnectionPool(host='localhost', port=8090): Max retries exceeded with url: /api/v1/result (Caused by NewConnectionError('<urllib3.connection.HTTPConnection object at 0x7f2da1d3dfa0>: Failed to establish a new connection: [Errno 111] Connection refused'))
2023-07-18 14:57:52,756  ERROR       send_post.py  post_report  HTTPConnectionPool(host='localhost', port=8090): Max retries exceeded with url: /api/v1/result (Caused by NewConnectionError('<urllib3.connection.HTTPConnection object at 0x7f2da1d488e0>: Failed to establish a new connection: [Errno 111] Connection refused'))
2023-07-18 14:57:52,773  ERROR       send_post.py  post_report  HTTPConnectionPool(host='localhost', port=8090): Max retries exceeded with url: /api/v1/result (Caused by NewConnectionError('<urllib3.connection.HTTPConnection object at 0x7f2da1d53370>: Failed to establish a new connection: [Errno 111] Connection refused'))
2023-07-18 14:57:52,788  ERROR       send_post.py  post_report  HTTPConnectionPool(host='localhost', port=8090): Max retries exceeded with url: /api/v1/result (Caused by NewConnectionError('<urllib3.connection.HTTPConnection object at 0x7f2da1d3dd90>: Failed to establish a new connection: [Errno 111] Connection refused'))
2023-07-18 14:57:52,806  ERROR       send_post.py  post_report  HTTPConnectionPool(host='localhost', port=8090): Max retries exceeded with url: /api/v1/result (Caused by NewConnectionError('<urllib3.connection.HTTPConnection object at 0x7f2da2173070>: Failed to establish a new connection: [Errno 111] Connection refused'))
2023-07-18 14:57:52,822  ERROR       send_post.py  post_report  HTTPConnectionPool(host='localhost', port=8090): Max retries exceeded with url: /api/v1/result (Caused by NewConnectionError('<urllib3.connection.HTTPConnection object at 0x7f2da1d53190>: Failed to establish a new connection: [Errno 111] Connection refused'))
2023-07-18 14:57:52,840  ERROR       send_post.py  post_report  HTTPConnectionPool(host='localhost', port=8090): Max retries exceeded with url: /api/v1/result (Caused by NewConnectionError('<urllib3.connection.HTTPConnection object at 0x7f2da1d53e80>: Failed to establish a new connection: [Errno 111] Connection refused'))
2023-07-18 14:57:52,856  ERROR       send_post.py  post_report  HTTPConnectionPool(host='localhost', port=8090): Max retries exceeded with url: /api/v1/result (Caused by NewConnectionError('<urllib3.connection.HTTPConnection object at 0x7f2da1d536a0>: Failed to establish a new connection: [Errno 111] Connection refused'))
2023-07-18 14:57:52,874  ERROR       send_post.py  post_report  HTTPConnectionPool(host='localhost', port=8090): Max retries exceeded with url: /api/v1/result (Caused by NewConnectionError('<urllib3.connection.HTTPConnection object at 0x7f2da2173340>: Failed to establish a new connection: [Errno 111] Connection refused'))
2023-07-26 09:51:10,193  ERROR       send_post.py  post_report  HTTPConnectionPool(host='localhost', port=8090): Max retries exceeded with url: /api/v1/result (Caused by NewConnectionError('<urllib3.connection.HTTPConnection object at 0x7f3fe77499a0>: Failed to establish a new connection: [Errno 111] Connection refused'))
2023-07-26 09:51:10,240  ERROR       send_post.py  post_report  HTTPConnectionPool(host='localhost', port=8090): Max retries exceeded with url: /api/v1/result (Caused by NewConnectionError('<urllib3.connection.HTTPConnection object at 0x7f3fe7703460>: Failed to establish a new connection: [Errno 111] Connection refused'))
2023-07-26 09:51:10,285  ERROR       send_post.py  post_report  HTTPConnectionPool(host='localhost', port=8090): Max retries exceeded with url: /api/v1/result (Caused by NewConnectionError('<urllib3.connection.HTTPConnection object at 0x7f3fe7703340>: Failed to establish a new connection: [Errno 111] Connection refused'))
2023-07-26 09:51:10,335  ERROR       send_post.py  post_report  HTTPConnectionPool(host='localhost', port=8090): Max retries exceeded with url: /api/v1/result (Caused by NewConnectionError('<urllib3.connection.HTTPConnection object at 0x7f3fe7703fa0>: Failed to establish a new connection: [Errno 111] Connection refused'))
2023-07-26 09:51:10,373  ERROR       send_post.py  post_report  HTTPConnectionPool(host='localhost', port=8090): Max retries exceeded with url: /api/v1/result (Caused by NewConnectionError('<urllib3.connection.HTTPConnection object at 0x7f3fe770ba00>: Failed to establish a new connection: [Errno 111] Connection refused'))
2023-07-26 09:51:10,418  ERROR       send_post.py  post_report  HTTPConnectionPool(host='localhost', port=8090): Max retries exceeded with url: /api/v1/result (Caused by NewConnectionError('<urllib3.connection.HTTPConnection object at 0x7f3fe7719370>: Failed to establish a new connection: [Errno 111] Connection refused'))
2023-07-26 09:51:10,466  ERROR       send_post.py  post_report  HTTPConnectionPool(host='localhost', port=8090): Max retries exceeded with url: /api/v1/result (Caused by NewConnectionError('<urllib3.connection.HTTPConnection object at 0x7f3fe7703a60>: Failed to establish a new connection: [Errno 111] Connection refused'))
2023-07-26 09:51:10,512  ERROR       send_post.py  post_report  HTTPConnectionPool(host='localhost', port=8090): Max retries exceeded with url: /api/v1/result (Caused by NewConnectionError('<urllib3.connection.HTTPConnection object at 0x7f3fe7a75430>: Failed to establish a new connection: [Errno 111] Connection refused'))
2023-07-26 09:51:10,558  ERROR       send_post.py  post_report  HTTPConnectionPool(host='localhost', port=8090): Max retries exceeded with url: /api/v1/result (Caused by NewConnectionError('<urllib3.connection.HTTPConnection object at 0x7f3fe7719190>: Failed to establish a new connection: [Errno 111] Connection refused'))
2023-07-26 09:54:31,589  ERROR       send_post.py  post_report  HTTPConnectionPool(host='localhost', port=8090): Max retries exceeded with url: /api/v1/result (Caused by NewConnectionError('<urllib3.connection.HTTPConnection object at 0x7f437bafb970>: Failed to establish a new connection: [Errno 111] Connection refused'))
2023-07-26 09:54:31,633  ERROR       send_post.py  post_report  HTTPConnectionPool(host='localhost', port=8090): Max retries exceeded with url: /api/v1/result (Caused by NewConnectionError('<urllib3.connection.HTTPConnection object at 0x7f437bab6580>: Failed to establish a new connection: [Errno 111] Connection refused'))
2023-07-26 09:54:31,678  ERROR       send_post.py  post_report  HTTPConnectionPool(host='localhost', port=8090): Max retries exceeded with url: /api/v1/result (Caused by NewConnectionError('<urllib3.connection.HTTPConnection object at 0x7f437bab6550>: Failed to establish a new connection: [Errno 111] Connection refused'))
2023-07-26 09:54:31,723  ERROR       send_post.py  post_report  HTTPConnectionPool(host='localhost', port=8090): Max retries exceeded with url: /api/v1/result (Caused by NewConnectionError('<urllib3.connection.HTTPConnection object at 0x7f437bab6e80>: Failed to establish a new connection: [Errno 111] Connection refused'))
2023-07-26 09:54:31,761  ERROR       send_post.py  post_report  HTTPConnectionPool(host='localhost', port=8090): Max retries exceeded with url: /api/v1/result (Caused by NewConnectionError('<urllib3.connection.HTTPConnection object at 0x7f437bac08e0>: Failed to establish a new connection: [Errno 111] Connection refused'))
2023-07-26 09:54:31,804  ERROR       send_post.py  post_report  HTTPConnectionPool(host='localhost', port=8090): Max retries exceeded with url: /api/v1/result (Caused by NewConnectionError('<urllib3.connection.HTTPConnection object at 0x7f437bacb370>: Failed to establish a new connection: [Errno 111] Connection refused'))
2023-07-26 09:54:31,850  ERROR       send_post.py  post_report  HTTPConnectionPool(host='localhost', port=8090): Max retries exceeded with url: /api/v1/result (Caused by NewConnectionError('<urllib3.connection.HTTPConnection object at 0x7f437bab6b50>: Failed to establish a new connection: [Errno 111] Connection refused'))
2023-07-26 09:54:31,894  ERROR       send_post.py  post_report  HTTPConnectionPool(host='localhost', port=8090): Max retries exceeded with url: /api/v1/result (Caused by NewConnectionError('<urllib3.connection.HTTPConnection object at 0x7f437bf6d700>: Failed to establish a new connection: [Errno 111] Connection refused'))
2023-07-26 09:54:31,940  ERROR       send_post.py  post_report  HTTPConnectionPool(host='localhost', port=8090): Max retries exceeded with url: /api/v1/result (Caused by NewConnectionError('<urllib3.connection.HTTPConnection object at 0x7f437bacb190>: Failed to establish a new connection: [Errno 111] Connection refused'))
2023-07-26 09:56:51,935  ERROR       send_post.py  post_report  HTTPConnectionPool(host='localhost', port=8090): Max retries exceeded with url: /api/v1/result (Caused by NewConnectionError('<urllib3.connection.HTTPConnection object at 0x7f3229f43970>: Failed to establish a new connection: [Errno 111] Connection refused'))
2023-07-26 09:56:52,123  ERROR       send_post.py  post_report  HTTPConnectionPool(host='localhost', port=8090): Max retries exceeded with url: /api/v1/result (Caused by NewConnectionError('<urllib3.connection.HTTPConnection object at 0x7f3229af5460>: Failed to establish a new connection: [Errno 111] Connection refused'))
2023-07-26 09:56:52,169  ERROR       send_post.py  post_report  HTTPConnectionPool(host='localhost', port=8090): Max retries exceeded with url: /api/v1/result (Caused by NewConnectionError('<urllib3.connection.HTTPConnection object at 0x7f3229af5490>: Failed to establish a new connection: [Errno 111] Connection refused'))
2023-07-26 09:56:52,215  ERROR       send_post.py  post_report  HTTPConnectionPool(host='localhost', port=8090): Max retries exceeded with url: /api/v1/result (Caused by NewConnectionError('<urllib3.connection.HTTPConnection object at 0x7f3229af5e80>: Failed to establish a new connection: [Errno 111] Connection refused'))
2023-07-26 09:56:52,315  ERROR       send_post.py  post_report  HTTPConnectionPool(host='localhost', port=8090): Max retries exceeded with url: /api/v1/result (Caused by NewConnectionError('<urllib3.connection.HTTPConnection object at 0x7f3229b008e0>: Failed to establish a new connection: [Errno 111] Connection refused'))
2023-07-26 09:56:52,409  ERROR       send_post.py  post_report  HTTPConnectionPool(host='localhost', port=8090): Max retries exceeded with url: /api/v1/result (Caused by NewConnectionError('<urllib3.connection.HTTPConnection object at 0x7f3229b0f370>: Failed to establish a new connection: [Errno 111] Connection refused'))
2023-07-26 09:56:52,455  ERROR       send_post.py  post_report  HTTPConnectionPool(host='localhost', port=8090): Max retries exceeded with url: /api/v1/result (Caused by NewConnectionError('<urllib3.connection.HTTPConnection object at 0x7f322a3737c0>: Failed to establish a new connection: [Errno 111] Connection refused'))
2023-07-26 09:58:29,235  ERROR       send_post.py  post_report  HTTPConnectionPool(host='localhost', port=8090): Max retries exceeded with url: /api/v1/result (Caused by NewConnectionError('<urllib3.connection.HTTPConnection object at 0x7f3bd2d09970>: Failed to establish a new connection: [Errno 111] Connection refused'))
2023-07-26 09:58:29,283  ERROR       send_post.py  post_report  HTTPConnectionPool(host='localhost', port=8090): Max retries exceeded with url: /api/v1/result (Caused by NewConnectionError('<urllib3.connection.HTTPConnection object at 0x7f3bd2943460>: Failed to establish a new connection: [Errno 111] Connection refused'))
2023-07-26 09:58:29,328  ERROR       send_post.py  post_report  HTTPConnectionPool(host='localhost', port=8090): Max retries exceeded with url: /api/v1/result (Caused by NewConnectionError('<urllib3.connection.HTTPConnection object at 0x7f3bd2943490>: Failed to establish a new connection: [Errno 111] Connection refused'))
2023-07-26 09:58:29,462  ERROR       send_post.py  post_report  HTTPConnectionPool(host='localhost', port=8090): Max retries exceeded with url: /api/v1/result (Caused by NewConnectionError('<urllib3.connection.HTTPConnection object at 0x7f3bd2943e80>: Failed to establish a new connection: [Errno 111] Connection refused'))
2023-07-26 09:58:29,500  ERROR       send_post.py  post_report  HTTPConnectionPool(host='localhost', port=8090): Max retries exceeded with url: /api/v1/result (Caused by NewConnectionError('<urllib3.connection.HTTPConnection object at 0x7f3bd294f8e0>: Failed to establish a new connection: [Errno 111] Connection refused'))
2023-07-26 09:58:29,545  ERROR       send_post.py  post_report  HTTPConnectionPool(host='localhost', port=8090): Max retries exceeded with url: /api/v1/result (Caused by NewConnectionError('<urllib3.connection.HTTPConnection object at 0x7f3bd2959370>: Failed to establish a new connection: [Errno 111] Connection refused'))
2023-07-26 09:58:29,593  ERROR       send_post.py  post_report  HTTPConnectionPool(host='localhost', port=8090): Max retries exceeded with url: /api/v1/result (Caused by NewConnectionError('<urllib3.connection.HTTPConnection object at 0x7f3bd2943c10>: Failed to establish a new connection: [Errno 111] Connection refused'))
2023-07-26 09:58:29,639  ERROR       send_post.py  post_report  HTTPConnectionPool(host='localhost', port=8090): Max retries exceeded with url: /api/v1/result (Caused by NewConnectionError('<urllib3.connection.HTTPConnection object at 0x7f3bd2d75a90>: Failed to establish a new connection: [Errno 111] Connection refused'))
2023-07-26 09:58:29,686  ERROR       send_post.py  post_report  HTTPConnectionPool(host='localhost', port=8090): Max retries exceeded with url: /api/v1/result (Caused by NewConnectionError('<urllib3.connection.HTTPConnection object at 0x7f3bd2959190>: Failed to establish a new connection: [Errno 111] Connection refused'))
2023-07-26 09:59:17,707  ERROR       send_post.py  post_report  HTTPConnectionPool(host='localhost', port=8090): Max retries exceeded with url: /api/v1/result (Caused by NewConnectionError('<urllib3.connection.HTTPConnection object at 0x7f7b22f099a0>: Failed to establish a new connection: [Errno 111] Connection refused'))
2023-07-26 09:59:17,815  ERROR       send_post.py  post_report  HTTPConnectionPool(host='localhost', port=8090): Max retries exceeded with url: /api/v1/result (Caused by NewConnectionError('<urllib3.connection.HTTPConnection object at 0x7f7b22b3e460>: Failed to establish a new connection: [Errno 111] Connection refused'))
2023-07-26 09:59:17,861  ERROR       send_post.py  post_report  HTTPConnectionPool(host='localhost', port=8090): Max retries exceeded with url: /api/v1/result (Caused by NewConnectionError('<urllib3.connection.HTTPConnection object at 0x7f7b22b3e190>: Failed to establish a new connection: [Errno 111] Connection refused'))
2023-07-26 09:59:17,906  ERROR       send_post.py  post_report  HTTPConnectionPool(host='localhost', port=8090): Max retries exceeded with url: /api/v1/result (Caused by NewConnectionError('<urllib3.connection.HTTPConnection object at 0x7f7b22b3efa0>: Failed to establish a new connection: [Errno 111] Connection refused'))
2023-07-26 09:59:17,954  ERROR       send_post.py  post_report  HTTPConnectionPool(host='localhost', port=8090): Max retries exceeded with url: /api/v1/result (Caused by NewConnectionError('<urllib3.connection.HTTPConnection object at 0x7f7b22b48a00>: Failed to establish a new connection: [Errno 111] Connection refused'))
2023-07-26 09:59:17,996  ERROR       send_post.py  post_report  HTTPConnectionPool(host='localhost', port=8090): Max retries exceeded with url: /api/v1/result (Caused by NewConnectionError('<urllib3.connection.HTTPConnection object at 0x7f7b22b53370>: Failed to establish a new connection: [Errno 111] Connection refused'))
2023-07-26 09:59:18,039  ERROR       send_post.py  post_report  HTTPConnectionPool(host='localhost', port=8090): Max retries exceeded with url: /api/v1/result (Caused by NewConnectionError('<urllib3.connection.HTTPConnection object at 0x7f7b22b3ed90>: Failed to establish a new connection: [Errno 111] Connection refused'))
2023-07-26 09:59:29,018  ERROR       send_post.py  post_report  HTTPConnectionPool(host='localhost', port=8090): Max retries exceeded with url: /api/v1/result (Caused by NewConnectionError('<urllib3.connection.HTTPConnection object at 0x7f7e70549970>: Failed to establish a new connection: [Errno 111] Connection refused'))
2023-07-26 09:59:29,063  ERROR       send_post.py  post_report  HTTPConnectionPool(host='localhost', port=8090): Max retries exceeded with url: /api/v1/result (Caused by NewConnectionError('<urllib3.connection.HTTPConnection object at 0x7f7e7013d460>: Failed to establish a new connection: [Errno 111] Connection refused'))
2023-07-26 09:59:29,108  ERROR       send_post.py  post_report  HTTPConnectionPool(host='localhost', port=8090): Max retries exceeded with url: /api/v1/result (Caused by NewConnectionError('<urllib3.connection.HTTPConnection object at 0x7f7e7013d490>: Failed to establish a new connection: [Errno 111] Connection refused'))
2023-07-26 09:59:29,154  ERROR       send_post.py  post_report  HTTPConnectionPool(host='localhost', port=8090): Max retries exceeded with url: /api/v1/result (Caused by NewConnectionError('<urllib3.connection.HTTPConnection object at 0x7f7e7013de80>: Failed to establish a new connection: [Errno 111] Connection refused'))
2023-07-26 09:59:29,191  ERROR       send_post.py  post_report  HTTPConnectionPool(host='localhost', port=8090): Max retries exceeded with url: /api/v1/result (Caused by NewConnectionError('<urllib3.connection.HTTPConnection object at 0x7f7e701498e0>: Failed to establish a new connection: [Errno 111] Connection refused'))
2023-07-26 09:59:29,235  ERROR       send_post.py  post_report  HTTPConnectionPool(host='localhost', port=8090): Max retries exceeded with url: /api/v1/result (Caused by NewConnectionError('<urllib3.connection.HTTPConnection object at 0x7f7e70153370>: Failed to establish a new connection: [Errno 111] Connection refused'))
2023-07-26 09:59:29,281  ERROR       send_post.py  post_report  HTTPConnectionPool(host='localhost', port=8090): Max retries exceeded with url: /api/v1/result (Caused by NewConnectionError('<urllib3.connection.HTTPConnection object at 0x7f7e7013ddc0>: Failed to establish a new connection: [Errno 111] Connection refused'))
2023-07-26 09:59:29,327  ERROR       send_post.py  post_report  HTTPConnectionPool(host='localhost', port=8090): Max retries exceeded with url: /api/v1/result (Caused by NewConnectionError('<urllib3.connection.HTTPConnection object at 0x7f7e709378e0>: Failed to establish a new connection: [Errno 111] Connection refused'))
2023-07-26 09:59:29,416  ERROR       send_post.py  post_report  HTTPConnectionPool(host='localhost', port=8090): Max retries exceeded with url: /api/v1/result (Caused by NewConnectionError('<urllib3.connection.HTTPConnection object at 0x7f7e70153190>: Failed to establish a new connection: [Errno 111] Connection refused'))
2023-07-26 15:03:07,887  ERROR       send_post.py  post_report  HTTPConnectionPool(host='localhost', port=8090): Max retries exceeded with url: /api/v1/result (Caused by NewConnectionError('<urllib3.connection.HTTPConnection object at 0x7f6b2c4fca30>: Failed to establish a new connection: [Errno 111] Connection refused'))
2023-07-26 15:03:08,046  ERROR       send_post.py  post_report  HTTPConnectionPool(host='localhost', port=8090): Max retries exceeded with url: /api/v1/result (Caused by NewConnectionError('<urllib3.connection.HTTPConnection object at 0x7f6b2c4b64f0>: Failed to establish a new connection: [Errno 111] Connection refused'))
2023-07-26 15:03:08,118  ERROR       send_post.py  post_report  HTTPConnectionPool(host='localhost', port=8090): Max retries exceeded with url: /api/v1/result (Caused by NewConnectionError('<urllib3.connection.HTTPConnection object at 0x7f6b2c4b6580>: Failed to establish a new connection: [Errno 111] Connection refused'))
2023-07-26 15:03:08,173  ERROR       send_post.py  post_report  HTTPConnectionPool(host='localhost', port=8090): Max retries exceeded with url: /api/v1/result (Caused by NewConnectionError('<urllib3.connection.HTTPConnection object at 0x7f6b2c4b6f70>: Failed to establish a new connection: [Errno 111] Connection refused'))
2023-07-26 15:03:08,234  ERROR       send_post.py  post_report  HTTPConnectionPool(host='localhost', port=8090): Max retries exceeded with url: /api/v1/result (Caused by NewConnectionError('<urllib3.connection.HTTPConnection object at 0x7f6b2c4c0970>: Failed to establish a new connection: [Errno 111] Connection refused'))
2023-07-26 15:03:08,297  ERROR       send_post.py  post_report  HTTPConnectionPool(host='localhost', port=8090): Max retries exceeded with url: /api/v1/result (Caused by NewConnectionError('<urllib3.connection.HTTPConnection object at 0x7f6b2c4d13d0>: Failed to establish a new connection: [Errno 111] Connection refused'))
2023-07-26 15:03:08,360  ERROR       send_post.py  post_report  HTTPConnectionPool(host='localhost', port=8090): Max retries exceeded with url: /api/v1/result (Caused by NewConnectionError('<urllib3.connection.HTTPConnection object at 0x7f6b2c96d850>: Failed to establish a new connection: [Errno 111] Connection refused'))
2023-07-26 15:03:08,538  ERROR       send_post.py  post_report  HTTPConnectionPool(host='localhost', port=8090): Max retries exceeded with url: /api/v1/result (Caused by NewConnectionError('<urllib3.connection.HTTPConnection object at 0x7f6b2c4fcca0>: Failed to establish a new connection: [Errno 111] Connection refused'))
2023-07-26 15:03:08,717  ERROR       send_post.py  post_report  HTTPConnectionPool(host='localhost', port=8090): Max retries exceeded with url: /api/v1/result (Caused by NewConnectionError('<urllib3.connection.HTTPConnection object at 0x7f6b2c4b6b50>: Failed to establish a new connection: [Errno 111] Connection refused'))
2023-07-26 15:03:08,782  ERROR       send_post.py  post_report  HTTPConnectionPool(host='localhost', port=8090): Max retries exceeded with url: /api/v1/result (Caused by NewConnectionError('<urllib3.connection.HTTPConnection object at 0x7f6b2c4d15e0>: Failed to establish a new connection: [Errno 111] Connection refused'))
2023-07-27 14:27:19,041  ERROR       send_post.py  post_report  HTTPConnectionPool(host='localhost', port=8090): Max retries exceeded with url: /api/v1/result (Caused by NewConnectionError('<urllib3.connection.HTTPConnection object at 0x7ff9395019d0>: Failed to establish a new connection: [Errno 111] Connection refused'))
2023-07-27 14:27:19,165  ERROR       send_post.py  post_report  HTTPConnectionPool(host='localhost', port=8090): Max retries exceeded with url: /api/v1/result (Caused by NewConnectionError('<urllib3.connection.HTTPConnection object at 0x7ff9394bb4c0>: Failed to establish a new connection: [Errno 111] Connection refused'))
2023-07-27 14:27:19,215  ERROR       send_post.py  post_report  HTTPConnectionPool(host='localhost', port=8090): Max retries exceeded with url: /api/v1/result (Caused by NewConnectionError('<urllib3.connection.HTTPConnection object at 0x7ff9394bb370>: Failed to establish a new connection: [Errno 111] Connection refused'))
2023-07-27 14:27:19,274  ERROR       send_post.py  post_report  HTTPConnectionPool(host='localhost', port=8090): Max retries exceeded with url: /api/v1/result (Caused by NewConnectionError('<urllib3.connection.HTTPConnection object at 0x7ff9394bbfd0>: Failed to establish a new connection: [Errno 111] Connection refused'))
2023-07-27 14:27:19,320  ERROR       send_post.py  post_report  HTTPConnectionPool(host='localhost', port=8090): Max retries exceeded with url: /api/v1/result (Caused by NewConnectionError('<urllib3.connection.HTTPConnection object at 0x7ff9394c5a30>: Failed to establish a new connection: [Errno 111] Connection refused'))
2023-07-27 14:27:19,394  ERROR       send_post.py  post_report  HTTPConnectionPool(host='localhost', port=8090): Max retries exceeded with url: /api/v1/result (Caused by NewConnectionError('<urllib3.connection.HTTPConnection object at 0x7ff9394f5460>: Failed to establish a new connection: [Errno 111] Connection refused'))
2023-07-27 14:27:19,485  ERROR       send_post.py  post_report  HTTPConnectionPool(host='localhost', port=8090): Max retries exceeded with url: /api/v1/result (Caused by NewConnectionError('<urllib3.connection.HTTPConnection object at 0x7ff9395018e0>: Failed to establish a new connection: [Errno 111] Connection refused'))
2023-07-27 14:27:19,542  ERROR       send_post.py  post_report  HTTPConnectionPool(host='localhost', port=8090): Max retries exceeded with url: /api/v1/result (Caused by NewConnectionError('<urllib3.connection.HTTPConnection object at 0x7ff9394bbd60>: Failed to establish a new connection: [Errno 111] Connection refused'))
2023-07-27 14:27:19,637  ERROR       send_post.py  post_report  HTTPConnectionPool(host='localhost', port=8090): Max retries exceeded with url: /api/v1/result (Caused by NewConnectionError('<urllib3.connection.HTTPConnection object at 0x7ff9394c5700>: Failed to establish a new connection: [Errno 111] Connection refused'))
2023-07-27 14:29:34,118  ERROR       send_post.py  post_report  HTTPConnectionPool(host='localhost', port=8090): Max retries exceeded with url: /api/v1/result (Caused by NewConnectionError('<urllib3.connection.HTTPConnection object at 0x7f876c349970>: Failed to establish a new connection: [Errno 111] Connection refused'))
2023-07-27 14:29:34,167  ERROR       send_post.py  post_report  HTTPConnectionPool(host='localhost', port=8090): Max retries exceeded with url: /api/v1/result (Caused by NewConnectionError('<urllib3.connection.HTTPConnection object at 0x7f876bfcb490>: Failed to establish a new connection: [Errno 111] Connection refused'))
2023-07-27 14:29:34,226  ERROR       send_post.py  post_report  HTTPConnectionPool(host='localhost', port=8090): Max retries exceeded with url: /api/v1/result (Caused by NewConnectionError('<urllib3.connection.HTTPConnection object at 0x7f876bfcb0d0>: Failed to establish a new connection: [Errno 111] Connection refused'))
2023-07-27 14:29:34,274  ERROR       send_post.py  post_report  HTTPConnectionPool(host='localhost', port=8090): Max retries exceeded with url: /api/v1/result (Caused by NewConnectionError('<urllib3.connection.HTTPConnection object at 0x7f876bfcbfa0>: Failed to establish a new connection: [Errno 111] Connection refused'))
2023-07-27 14:29:34,329  ERROR       send_post.py  post_report  HTTPConnectionPool(host='localhost', port=8090): Max retries exceeded with url: /api/v1/result (Caused by NewConnectionError('<urllib3.connection.HTTPConnection object at 0x7f876bfd6760>: Failed to establish a new connection: [Errno 111] Connection refused'))
2023-07-27 14:29:34,377  ERROR       send_post.py  post_report  HTTPConnectionPool(host='localhost', port=8090): Max retries exceeded with url: /api/v1/result (Caused by NewConnectionError('<urllib3.connection.HTTPConnection object at 0x7f876bfd65b0>: Failed to establish a new connection: [Errno 111] Connection refused'))
2023-07-27 14:29:34,431  ERROR       send_post.py  post_report  HTTPConnectionPool(host='localhost', port=8090): Max retries exceeded with url: /api/v1/result (Caused by NewConnectionError('<urllib3.connection.HTTPConnection object at 0x7f876bfcbe80>: Failed to establish a new connection: [Errno 111] Connection refused'))
2023-07-27 14:29:34,478  ERROR       send_post.py  post_report  HTTPConnectionPool(host='localhost', port=8090): Max retries exceeded with url: /api/v1/result (Caused by NewConnectionError('<urllib3.connection.HTTPConnection object at 0x7f876c349310>: Failed to establish a new connection: [Errno 111] Connection refused'))
2023-07-27 14:29:34,532  ERROR       send_post.py  post_report  HTTPConnectionPool(host='localhost', port=8090): Max retries exceeded with url: /api/v1/result (Caused by NewConnectionError('<urllib3.connection.HTTPConnection object at 0x7f876bfe4100>: Failed to establish a new connection: [Errno 111] Connection refused'))
2023-07-27 17:30:14,248  ERROR       send_post.py  post_report  HTTPConnectionPool(host='localhost', port=8090): Max retries exceeded with url: /api/v1/result (Caused by NewConnectionError('<urllib3.connection.HTTPConnection object at 0x7fe3a5dc4280>: Failed to establish a new connection: [Errno 111] Connection refused'))
2023-07-27 17:30:14,321  ERROR       send_post.py  post_report  HTTPConnectionPool(host='localhost', port=8090): Max retries exceeded with url: /api/v1/result (Caused by NewConnectionError('<urllib3.connection.HTTPConnection object at 0x7fe3a5dc45b0>: Failed to establish a new connection: [Errno 111] Connection refused'))
2023-07-27 17:30:14,386  ERROR       send_post.py  post_report  HTTPConnectionPool(host='localhost', port=8090): Max retries exceeded with url: /api/v1/result (Caused by NewConnectionError('<urllib3.connection.HTTPConnection object at 0x7fe3a5dc43d0>: Failed to establish a new connection: [Errno 111] Connection refused'))
2023-07-27 17:30:14,454  ERROR       send_post.py  post_report  HTTPConnectionPool(host='localhost', port=8090): Max retries exceeded with url: /api/v1/result (Caused by NewConnectionError('<urllib3.connection.HTTPConnection object at 0x7fe3a5dd3580>: Failed to establish a new connection: [Errno 111] Connection refused'))
2023-07-27 17:30:14,512  ERROR       send_post.py  post_report  HTTPConnectionPool(host='localhost', port=8090): Max retries exceeded with url: /api/v1/result (Caused by NewConnectionError('<urllib3.connection.HTTPConnection object at 0x7fe3a5de0190>: Failed to establish a new connection: [Errno 111] Connection refused'))
2023-07-27 17:30:14,581  ERROR       send_post.py  post_report  HTTPConnectionPool(host='localhost', port=8090): Max retries exceeded with url: /api/v1/result (Caused by NewConnectionError('<urllib3.connection.HTTPConnection object at 0x7fe3a5dd3580>: Failed to establish a new connection: [Errno 111] Connection refused'))
2023-07-27 17:30:14,646  ERROR       send_post.py  post_report  HTTPConnectionPool(host='localhost', port=8090): Max retries exceeded with url: /api/v1/result (Caused by NewConnectionError('<urllib3.connection.HTTPConnection object at 0x7fe3a5dc4c70>: Failed to establish a new connection: [Errno 111] Connection refused'))
2023-07-27 17:30:14,746  ERROR       send_post.py  post_report  HTTPConnectionPool(host='localhost', port=8090): Max retries exceeded with url: /api/v1/result (Caused by NewConnectionError('<urllib3.connection.HTTPConnection object at 0x7fe3a6143250>: Failed to establish a new connection: [Errno 111] Connection refused'))
2023-07-27 17:30:14,820  ERROR       send_post.py  post_report  HTTPConnectionPool(host='localhost', port=8090): Max retries exceeded with url: /api/v1/result (Caused by NewConnectionError('<urllib3.connection.HTTPConnection object at 0x7fe3a5de41c0>: Failed to establish a new connection: [Errno 111] Connection refused'))
2023-07-27 17:31:20,894  ERROR       send_post.py  post_report  HTTPConnectionPool(host='localhost', port=8090): Max retries exceeded with url: /api/v1/result (Caused by NewConnectionError('<urllib3.connection.HTTPConnection object at 0x7f4f64d522e0>: Failed to establish a new connection: [Errno 111] Connection refused'))
2023-07-27 17:31:20,959  ERROR       send_post.py  post_report  HTTPConnectionPool(host='localhost', port=8090): Max retries exceeded with url: /api/v1/result (Caused by NewConnectionError('<urllib3.connection.HTTPConnection object at 0x7f4f64d526d0>: Failed to establish a new connection: [Errno 111] Connection refused'))
2023-07-27 17:31:21,033  ERROR       send_post.py  post_report  HTTPConnectionPool(host='localhost', port=8090): Max retries exceeded with url: /api/v1/result (Caused by NewConnectionError('<urllib3.connection.HTTPConnection object at 0x7f4f64d52310>: Failed to establish a new connection: [Errno 111] Connection refused'))
2023-07-27 17:31:21,101  ERROR       send_post.py  post_report  HTTPConnectionPool(host='localhost', port=8090): Max retries exceeded with url: /api/v1/result (Caused by NewConnectionError('<urllib3.connection.HTTPConnection object at 0x7f4f64d0e640>: Failed to establish a new connection: [Errno 111] Connection refused'))
2023-07-27 17:31:21,165  ERROR       send_post.py  post_report  HTTPConnectionPool(host='localhost', port=8090): Max retries exceeded with url: /api/v1/result (Caused by NewConnectionError('<urllib3.connection.HTTPConnection object at 0x7f4f64d1a250>: Failed to establish a new connection: [Errno 111] Connection refused'))
2023-07-27 17:31:21,219  ERROR       send_post.py  post_report  HTTPConnectionPool(host='localhost', port=8090): Max retries exceeded with url: /api/v1/result (Caused by NewConnectionError('<urllib3.connection.HTTPConnection object at 0x7f4f64d0e370>: Failed to establish a new connection: [Errno 111] Connection refused'))
2023-07-27 17:31:21,292  ERROR       send_post.py  post_report  HTTPConnectionPool(host='localhost', port=8090): Max retries exceeded with url: /api/v1/result (Caused by NewConnectionError('<urllib3.connection.HTTPConnection object at 0x7f4f64d523d0>: Failed to establish a new connection: [Errno 111] Connection refused'))
2023-07-27 17:31:21,352  ERROR       send_post.py  post_report  HTTPConnectionPool(host='localhost', port=8090): Max retries exceeded with url: /api/v1/result (Caused by NewConnectionError('<urllib3.connection.HTTPConnection object at 0x7f4f6506aeb0>: Failed to establish a new connection: [Errno 111] Connection refused'))
2023-07-27 17:31:21,422  ERROR       send_post.py  post_report  HTTPConnectionPool(host='localhost', port=8090): Max retries exceeded with url: /api/v1/result (Caused by NewConnectionError('<urllib3.connection.HTTPConnection object at 0x7f4f64d0f250>: Failed to establish a new connection: [Errno 111] Connection refused'))
2023-07-27 17:34:40,268  ERROR       send_post.py  post_report  HTTPConnectionPool(host='localhost', port=8090): Max retries exceeded with url: /api/v1/result (Caused by NewConnectionError('<urllib3.connection.HTTPConnection object at 0x7eff799523d0>: Failed to establish a new connection: [Errno 111] Connection refused'))
2023-07-27 17:34:40,339  ERROR       send_post.py  post_report  HTTPConnectionPool(host='localhost', port=8090): Max retries exceeded with url: /api/v1/result (Caused by NewConnectionError('<urllib3.connection.HTTPConnection object at 0x7eff79952ac0>: Failed to establish a new connection: [Errno 111] Connection refused'))
2023-07-27 17:34:40,417  ERROR       send_post.py  post_report  HTTPConnectionPool(host='localhost', port=8090): Max retries exceeded with url: /api/v1/result (Caused by NewConnectionError('<urllib3.connection.HTTPConnection object at 0x7eff79952f70>: Failed to establish a new connection: [Errno 111] Connection refused'))
2023-07-27 17:34:40,485  ERROR       send_post.py  post_report  HTTPConnectionPool(host='localhost', port=8090): Max retries exceeded with url: /api/v1/result (Caused by NewConnectionError('<urllib3.connection.HTTPConnection object at 0x7eff7990e9d0>: Failed to establish a new connection: [Errno 111] Connection refused'))
2023-07-27 17:34:40,555  ERROR       send_post.py  post_report  HTTPConnectionPool(host='localhost', port=8090): Max retries exceeded with url: /api/v1/result (Caused by NewConnectionError('<urllib3.connection.HTTPConnection object at 0x7eff7991a340>: Failed to establish a new connection: [Errno 111] Connection refused'))
2023-07-27 17:34:40,616  ERROR       send_post.py  post_report  HTTPConnectionPool(host='localhost', port=8090): Max retries exceeded with url: /api/v1/result (Caused by NewConnectionError('<urllib3.connection.HTTPConnection object at 0x7eff7990e5e0>: Failed to establish a new connection: [Errno 111] Connection refused'))
2023-07-27 17:34:40,693  ERROR       send_post.py  post_report  HTTPConnectionPool(host='localhost', port=8090): Max retries exceeded with url: /api/v1/result (Caused by NewConnectionError('<urllib3.connection.HTTPConnection object at 0x7eff799527f0>: Failed to establish a new connection: [Errno 111] Connection refused'))
2023-07-27 17:34:40,766  ERROR       send_post.py  post_report  HTTPConnectionPool(host='localhost', port=8090): Max retries exceeded with url: /api/v1/result (Caused by NewConnectionError('<urllib3.connection.HTTPConnection object at 0x7eff79c68f70>: Failed to establish a new connection: [Errno 111] Connection refused'))
2023-07-27 17:34:40,842  ERROR       send_post.py  post_report  HTTPConnectionPool(host='localhost', port=8090): Max retries exceeded with url: /api/v1/result (Caused by NewConnectionError('<urllib3.connection.HTTPConnection object at 0x7eff798fd340>: Failed to establish a new connection: [Errno 111] Connection refused'))
2023-07-27 17:36:34,542  ERROR       send_post.py  post_report  HTTPConnectionPool(host='localhost', port=8090): Max retries exceeded with url: /api/v1/result (Caused by NewConnectionError('<urllib3.connection.HTTPConnection object at 0x7f13f734c3a0>: Failed to establish a new connection: [Errno 111] Connection refused'))
2023-07-27 17:36:34,620  ERROR       send_post.py  post_report  HTTPConnectionPool(host='localhost', port=8090): Max retries exceeded with url: /api/v1/result (Caused by NewConnectionError('<urllib3.connection.HTTPConnection object at 0x7f13f734ca90>: Failed to establish a new connection: [Errno 111] Connection refused'))
2023-07-27 17:36:34,698  ERROR       send_post.py  post_report  HTTPConnectionPool(host='localhost', port=8090): Max retries exceeded with url: /api/v1/result (Caused by NewConnectionError('<urllib3.connection.HTTPConnection object at 0x7f13f734cf40>: Failed to establish a new connection: [Errno 111] Connection refused'))
2023-07-27 17:36:34,804  ERROR       send_post.py  post_report  HTTPConnectionPool(host='localhost', port=8090): Max retries exceeded with url: /api/v1/result (Caused by NewConnectionError('<urllib3.connection.HTTPConnection object at 0x7f13f6f009a0>: Failed to establish a new connection: [Errno 111] Connection refused'))
2023-07-27 17:36:34,873  ERROR       send_post.py  post_report  HTTPConnectionPool(host='localhost', port=8090): Max retries exceeded with url: /api/v1/result (Caused by NewConnectionError('<urllib3.connection.HTTPConnection object at 0x7f13f6f0d310>: Failed to establish a new connection: [Errno 111] Connection refused'))
2023-07-27 17:36:34,945  ERROR       send_post.py  post_report  HTTPConnectionPool(host='localhost', port=8090): Max retries exceeded with url: /api/v1/result (Caused by NewConnectionError('<urllib3.connection.HTTPConnection object at 0x7f13f6f00700>: Failed to establish a new connection: [Errno 111] Connection refused'))
2023-07-27 17:36:35,021  ERROR       send_post.py  post_report  HTTPConnectionPool(host='localhost', port=8090): Max retries exceeded with url: /api/v1/result (Caused by NewConnectionError('<urllib3.connection.HTTPConnection object at 0x7f13f734c460>: Failed to establish a new connection: [Errno 111] Connection refused'))
2023-07-27 17:36:35,092  ERROR       send_post.py  post_report  HTTPConnectionPool(host='localhost', port=8090): Max retries exceeded with url: /api/v1/result (Caused by NewConnectionError('<urllib3.connection.HTTPConnection object at 0x7f13f77665e0>: Failed to establish a new connection: [Errno 111] Connection refused'))
2023-07-27 17:36:35,166  ERROR       send_post.py  post_report  HTTPConnectionPool(host='localhost', port=8090): Max retries exceeded with url: /api/v1/result (Caused by NewConnectionError('<urllib3.connection.HTTPConnection object at 0x7f13f6eef310>: Failed to establish a new connection: [Errno 111] Connection refused'))
2023-07-27 17:39:22,362  ERROR       send_post.py  post_report  HTTPConnectionPool(host='localhost', port=8090): Max retries exceeded with url: /api/v1/result (Caused by NewConnectionError('<urllib3.connection.HTTPConnection object at 0x7f784d1123a0>: Failed to establish a new connection: [Errno 111] Connection refused'))
2023-07-27 17:39:22,454  ERROR       send_post.py  post_report  HTTPConnectionPool(host='localhost', port=8090): Max retries exceeded with url: /api/v1/result (Caused by NewConnectionError('<urllib3.connection.HTTPConnection object at 0x7f784d112a30>: Failed to establish a new connection: [Errno 111] Connection refused'))
2023-07-27 17:39:22,521  ERROR       send_post.py  post_report  HTTPConnectionPool(host='localhost', port=8090): Max retries exceeded with url: /api/v1/result (Caused by NewConnectionError('<urllib3.connection.HTTPConnection object at 0x7f784d112f40>: Failed to establish a new connection: [Errno 111] Connection refused'))
2023-07-27 17:39:22,579  ERROR       send_post.py  post_report  HTTPConnectionPool(host='localhost', port=8090): Max retries exceeded with url: /api/v1/result (Caused by NewConnectionError('<urllib3.connection.HTTPConnection object at 0x7f784cd489a0>: Failed to establish a new connection: [Errno 111] Connection refused'))
2023-07-27 17:39:22,650  ERROR       send_post.py  post_report  HTTPConnectionPool(host='localhost', port=8090): Max retries exceeded with url: /api/v1/result (Caused by NewConnectionError('<urllib3.connection.HTTPConnection object at 0x7f784cd57310>: Failed to establish a new connection: [Errno 111] Connection refused'))
2023-07-27 17:39:22,704  ERROR       send_post.py  post_report  HTTPConnectionPool(host='localhost', port=8090): Max retries exceeded with url: /api/v1/result (Caused by NewConnectionError('<urllib3.connection.HTTPConnection object at 0x7f784cd48700>: Failed to establish a new connection: [Errno 111] Connection refused'))
2023-07-27 17:47:18,636  ERROR       send_post.py  post_report  HTTPConnectionPool(host='localhost', port=8090): Max retries exceeded with url: /api/v1/result (Caused by NewConnectionError('<urllib3.connection.HTTPConnection object at 0x7f46577523a0>: Failed to establish a new connection: [Errno 111] Connection refused'))
2023-07-27 17:47:18,709  ERROR       send_post.py  post_report  HTTPConnectionPool(host='localhost', port=8090): Max retries exceeded with url: /api/v1/result (Caused by NewConnectionError('<urllib3.connection.HTTPConnection object at 0x7f4657752a30>: Failed to establish a new connection: [Errno 111] Connection refused'))
2023-07-27 17:47:18,788  ERROR       send_post.py  post_report  HTTPConnectionPool(host='localhost', port=8090): Max retries exceeded with url: /api/v1/result (Caused by NewConnectionError('<urllib3.connection.HTTPConnection object at 0x7f4657752f40>: Failed to establish a new connection: [Errno 111] Connection refused'))
2023-07-27 17:47:18,859  ERROR       send_post.py  post_report  HTTPConnectionPool(host='localhost', port=8090): Max retries exceeded with url: /api/v1/result (Caused by NewConnectionError('<urllib3.connection.HTTPConnection object at 0x7f465770f9a0>: Failed to establish a new connection: [Errno 111] Connection refused'))
2023-07-27 17:47:18,926  ERROR       send_post.py  post_report  HTTPConnectionPool(host='localhost', port=8090): Max retries exceeded with url: /api/v1/result (Caused by NewConnectionError('<urllib3.connection.HTTPConnection object at 0x7f46577182e0>: Failed to establish a new connection: [Errno 111] Connection refused'))
2023-07-27 17:47:18,992  ERROR       send_post.py  post_report  HTTPConnectionPool(host='localhost', port=8090): Max retries exceeded with url: /api/v1/result (Caused by NewConnectionError('<urllib3.connection.HTTPConnection object at 0x7f465770f7c0>: Failed to establish a new connection: [Errno 111] Connection refused'))
2023-07-27 17:47:19,069  ERROR       send_post.py  post_report  HTTPConnectionPool(host='localhost', port=8090): Max retries exceeded with url: /api/v1/result (Caused by NewConnectionError('<urllib3.connection.HTTPConnection object at 0x7f4657752f10>: Failed to establish a new connection: [Errno 111] Connection refused'))
2023-07-27 17:47:19,137  ERROR       send_post.py  post_report  HTTPConnectionPool(host='localhost', port=8090): Max retries exceeded with url: /api/v1/result (Caused by NewConnectionError('<urllib3.connection.HTTPConnection object at 0x7f4657a68af0>: Failed to establish a new connection: [Errno 111] Connection refused'))
2023-07-27 17:47:19,215  ERROR       send_post.py  post_report  HTTPConnectionPool(host='localhost', port=8090): Max retries exceeded with url: /api/v1/result (Caused by NewConnectionError('<urllib3.connection.HTTPConnection object at 0x7f4657719310>: Failed to establish a new connection: [Errno 111] Connection refused'))
2023-07-27 18:01:57,447  ERROR       send_post.py  post_report  HTTPConnectionPool(host='localhost', port=8090): Max retries exceeded with url: /api/v1/result (Caused by NewConnectionError('<urllib3.connection.HTTPConnection object at 0x7fbf8374c370>: Failed to establish a new connection: [Errno 111] Connection refused'))
2023-07-27 18:01:57,513  ERROR       send_post.py  post_report  HTTPConnectionPool(host='localhost', port=8090): Max retries exceeded with url: /api/v1/result (Caused by NewConnectionError('<urllib3.connection.HTTPConnection object at 0x7fbf8374c760>: Failed to establish a new connection: [Errno 111] Connection refused'))
2023-07-27 18:01:57,584  ERROR       send_post.py  post_report  HTTPConnectionPool(host='localhost', port=8090): Max retries exceeded with url: /api/v1/result (Caused by NewConnectionError('<urllib3.connection.HTTPConnection object at 0x7fbf8374c370>: Failed to establish a new connection: [Errno 111] Connection refused'))
2023-07-27 18:01:57,648  ERROR       send_post.py  post_report  HTTPConnectionPool(host='localhost', port=8090): Max retries exceeded with url: /api/v1/result (Caused by NewConnectionError('<urllib3.connection.HTTPConnection object at 0x7fbf833006d0>: Failed to establish a new connection: [Errno 111] Connection refused'))
2023-07-27 18:01:57,713  ERROR       send_post.py  post_report  HTTPConnectionPool(host='localhost', port=8090): Max retries exceeded with url: /api/v1/result (Caused by NewConnectionError('<urllib3.connection.HTTPConnection object at 0x7fbf8330f2e0>: Failed to establish a new connection: [Errno 111] Connection refused'))
2023-07-27 18:01:57,773  ERROR       send_post.py  post_report  HTTPConnectionPool(host='localhost', port=8090): Max retries exceeded with url: /api/v1/result (Caused by NewConnectionError('<urllib3.connection.HTTPConnection object at 0x7fbf83300430>: Failed to establish a new connection: [Errno 111] Connection refused'))
2023-07-27 18:01:57,845  ERROR       send_post.py  post_report  HTTPConnectionPool(host='localhost', port=8090): Max retries exceeded with url: /api/v1/result (Caused by NewConnectionError('<urllib3.connection.HTTPConnection object at 0x7fbf8374cd90>: Failed to establish a new connection: [Errno 111] Connection refused'))
2023-07-27 18:01:57,910  ERROR       send_post.py  post_report  HTTPConnectionPool(host='localhost', port=8090): Max retries exceeded with url: /api/v1/result (Caused by NewConnectionError('<urllib3.connection.HTTPConnection object at 0x7fbf83b66dc0>: Failed to establish a new connection: [Errno 111] Connection refused'))
2023-07-27 18:01:57,980  ERROR       send_post.py  post_report  HTTPConnectionPool(host='localhost', port=8090): Max retries exceeded with url: /api/v1/result (Caused by NewConnectionError('<urllib3.connection.HTTPConnection object at 0x7fbf832ef2e0>: Failed to establish a new connection: [Errno 111] Connection refused'))
2023-07-27 18:04:18,711  ERROR       send_post.py  post_report  HTTPConnectionPool(host='localhost', port=8090): Max retries exceeded with url: /api/v1/result (Caused by NewConnectionError('<urllib3.connection.HTTPConnection object at 0x7ff418152370>: Failed to establish a new connection: [Errno 111] Connection refused'))
2023-07-27 18:04:18,790  ERROR       send_post.py  post_report  HTTPConnectionPool(host='localhost', port=8090): Max retries exceeded with url: /api/v1/result (Caused by NewConnectionError('<urllib3.connection.HTTPConnection object at 0x7ff418152a00>: Failed to establish a new connection: [Errno 111] Connection refused'))
2023-07-27 18:04:18,861  ERROR       send_post.py  post_report  HTTPConnectionPool(host='localhost', port=8090): Max retries exceeded with url: /api/v1/result (Caused by NewConnectionError('<urllib3.connection.HTTPConnection object at 0x7ff418152f10>: Failed to establish a new connection: [Errno 111] Connection refused'))
2023-07-27 18:04:18,936  ERROR       send_post.py  post_report  HTTPConnectionPool(host='localhost', port=8090): Max retries exceeded with url: /api/v1/result (Caused by NewConnectionError('<urllib3.connection.HTTPConnection object at 0x7ff417d48970>: Failed to establish a new connection: [Errno 111] Connection refused'))
2023-07-27 18:04:18,998  ERROR       send_post.py  post_report  HTTPConnectionPool(host='localhost', port=8090): Max retries exceeded with url: /api/v1/result (Caused by NewConnectionError('<urllib3.connection.HTTPConnection object at 0x7ff417d542e0>: Failed to establish a new connection: [Errno 111] Connection refused'))
2023-07-27 18:04:19,065  ERROR       send_post.py  post_report  HTTPConnectionPool(host='localhost', port=8090): Max retries exceeded with url: /api/v1/result (Caused by NewConnectionError('<urllib3.connection.HTTPConnection object at 0x7ff417d48040>: Failed to establish a new connection: [Errno 111] Connection refused'))
2023-07-27 18:04:19,139  ERROR       send_post.py  post_report  HTTPConnectionPool(host='localhost', port=8090): Max retries exceeded with url: /api/v1/result (Caused by NewConnectionError('<urllib3.connection.HTTPConnection object at 0x7ff4181520d0>: Failed to establish a new connection: [Errno 111] Connection refused'))
2023-07-27 18:04:19,211  ERROR       send_post.py  post_report  HTTPConnectionPool(host='localhost', port=8090): Max retries exceeded with url: /api/v1/result (Caused by NewConnectionError('<urllib3.connection.HTTPConnection object at 0x7ff41852c430>: Failed to establish a new connection: [Errno 111] Connection refused'))
2023-07-27 18:04:19,282  ERROR       send_post.py  post_report  HTTPConnectionPool(host='localhost', port=8090): Max retries exceeded with url: /api/v1/result (Caused by NewConnectionError('<urllib3.connection.HTTPConnection object at 0x7ff417d442e0>: Failed to establish a new connection: [Errno 111] Connection refused'))
2023-08-07 11:53:54,096  ERROR       send_post.py  post_report  HTTPConnectionPool(host='localhost', port=8090): Max retries exceeded with url: /api/v1/result (Caused by NewConnectionError('<urllib3.connection.HTTPConnection object at 0x7fcd17b043a0>: Failed to establish a new connection: [Errno 111] Connection refused'))
2023-08-07 11:53:54,162  ERROR       send_post.py  post_report  HTTPConnectionPool(host='localhost', port=8090): Max retries exceeded with url: /api/v1/result (Caused by NewConnectionError('<urllib3.connection.HTTPConnection object at 0x7fcd17b04a90>: Failed to establish a new connection: [Errno 111] Connection refused'))
2023-08-07 11:54:39,189  ERROR       send_post.py  post_report  HTTPConnectionPool(host='localhost', port=8090): Max retries exceeded with url: /api/v1/result (Caused by NewConnectionError('<urllib3.connection.HTTPConnection object at 0x7f530f14c3a0>: Failed to establish a new connection: [Errno 111] Connection refused'))
2023-08-07 11:54:39,288  ERROR       send_post.py  post_report  HTTPConnectionPool(host='localhost', port=8090): Max retries exceeded with url: /api/v1/result (Caused by NewConnectionError('<urllib3.connection.HTTPConnection object at 0x7f530f14ca90>: Failed to establish a new connection: [Errno 111] Connection refused'))
2023-08-07 11:56:13,977  ERROR       send_post.py  post_report  HTTPConnectionPool(host='localhost', port=8090): Max retries exceeded with url: /api/v1/result (Caused by NewConnectionError('<urllib3.connection.HTTPConnection object at 0x7f8903d524c0>: Failed to establish a new connection: [Errno 111] Connection refused'))
2023-08-07 11:56:14,050  ERROR       send_post.py  post_report  HTTPConnectionPool(host='localhost', port=8090): Max retries exceeded with url: /api/v1/result (Caused by NewConnectionError('<urllib3.connection.HTTPConnection object at 0x7f8903d52bb0>: Failed to establish a new connection: [Errno 111] Connection refused'))
2023-08-07 12:06:24,149  ERROR       send_post.py  post_report  HTTPConnectionPool(host='localhost', port=8090): Max retries exceeded with url: /api/v1/result (Caused by NewConnectionError('<urllib3.connection.HTTPConnection object at 0x7f1ec57144c0>: Failed to establish a new connection: [Errno 111] Connection refused'))
2023-08-07 12:06:24,218  ERROR       send_post.py  post_report  HTTPConnectionPool(host='localhost', port=8090): Max retries exceeded with url: /api/v1/result (Caused by NewConnectionError('<urllib3.connection.HTTPConnection object at 0x7f1ec5714b50>: Failed to establish a new connection: [Errno 111] Connection refused'))
2023-08-07 12:07:22,692  ERROR       send_post.py  post_report  HTTPConnectionPool(host='localhost', port=8090): Max retries exceeded with url: /api/v1/result (Caused by NewConnectionError('<urllib3.connection.HTTPConnection object at 0x7f3c29b144c0>: Failed to establish a new connection: [Errno 111] Connection refused'))
2023-08-07 12:07:22,762  ERROR       send_post.py  post_report  HTTPConnectionPool(host='localhost', port=8090): Max retries exceeded with url: /api/v1/result (Caused by NewConnectionError('<urllib3.connection.HTTPConnection object at 0x7f3c29b14bb0>: Failed to establish a new connection: [Errno 111] Connection refused'))
2023-08-07 17:35:32,619  ERROR       send_post.py  post_report  HTTPConnectionPool(host='localhost', port=8090): Max retries exceeded with url: /api/v1/result (Caused by NewConnectionError('<urllib3.connection.HTTPConnection object at 0x7f7db6fd0a90>: Failed to establish a new connection: [Errno 111] Connection refused'))
2023-08-07 17:35:32,700  ERROR       send_post.py  post_report  HTTPConnectionPool(host='localhost', port=8090): Max retries exceeded with url: /api/v1/result (Caused by NewConnectionError('<urllib3.connection.HTTPConnection object at 0x7f7db6fd0eb0>: Failed to establish a new connection: [Errno 111] Connection refused'))
2023-08-07 17:51:18,545  ERROR       send_post.py  post_report  HTTPConnectionPool(host='localhost', port=8090): Max retries exceeded with url: /api/v1/result (Caused by NewConnectionError('<urllib3.connection.HTTPConnection object at 0x7fadbd9bca90>: Failed to establish a new connection: [Errno 111] Connection refused'))
2023-08-07 17:51:18,636  ERROR       send_post.py  post_report  HTTPConnectionPool(host='localhost', port=8090): Max retries exceeded with url: /api/v1/result (Caused by NewConnectionError('<urllib3.connection.HTTPConnection object at 0x7fadbd9bceb0>: Failed to establish a new connection: [Errno 111] Connection refused'))
2023-08-07 17:51:32,525  ERROR       send_post.py  post_report  HTTPConnectionPool(host='localhost', port=8090): Max retries exceeded with url: /api/v1/result (Caused by NewConnectionError('<urllib3.connection.HTTPConnection object at 0x7f2ab6ac8a90>: Failed to establish a new connection: [Errno 111] Connection refused'))
2023-08-07 17:51:32,605  ERROR       send_post.py  post_report  HTTPConnectionPool(host='localhost', port=8090): Max retries exceeded with url: /api/v1/result (Caused by NewConnectionError('<urllib3.connection.HTTPConnection object at 0x7f2ab6ac8eb0>: Failed to establish a new connection: [Errno 111] Connection refused'))
2023-08-09 11:33:50,479  ERROR       send_post.py  run  HTTPConnectionPool(host='0.0.0.0', port=9635): Max retries exceeded with url: /test (Caused by NewConnectionError('<urllib3.connection.HTTPConnection object at 0x7f70129424d0>: Failed to establish a new connection: [Errno 111] Connection refused'))
2023-08-09 11:33:55,499  ERROR       send_post.py  run  HTTPConnectionPool(host='0.0.0.0', port=9635): Max retries exceeded with url: /test (Caused by NewConnectionError('<urllib3.connection.HTTPConnection object at 0x7f701294eed0>: Failed to establish a new connection: [Errno 111] Connection refused'))
2023-08-09 11:34:00,503  ERROR       send_post.py  run  HTTPConnectionPool(host='0.0.0.0', port=9635): Max retries exceeded with url: /test (Caused by NewConnectionError('<urllib3.connection.HTTPConnection object at 0x7f7012959890>: Failed to establish a new connection: [Errno 111] Connection refused'))
2023-08-09 11:34:05,506  ERROR       send_post.py  run  HTTPConnectionPool(host='0.0.0.0', port=9635): Max retries exceeded with url: /test (Caused by NewConnectionError('<urllib3.connection.HTTPConnection object at 0x7f701294d710>: Failed to establish a new connection: [Errno 111] Connection refused'))
2023-08-09 11:34:10,509  ERROR       send_post.py  run  HTTPConnectionPool(host='0.0.0.0', port=9635): Max retries exceeded with url: /test (Caused by NewConnectionError('<urllib3.connection.HTTPConnection object at 0x7f7012926890>: Failed to establish a new connection: [Errno 111] Connection refused'))
2023-08-09 11:34:15,513  ERROR       send_post.py  run  HTTPConnectionPool(host='0.0.0.0', port=9635): Max retries exceeded with url: /test (Caused by NewConnectionError('<urllib3.connection.HTTPConnection object at 0x7f701295bc90>: Failed to establish a new connection: [Errno 111] Connection refused'))
2023-08-09 11:34:20,516  ERROR       send_post.py  run  HTTPConnectionPool(host='0.0.0.0', port=9635): Max retries exceeded with url: /test (Caused by NewConnectionError('<urllib3.connection.HTTPConnection object at 0x7f701296e110>: Failed to establish a new connection: [Errno 111] Connection refused'))
2023-08-09 11:34:25,518  ERROR       send_post.py  run  HTTPConnectionPool(host='0.0.0.0', port=9635): Max retries exceeded with url: /test (Caused by NewConnectionError('<urllib3.connection.HTTPConnection object at 0x7f7012970510>: Failed to establish a new connection: [Errno 111] Connection refused'))
2023-08-09 11:34:30,521  ERROR       send_post.py  run  HTTPConnectionPool(host='0.0.0.0', port=9635): Max retries exceeded with url: /test (Caused by NewConnectionError('<urllib3.connection.HTTPConnection object at 0x7f701296f110>: Failed to establish a new connection: [Errno 111] Connection refused'))
2023-08-09 11:34:35,524  ERROR       send_post.py  run  HTTPConnectionPool(host='0.0.0.0', port=9635): Max retries exceeded with url: /test (Caused by NewConnectionError('<urllib3.connection.HTTPConnection object at 0x7f701296d910>: Failed to establish a new connection: [Errno 111] Connection refused'))
2023-08-09 11:34:40,527  ERROR       send_post.py  run  HTTPConnectionPool(host='0.0.0.0', port=9635): Max retries exceeded with url: /test (Caused by NewConnectionError('<urllib3.connection.HTTPConnection object at 0x7f7012926690>: Failed to establish a new connection: [Errno 111] Connection refused'))
2023-08-09 11:34:42,788  ERROR       send_post.py  run  HTTPConnectionPool(host='0.0.0.0', port=9635): Max retries exceeded with url: /test (Caused by NewConnectionError('<urllib3.connection.HTTPConnection object at 0x7f602ce190d0>: Failed to establish a new connection: [Errno 111] Connection refused'))
2023-08-09 11:34:45,530  ERROR       send_post.py  run  HTTPConnectionPool(host='0.0.0.0', port=9635): Max retries exceeded with url: /test (Caused by NewConnectionError('<urllib3.connection.HTTPConnection object at 0x7f701295ad50>: Failed to establish a new connection: [Errno 111] Connection refused'))
2023-08-09 11:34:47,791  ERROR       send_post.py  run  HTTPConnectionPool(host='0.0.0.0', port=9635): Max retries exceeded with url: /test (Caused by NewConnectionError('<urllib3.connection.HTTPConnection object at 0x7f602ce1b9d0>: Failed to establish a new connection: [Errno 111] Connection refused'))
2023-08-09 11:34:50,532  ERROR       send_post.py  run  HTTPConnectionPool(host='0.0.0.0', port=9635): Max retries exceeded with url: /test (Caused by NewConnectionError('<urllib3.connection.HTTPConnection object at 0x7f701294e890>: Failed to establish a new connection: [Errno 111] Connection refused'))
2023-08-09 11:34:52,794  ERROR       send_post.py  run  HTTPConnectionPool(host='0.0.0.0', port=9635): Max retries exceeded with url: /test (Caused by NewConnectionError('<urllib3.connection.HTTPConnection object at 0x7f602ce2a390>: Failed to establish a new connection: [Errno 111] Connection refused'))
2023-08-09 11:34:55,533  ERROR       send_post.py  run  HTTPConnectionPool(host='0.0.0.0', port=9635): Max retries exceeded with url: /test (Caused by NewConnectionError('<urllib3.connection.HTTPConnection object at 0x7f7012972910>: Failed to establish a new connection: [Errno 111] Connection refused'))
2023-08-09 11:35:00,535  ERROR       send_post.py  run  HTTPConnectionPool(host='0.0.0.0', port=9635): Max retries exceeded with url: /test (Caused by NewConnectionError('<urllib3.connection.HTTPConnection object at 0x7f7012959390>: Failed to establish a new connection: [Errno 111] Connection refused'))
2023-08-09 11:35:05,538  ERROR       send_post.py  run  HTTPConnectionPool(host='0.0.0.0', port=9635): Max retries exceeded with url: /test (Caused by NewConnectionError('<urllib3.connection.HTTPConnection object at 0x7f701295af50>: Failed to establish a new connection: [Errno 111] Connection refused'))
2023-08-09 11:35:10,541  ERROR       send_post.py  run  HTTPConnectionPool(host='0.0.0.0', port=9635): Max retries exceeded with url: /test (Caused by NewConnectionError('<urllib3.connection.HTTPConnection object at 0x7f701294ef10>: Failed to establish a new connection: [Errno 111] Connection refused'))
2023-08-09 11:35:15,544  ERROR       send_post.py  run  HTTPConnectionPool(host='0.0.0.0', port=9635): Max retries exceeded with url: /test (Caused by NewConnectionError('<urllib3.connection.HTTPConnection object at 0x7f7012972650>: Failed to establish a new connection: [Errno 111] Connection refused'))
2023-08-09 11:35:20,546  ERROR       send_post.py  run  HTTPConnectionPool(host='0.0.0.0', port=9635): Max retries exceeded with url: /test (Caused by NewConnectionError('<urllib3.connection.HTTPConnection object at 0x7f701296c6d0>: Failed to establish a new connection: [Errno 111] Connection refused'))
2023-08-09 11:35:25,549  ERROR       send_post.py  run  HTTPConnectionPool(host='0.0.0.0', port=9635): Max retries exceeded with url: /test (Caused by NewConnectionError('<urllib3.connection.HTTPConnection object at 0x7f701296e890>: Failed to establish a new connection: [Errno 111] Connection refused'))
2023-08-09 11:35:30,553  ERROR       send_post.py  run  HTTPConnectionPool(host='0.0.0.0', port=9635): Max retries exceeded with url: /test (Caused by NewConnectionError('<urllib3.connection.HTTPConnection object at 0x7f701294f4d0>: Failed to establish a new connection: [Errno 111] Connection refused'))
2023-08-09 11:35:35,556  ERROR       send_post.py  run  HTTPConnectionPool(host='0.0.0.0', port=9635): Max retries exceeded with url: /test (Caused by NewConnectionError('<urllib3.connection.HTTPConnection object at 0x7f701294ebd0>: Failed to establish a new connection: [Errno 111] Connection refused'))
2023-08-09 11:35:40,559  ERROR       send_post.py  run  HTTPConnectionPool(host='0.0.0.0', port=9635): Max retries exceeded with url: /test (Caused by NewConnectionError('<urllib3.connection.HTTPConnection object at 0x7f701296ce90>: Failed to establish a new connection: [Errno 111] Connection refused'))
2023-08-09 11:35:45,562  ERROR       send_post.py  run  HTTPConnectionPool(host='0.0.0.0', port=9635): Max retries exceeded with url: /test (Caused by NewConnectionError('<urllib3.connection.HTTPConnection object at 0x7f7012943ed0>: Failed to establish a new connection: [Errno 111] Connection refused'))
2023-08-09 11:35:50,565  ERROR       send_post.py  run  HTTPConnectionPool(host='0.0.0.0', port=9635): Max retries exceeded with url: /test (Caused by NewConnectionError('<urllib3.connection.HTTPConnection object at 0x7f7012971890>: Failed to establish a new connection: [Errno 111] Connection refused'))
2023-08-09 11:35:55,568  ERROR       send_post.py  run  HTTPConnectionPool(host='0.0.0.0', port=9635): Max retries exceeded with url: /test (Caused by NewConnectionError('<urllib3.connection.HTTPConnection object at 0x7f701295bfd0>: Failed to establish a new connection: [Errno 111] Connection refused'))
2023-08-09 11:36:00,571  ERROR       send_post.py  run  HTTPConnectionPool(host='0.0.0.0', port=9635): Max retries exceeded with url: /test (Caused by NewConnectionError('<urllib3.connection.HTTPConnection object at 0x7f701297ced0>: Failed to establish a new connection: [Errno 111] Connection refused'))
2023-08-09 11:36:05,574  ERROR       send_post.py  run  HTTPConnectionPool(host='0.0.0.0', port=9635): Max retries exceeded with url: /test (Caused by NewConnectionError('<urllib3.connection.HTTPConnection object at 0x7f705089ab10>: Failed to establish a new connection: [Errno 111] Connection refused'))
2023-08-09 11:36:10,577  ERROR       send_post.py  run  HTTPConnectionPool(host='0.0.0.0', port=9635): Max retries exceeded with url: /test (Caused by NewConnectionError('<urllib3.connection.HTTPConnection object at 0x7f7012971210>: Failed to establish a new connection: [Errno 111] Connection refused'))
2023-08-09 11:36:15,579  ERROR       send_post.py  run  HTTPConnectionPool(host='0.0.0.0', port=9635): Max retries exceeded with url: /test (Caused by NewConnectionError('<urllib3.connection.HTTPConnection object at 0x7f7012972fd0>: Failed to establish a new connection: [Errno 111] Connection refused'))
2023-08-09 11:36:20,488  ERROR       send_post.py  run  HTTPConnectionPool(host='0.0.0.0', port=9635): Max retries exceeded with url: /test (Caused by NewConnectionError('<urllib3.connection.HTTPConnection object at 0x7feba8a0c8d0>: Failed to establish a new connection: [Errno 111] Connection refused'))
2023-08-09 11:36:20,582  ERROR       send_post.py  run  HTTPConnectionPool(host='0.0.0.0', port=9635): Max retries exceeded with url: /test (Caused by NewConnectionError('<urllib3.connection.HTTPConnection object at 0x7f701296d290>: Failed to establish a new connection: [Errno 111] Connection refused'))
2023-08-09 11:36:25,490  ERROR       send_post.py  run  HTTPConnectionPool(host='0.0.0.0', port=9635): Max retries exceeded with url: /test (Caused by NewConnectionError('<urllib3.connection.HTTPConnection object at 0x7feba8a0f010>: Failed to establish a new connection: [Errno 111] Connection refused'))
2023-08-09 11:36:25,584  ERROR       send_post.py  run  HTTPConnectionPool(host='0.0.0.0', port=9635): Max retries exceeded with url: /test (Caused by NewConnectionError('<urllib3.connection.HTTPConnection object at 0x7f701296ded0>: Failed to establish a new connection: [Errno 111] Connection refused'))
2023-08-09 11:36:30,494  ERROR       send_post.py  run  HTTPConnectionPool(host='0.0.0.0', port=9635): Max retries exceeded with url: /test (Caused by NewConnectionError('<urllib3.connection.HTTPConnection object at 0x7feba8a1d9d0>: Failed to establish a new connection: [Errno 111] Connection refused'))
2023-08-09 11:36:30,588  ERROR       send_post.py  run  HTTPConnectionPool(host='0.0.0.0', port=9635): Max retries exceeded with url: /test (Caused by NewConnectionError('<urllib3.connection.HTTPConnection object at 0x7f701294c110>: Failed to establish a new connection: [Errno 111] Connection refused'))
2023-08-09 11:36:35,497  ERROR       send_post.py  run  HTTPConnectionPool(host='0.0.0.0', port=9635): Max retries exceeded with url: /test (Caused by NewConnectionError('<urllib3.connection.HTTPConnection object at 0x7feba8a0e590>: Failed to establish a new connection: [Errno 111] Connection refused'))
2023-08-09 11:36:35,591  ERROR       send_post.py  run  HTTPConnectionPool(host='0.0.0.0', port=9635): Max retries exceeded with url: /test (Caused by NewConnectionError('<urllib3.connection.HTTPConnection object at 0x7f701296efd0>: Failed to establish a new connection: [Errno 111] Connection refused'))
2023-08-09 11:36:40,500  ERROR       send_post.py  run  HTTPConnectionPool(host='0.0.0.0', port=9635): Max retries exceeded with url: /test (Caused by NewConnectionError('<urllib3.connection.HTTPConnection object at 0x7feba89eb3d0>: Failed to establish a new connection: [Errno 111] Connection refused'))
2023-08-09 11:36:40,594  ERROR       send_post.py  run  HTTPConnectionPool(host='0.0.0.0', port=9635): Max retries exceeded with url: /test (Caused by NewConnectionError('<urllib3.connection.HTTPConnection object at 0x7f701296c550>: Failed to establish a new connection: [Errno 111] Connection refused'))
2023-08-09 11:36:45,502  ERROR       send_post.py  run  HTTPConnectionPool(host='0.0.0.0', port=9635): Max retries exceeded with url: /test (Caused by NewConnectionError('<urllib3.connection.HTTPConnection object at 0x7feba8a1fd90>: Failed to establish a new connection: [Errno 111] Connection refused'))
2023-08-09 11:36:45,597  ERROR       send_post.py  run  HTTPConnectionPool(host='0.0.0.0', port=9635): Max retries exceeded with url: /test (Caused by NewConnectionError('<urllib3.connection.HTTPConnection object at 0x7f7012970a90>: Failed to establish a new connection: [Errno 111] Connection refused'))
2023-08-09 11:36:50,504  ERROR       send_post.py  run  HTTPConnectionPool(host='0.0.0.0', port=9635): Max retries exceeded with url: /test (Caused by NewConnectionError('<urllib3.connection.HTTPConnection object at 0x7feba8a32210>: Failed to establish a new connection: [Errno 111] Connection refused'))
2023-08-09 11:36:50,600  ERROR       send_post.py  run  HTTPConnectionPool(host='0.0.0.0', port=9635): Max retries exceeded with url: /test (Caused by NewConnectionError('<urllib3.connection.HTTPConnection object at 0x7f7012b1d410>: Failed to establish a new connection: [Errno 111] Connection refused'))
2023-08-09 11:36:55,507  ERROR       send_post.py  run  HTTPConnectionPool(host='0.0.0.0', port=9635): Max retries exceeded with url: /test (Caused by NewConnectionError('<urllib3.connection.HTTPConnection object at 0x7feba8a34650>: Failed to establish a new connection: [Errno 111] Connection refused'))
2023-08-09 11:36:55,603  ERROR       send_post.py  run  HTTPConnectionPool(host='0.0.0.0', port=9635): Max retries exceeded with url: /test (Caused by NewConnectionError('<urllib3.connection.HTTPConnection object at 0x7f701294eb10>: Failed to establish a new connection: [Errno 111] Connection refused'))
2023-08-09 11:37:00,511  ERROR       send_post.py  run  HTTPConnectionPool(host='0.0.0.0', port=9635): Max retries exceeded with url: /test (Caused by NewConnectionError('<urllib3.connection.HTTPConnection object at 0x7feba8a318d0>: Failed to establish a new connection: [Errno 111] Connection refused'))
2023-08-09 11:37:00,607  ERROR       send_post.py  run  HTTPConnectionPool(host='0.0.0.0', port=9635): Max retries exceeded with url: /test (Caused by NewConnectionError('<urllib3.connection.HTTPConnection object at 0x7f701297f290>: Failed to establish a new connection: [Errno 111] Connection refused'))
2023-08-09 11:37:05,514  ERROR       send_post.py  run  HTTPConnectionPool(host='0.0.0.0', port=9635): Max retries exceeded with url: /test (Caused by NewConnectionError('<urllib3.connection.HTTPConnection object at 0x7feba8a32110>: Failed to establish a new connection: [Errno 111] Connection refused'))
2023-08-09 11:37:05,609  ERROR       send_post.py  run  HTTPConnectionPool(host='0.0.0.0', port=9635): Max retries exceeded with url: /test (Caused by NewConnectionError('<urllib3.connection.HTTPConnection object at 0x7f7012941890>: Failed to establish a new connection: [Errno 111] Connection refused'))
2023-08-09 11:37:10,517  ERROR       send_post.py  run  HTTPConnectionPool(host='0.0.0.0', port=9635): Max retries exceeded with url: /test (Caused by NewConnectionError('<urllib3.connection.HTTPConnection object at 0x7feba89eb290>: Failed to establish a new connection: [Errno 111] Connection refused'))
2023-08-09 11:37:10,612  ERROR       send_post.py  run  HTTPConnectionPool(host='0.0.0.0', port=9635): Max retries exceeded with url: /test (Caused by NewConnectionError('<urllib3.connection.HTTPConnection object at 0x7f7012973b90>: Failed to establish a new connection: [Errno 111] Connection refused'))
2023-08-09 11:37:15,520  ERROR       send_post.py  run  HTTPConnectionPool(host='0.0.0.0', port=9635): Max retries exceeded with url: /test (Caused by NewConnectionError('<urllib3.connection.HTTPConnection object at 0x7feba8a1ea50>: Failed to establish a new connection: [Errno 111] Connection refused'))
2023-08-09 11:37:15,615  ERROR       send_post.py  run  HTTPConnectionPool(host='0.0.0.0', port=9635): Max retries exceeded with url: /test (Caused by NewConnectionError('<urllib3.connection.HTTPConnection object at 0x7f7012971b10>: Failed to establish a new connection: [Errno 111] Connection refused'))
2023-08-09 11:37:20,523  ERROR       send_post.py  run  HTTPConnectionPool(host='0.0.0.0', port=9635): Max retries exceeded with url: /test (Caused by NewConnectionError('<urllib3.connection.HTTPConnection object at 0x7feba8a0fa50>: Failed to establish a new connection: [Errno 111] Connection refused'))
2023-08-09 11:37:20,618  ERROR       send_post.py  run  HTTPConnectionPool(host='0.0.0.0', port=9635): Max retries exceeded with url: /test (Caused by NewConnectionError('<urllib3.connection.HTTPConnection object at 0x7f701296e0d0>: Failed to establish a new connection: [Errno 111] Connection refused'))
2023-08-09 11:37:25,526  ERROR       send_post.py  run  HTTPConnectionPool(host='0.0.0.0', port=9635): Max retries exceeded with url: /test (Caused by NewConnectionError('<urllib3.connection.HTTPConnection object at 0x7feba8a36a90>: Failed to establish a new connection: [Errno 111] Connection refused'))
2023-08-09 11:37:25,621  ERROR       send_post.py  run  HTTPConnectionPool(host='0.0.0.0', port=9635): Max retries exceeded with url: /test (Caused by NewConnectionError('<urllib3.connection.HTTPConnection object at 0x7f7012926450>: Failed to establish a new connection: [Errno 111] Connection refused'))
2023-08-09 11:37:30,528  ERROR       send_post.py  run  HTTPConnectionPool(host='0.0.0.0', port=9635): Max retries exceeded with url: /test (Caused by NewConnectionError('<urllib3.connection.HTTPConnection object at 0x7feba8a1fc90>: Failed to establish a new connection: [Errno 111] Connection refused'))
2023-08-09 11:37:30,625  ERROR       send_post.py  run  HTTPConnectionPool(host='0.0.0.0', port=9635): Max retries exceeded with url: /test (Caused by NewConnectionError('<urllib3.connection.HTTPConnection object at 0x7f70129856d0>: Failed to establish a new connection: [Errno 111] Connection refused'))
2023-08-09 11:37:35,531  ERROR       send_post.py  run  HTTPConnectionPool(host='0.0.0.0', port=9635): Max retries exceeded with url: /test (Caused by NewConnectionError('<urllib3.connection.HTTPConnection object at 0x7feba8a1e650>: Failed to establish a new connection: [Errno 111] Connection refused'))
2023-08-09 11:37:35,628  ERROR       send_post.py  run  HTTPConnectionPool(host='0.0.0.0', port=9635): Max retries exceeded with url: /test (Caused by NewConnectionError('<urllib3.connection.HTTPConnection object at 0x7f701296fdd0>: Failed to establish a new connection: [Errno 111] Connection refused'))
2023-08-09 11:37:40,533  ERROR       send_post.py  run  HTTPConnectionPool(host='0.0.0.0', port=9635): Max retries exceeded with url: /test (Caused by NewConnectionError('<urllib3.connection.HTTPConnection object at 0x7feba8a0d310>: Failed to establish a new connection: [Errno 111] Connection refused'))
2023-08-09 11:37:40,629  ERROR       send_post.py  run  HTTPConnectionPool(host='0.0.0.0', port=9635): Max retries exceeded with url: /test (Caused by NewConnectionError('<urllib3.connection.HTTPConnection object at 0x7f701296ea90>: Failed to establish a new connection: [Errno 111] Connection refused'))
2023-08-09 11:37:45,535  ERROR       send_post.py  run  HTTPConnectionPool(host='0.0.0.0', port=9635): Max retries exceeded with url: /test (Caused by NewConnectionError('<urllib3.connection.HTTPConnection object at 0x7feba8a34210>: Failed to establish a new connection: [Errno 111] Connection refused'))
2023-08-09 11:37:45,631  ERROR       send_post.py  run  HTTPConnectionPool(host='0.0.0.0', port=9635): Max retries exceeded with url: /test (Caused by NewConnectionError('<urllib3.connection.HTTPConnection object at 0x7f7012970290>: Failed to establish a new connection: [Errno 111] Connection refused'))
2023-08-09 11:37:50,538  ERROR       send_post.py  run  HTTPConnectionPool(host='0.0.0.0', port=9635): Max retries exceeded with url: /test (Caused by NewConnectionError('<urllib3.connection.HTTPConnection object at 0x7feba8a30e10>: Failed to establish a new connection: [Errno 111] Connection refused'))
2023-08-09 11:37:50,634  ERROR       send_post.py  run  HTTPConnectionPool(host='0.0.0.0', port=9635): Max retries exceeded with url: /test (Caused by NewConnectionError('<urllib3.connection.HTTPConnection object at 0x7f7012973710>: Failed to establish a new connection: [Errno 111] Connection refused'))
2023-08-09 11:37:55,540  ERROR       send_post.py  run  HTTPConnectionPool(host='0.0.0.0', port=9635): Max retries exceeded with url: /test (Caused by NewConnectionError('<urllib3.connection.HTTPConnection object at 0x7feba8a32990>: Failed to establish a new connection: [Errno 111] Connection refused'))
2023-08-09 11:37:55,636  ERROR       send_post.py  run  HTTPConnectionPool(host='0.0.0.0', port=9635): Max retries exceeded with url: /test (Caused by NewConnectionError('<urllib3.connection.HTTPConnection object at 0x7f701295aa10>: Failed to establish a new connection: [Errno 111] Connection refused'))
2023-08-09 11:38:00,544  ERROR       send_post.py  run  HTTPConnectionPool(host='0.0.0.0', port=9635): Max retries exceeded with url: /test (Caused by NewConnectionError('<urllib3.connection.HTTPConnection object at 0x7feba8a07e50>: Failed to establish a new connection: [Errno 111] Connection refused'))
2023-08-09 11:38:00,639  ERROR       send_post.py  run  HTTPConnectionPool(host='0.0.0.0', port=9635): Max retries exceeded with url: /test (Caused by NewConnectionError('<urllib3.connection.HTTPConnection object at 0x7f7012987b10>: Failed to establish a new connection: [Errno 111] Connection refused'))
2023-08-09 11:38:05,547  ERROR       send_post.py  run  HTTPConnectionPool(host='0.0.0.0', port=9635): Max retries exceeded with url: /test (Caused by NewConnectionError('<urllib3.connection.HTTPConnection object at 0x7feba8a31c50>: Failed to establish a new connection: [Errno 111] Connection refused'))
2023-08-09 11:38:05,642  ERROR       send_post.py  run  HTTPConnectionPool(host='0.0.0.0', port=9635): Max retries exceeded with url: /test (Caused by NewConnectionError('<urllib3.connection.HTTPConnection object at 0x7f7012926cd0>: Failed to establish a new connection: [Errno 111] Connection refused'))
2023-08-09 11:38:10,550  ERROR       send_post.py  run  HTTPConnectionPool(host='0.0.0.0', port=9635): Max retries exceeded with url: /test (Caused by NewConnectionError('<urllib3.connection.HTTPConnection object at 0x7feba8a0e850>: Failed to establish a new connection: [Errno 111] Connection refused'))
2023-08-09 11:38:10,645  ERROR       send_post.py  run  HTTPConnectionPool(host='0.0.0.0', port=9635): Max retries exceeded with url: /test (Caused by NewConnectionError('<urllib3.connection.HTTPConnection object at 0x7f7012985f90>: Failed to establish a new connection: [Errno 111] Connection refused'))
2023-08-09 11:38:15,552  ERROR       send_post.py  run  HTTPConnectionPool(host='0.0.0.0', port=9635): Max retries exceeded with url: /test (Caused by NewConnectionError('<urllib3.connection.HTTPConnection object at 0x7feba8a0ea90>: Failed to establish a new connection: [Errno 111] Connection refused'))
2023-08-09 11:38:15,648  ERROR       send_post.py  run  HTTPConnectionPool(host='0.0.0.0', port=9635): Max retries exceeded with url: /test (Caused by NewConnectionError('<urllib3.connection.HTTPConnection object at 0x7f701296e250>: Failed to establish a new connection: [Errno 111] Connection refused'))
2023-08-09 11:38:20,555  ERROR       send_post.py  run  HTTPConnectionPool(host='0.0.0.0', port=9635): Max retries exceeded with url: /test (Caused by NewConnectionError('<urllib3.connection.HTTPConnection object at 0x7feba8a36610>: Failed to establish a new connection: [Errno 111] Connection refused'))
2023-08-09 11:38:20,650  ERROR       send_post.py  run  HTTPConnectionPool(host='0.0.0.0', port=9635): Max retries exceeded with url: /test (Caused by NewConnectionError('<urllib3.connection.HTTPConnection object at 0x7f701296fe50>: Failed to establish a new connection: [Errno 111] Connection refused'))
2023-08-09 11:38:25,558  ERROR       send_post.py  run  HTTPConnectionPool(host='0.0.0.0', port=9635): Max retries exceeded with url: /test (Caused by NewConnectionError('<urllib3.connection.HTTPConnection object at 0x7feba8a1cad0>: Failed to establish a new connection: [Errno 111] Connection refused'))
2023-08-09 11:38:25,653  ERROR       send_post.py  run  HTTPConnectionPool(host='0.0.0.0', port=9635): Max retries exceeded with url: /test (Caused by NewConnectionError('<urllib3.connection.HTTPConnection object at 0x7f701297f110>: Failed to establish a new connection: [Errno 111] Connection refused'))
2023-08-09 11:38:30,562  ERROR       send_post.py  run  HTTPConnectionPool(host='0.0.0.0', port=9635): Max retries exceeded with url: /test (Caused by NewConnectionError('<urllib3.connection.HTTPConnection object at 0x7feba8a40fd0>: Failed to establish a new connection: [Errno 111] Connection refused'))
2023-08-09 11:38:30,655  ERROR       send_post.py  run  HTTPConnectionPool(host='0.0.0.0', port=9635): Max retries exceeded with url: /test (Caused by NewConnectionError('<urllib3.connection.HTTPConnection object at 0x7f7012973c50>: Failed to establish a new connection: [Errno 111] Connection refused'))
2023-08-09 11:38:35,565  ERROR       send_post.py  run  HTTPConnectionPool(host='0.0.0.0', port=9635): Max retries exceeded with url: /test (Caused by NewConnectionError('<urllib3.connection.HTTPConnection object at 0x7febe39c5dd0>: Failed to establish a new connection: [Errno 111] Connection refused'))
2023-08-09 11:38:35,659  ERROR       send_post.py  run  HTTPConnectionPool(host='0.0.0.0', port=9635): Max retries exceeded with url: /test (Caused by NewConnectionError('<urllib3.connection.HTTPConnection object at 0x7f701297e5d0>: Failed to establish a new connection: [Errno 111] Connection refused'))
2023-08-09 11:38:40,568  ERROR       send_post.py  run  HTTPConnectionPool(host='0.0.0.0', port=9635): Max retries exceeded with url: /test (Caused by NewConnectionError('<urllib3.connection.HTTPConnection object at 0x7feba8a34110>: Failed to establish a new connection: [Errno 111] Connection refused'))
2023-08-09 11:38:40,662  ERROR       send_post.py  run  HTTPConnectionPool(host='0.0.0.0', port=9635): Max retries exceeded with url: /test (Caused by NewConnectionError('<urllib3.connection.HTTPConnection object at 0x7f701296efd0>: Failed to establish a new connection: [Errno 111] Connection refused'))
2023-08-09 11:38:45,571  ERROR       send_post.py  run  HTTPConnectionPool(host='0.0.0.0', port=9635): Max retries exceeded with url: /test (Caused by NewConnectionError('<urllib3.connection.HTTPConnection object at 0x7feba8a35cd0>: Failed to establish a new connection: [Errno 111] Connection refused'))
2023-08-09 11:38:45,665  ERROR       send_post.py  run  HTTPConnectionPool(host='0.0.0.0', port=9635): Max retries exceeded with url: /test (Caused by NewConnectionError('<urllib3.connection.HTTPConnection object at 0x7f701296c350>: Failed to establish a new connection: [Errno 111] Connection refused'))
2023-08-09 11:38:50,574  ERROR       send_post.py  run  HTTPConnectionPool(host='0.0.0.0', port=9635): Max retries exceeded with url: /test (Caused by NewConnectionError('<urllib3.connection.HTTPConnection object at 0x7feba8a0efd0>: Failed to establish a new connection: [Errno 111] Connection refused'))
2023-08-09 11:38:50,668  ERROR       send_post.py  run  HTTPConnectionPool(host='0.0.0.0', port=9635): Max retries exceeded with url: /test (Caused by NewConnectionError('<urllib3.connection.HTTPConnection object at 0x7f7012985710>: Failed to establish a new connection: [Errno 111] Connection refused'))
2023-08-09 11:38:55,577  ERROR       send_post.py  run  HTTPConnectionPool(host='0.0.0.0', port=9635): Max retries exceeded with url: /test (Caused by NewConnectionError('<urllib3.connection.HTTPConnection object at 0x7feba8a31210>: Failed to establish a new connection: [Errno 111] Connection refused'))
2023-08-09 11:38:55,671  ERROR       send_post.py  run  HTTPConnectionPool(host='0.0.0.0', port=9635): Max retries exceeded with url: /test (Caused by NewConnectionError('<urllib3.connection.HTTPConnection object at 0x7f7012943b90>: Failed to establish a new connection: [Errno 111] Connection refused'))
2023-08-09 11:39:00,581  ERROR       send_post.py  run  HTTPConnectionPool(host='0.0.0.0', port=9635): Max retries exceeded with url: /test (Caused by NewConnectionError('<urllib3.connection.HTTPConnection object at 0x7feba8a05450>: Failed to establish a new connection: [Errno 111] Connection refused'))
2023-08-09 11:39:00,674  ERROR       send_post.py  run  HTTPConnectionPool(host='0.0.0.0', port=9635): Max retries exceeded with url: /test (Caused by NewConnectionError('<urllib3.connection.HTTPConnection object at 0x7f7012971bd0>: Failed to establish a new connection: [Errno 111] Connection refused'))
2023-08-09 11:39:05,582  ERROR       send_post.py  run  HTTPConnectionPool(host='0.0.0.0', port=9635): Max retries exceeded with url: /test (Caused by NewConnectionError('<urllib3.connection.HTTPConnection object at 0x7feba8a0f9d0>: Failed to establish a new connection: [Errno 111] Connection refused'))
2023-08-09 11:39:05,678  ERROR       send_post.py  run  HTTPConnectionPool(host='0.0.0.0', port=9635): Max retries exceeded with url: /test (Caused by NewConnectionError('<urllib3.connection.HTTPConnection object at 0x7f7012984b10>: Failed to establish a new connection: [Errno 111] Connection refused'))
2023-08-09 11:39:10,128  ERROR       send_post.py  run  HTTPConnectionPool(host='0.0.0.0', port=9635): Max retries exceeded with url: /test (Caused by NewConnectionError('<urllib3.connection.HTTPConnection object at 0x7f5af01bebd0>: Failed to establish a new connection: [Errno 111] Connection refused'))
2023-08-09 11:39:10,585  ERROR       send_post.py  run  HTTPConnectionPool(host='0.0.0.0', port=9635): Max retries exceeded with url: /test (Caused by NewConnectionError('<urllib3.connection.HTTPConnection object at 0x7feba8a36950>: Failed to establish a new connection: [Errno 111] Connection refused'))
2023-08-09 11:39:10,681  ERROR       send_post.py  run  HTTPConnectionPool(host='0.0.0.0', port=9635): Max retries exceeded with url: /test (Caused by NewConnectionError('<urllib3.connection.HTTPConnection object at 0x7f7012984050>: Failed to establish a new connection: [Errno 111] Connection refused'))
2023-08-09 11:39:15,131  ERROR       send_post.py  run  HTTPConnectionPool(host='0.0.0.0', port=9635): Max retries exceeded with url: /test (Caused by NewConnectionError('<urllib3.connection.HTTPConnection object at 0x7f5ab500b650>: Failed to establish a new connection: [Errno 111] Connection refused'))
2023-08-09 11:39:15,588  ERROR       send_post.py  run  HTTPConnectionPool(host='0.0.0.0', port=9635): Max retries exceeded with url: /test (Caused by NewConnectionError('<urllib3.connection.HTTPConnection object at 0x7feba8a35710>: Failed to establish a new connection: [Errno 111] Connection refused'))
2023-08-09 11:39:15,684  ERROR       send_post.py  run  HTTPConnectionPool(host='0.0.0.0', port=9635): Max retries exceeded with url: /test (Caused by NewConnectionError('<urllib3.connection.HTTPConnection object at 0x7f701296ca10>: Failed to establish a new connection: [Errno 111] Connection refused'))
2023-08-09 11:39:20,135  ERROR       send_post.py  run  HTTPConnectionPool(host='0.0.0.0', port=9635): Max retries exceeded with url: /test (Caused by NewConnectionError('<urllib3.connection.HTTPConnection object at 0x7f5ab5016010>: Failed to establish a new connection: [Errno 111] Connection refused'))
2023-08-09 11:39:20,591  ERROR       send_post.py  run  HTTPConnectionPool(host='0.0.0.0', port=9635): Max retries exceeded with url: /test (Caused by NewConnectionError('<urllib3.connection.HTTPConnection object at 0x7feba8a1e450>: Failed to establish a new connection: [Errno 111] Connection refused'))
2023-08-09 11:39:20,687  ERROR       send_post.py  run  HTTPConnectionPool(host='0.0.0.0', port=9635): Max retries exceeded with url: /test (Caused by NewConnectionError('<urllib3.connection.HTTPConnection object at 0x7f701296e850>: Failed to establish a new connection: [Errno 111] Connection refused'))
2023-08-09 11:39:25,137  ERROR       send_post.py  run  HTTPConnectionPool(host='0.0.0.0', port=9635): Max retries exceeded with url: /test (Caused by NewConnectionError('<urllib3.connection.HTTPConnection object at 0x7f5ab5009a50>: Failed to establish a new connection: [Errno 111] Connection refused'))
2023-08-09 11:39:25,594  ERROR       send_post.py  run  HTTPConnectionPool(host='0.0.0.0', port=9635): Max retries exceeded with url: /test (Caused by NewConnectionError('<urllib3.connection.HTTPConnection object at 0x7feba8a30850>: Failed to establish a new connection: [Errno 111] Connection refused'))
2023-08-09 11:39:25,690  ERROR       send_post.py  run  HTTPConnectionPool(host='0.0.0.0', port=9635): Max retries exceeded with url: /test (Caused by NewConnectionError('<urllib3.connection.HTTPConnection object at 0x7f701297c990>: Failed to establish a new connection: [Errno 111] Connection refused'))
2023-08-09 11:39:30,140  ERROR       send_post.py  run  HTTPConnectionPool(host='0.0.0.0', port=9635): Max retries exceeded with url: /test (Caused by NewConnectionError('<urllib3.connection.HTTPConnection object at 0x7f5ab4fdf410>: Failed to establish a new connection: [Errno 111] Connection refused'))
2023-08-09 11:39:30,597  ERROR       send_post.py  run  HTTPConnectionPool(host='0.0.0.0', port=9635): Max retries exceeded with url: /test (Caused by NewConnectionError('<urllib3.connection.HTTPConnection object at 0x7feba8a433d0>: Failed to establish a new connection: [Errno 111] Connection refused'))
2023-08-09 11:39:30,692  ERROR       send_post.py  run  HTTPConnectionPool(host='0.0.0.0', port=9635): Max retries exceeded with url: /test (Caused by NewConnectionError('<urllib3.connection.HTTPConnection object at 0x7f7012959550>: Failed to establish a new connection: [Errno 111] Connection refused'))
2023-08-09 11:39:35,143  ERROR       send_post.py  run  HTTPConnectionPool(host='0.0.0.0', port=9635): Max retries exceeded with url: /test (Caused by NewConnectionError('<urllib3.connection.HTTPConnection object at 0x7f5ab5028490>: Failed to establish a new connection: [Errno 111] Connection refused'))
2023-08-09 11:39:35,600  ERROR       send_post.py  run  HTTPConnectionPool(host='0.0.0.0', port=9635): Max retries exceeded with url: /test (Caused by NewConnectionError('<urllib3.connection.HTTPConnection object at 0x7feba8a306d0>: Failed to establish a new connection: [Errno 111] Connection refused'))
2023-08-09 11:39:35,696  ERROR       send_post.py  run  HTTPConnectionPool(host='0.0.0.0', port=9635): Max retries exceeded with url: /test (Caused by NewConnectionError('<urllib3.connection.HTTPConnection object at 0x7f701297f010>: Failed to establish a new connection: [Errno 111] Connection refused'))
2023-08-09 11:39:40,147  ERROR       send_post.py  run  HTTPConnectionPool(host='0.0.0.0', port=9635): Max retries exceeded with url: /test (Caused by NewConnectionError('<urllib3.connection.HTTPConnection object at 0x7f5ab502a8d0>: Failed to establish a new connection: [Errno 111] Connection refused'))
2023-08-09 11:39:40,603  ERROR       send_post.py  run  HTTPConnectionPool(host='0.0.0.0', port=9635): Max retries exceeded with url: /test (Caused by NewConnectionError('<urllib3.connection.HTTPConnection object at 0x7feba8a1e610>: Failed to establish a new connection: [Errno 111] Connection refused'))
2023-08-09 11:39:40,699  ERROR       send_post.py  run  HTTPConnectionPool(host='0.0.0.0', port=9635): Max retries exceeded with url: /test (Caused by NewConnectionError('<urllib3.connection.HTTPConnection object at 0x7f701296f110>: Failed to establish a new connection: [Errno 111] Connection refused'))
2023-08-09 11:39:45,150  ERROR       send_post.py  run  HTTPConnectionPool(host='0.0.0.0', port=9635): Max retries exceeded with url: /test (Caused by NewConnectionError('<urllib3.connection.HTTPConnection object at 0x7f5ab502cd10>: Failed to establish a new connection: [Errno 111] Connection refused'))
2023-08-09 11:39:45,606  ERROR       send_post.py  run  HTTPConnectionPool(host='0.0.0.0', port=9635): Max retries exceeded with url: /test (Caused by NewConnectionError('<urllib3.connection.HTTPConnection object at 0x7feba8a35510>: Failed to establish a new connection: [Errno 111] Connection refused'))
2023-08-09 11:39:45,702  ERROR       send_post.py  run  HTTPConnectionPool(host='0.0.0.0', port=9635): Max retries exceeded with url: /test (Caused by NewConnectionError('<urllib3.connection.HTTPConnection object at 0x7f701296d990>: Failed to establish a new connection: [Errno 111] Connection refused'))
2023-08-09 11:39:50,154  ERROR       send_post.py  run  HTTPConnectionPool(host='0.0.0.0', port=9635): Max retries exceeded with url: /test (Caused by NewConnectionError('<urllib3.connection.HTTPConnection object at 0x7f5ab5029c90>: Failed to establish a new connection: [Errno 111] Connection refused'))
2023-08-09 11:39:50,609  ERROR       send_post.py  run  HTTPConnectionPool(host='0.0.0.0', port=9635): Max retries exceeded with url: /test (Caused by NewConnectionError('<urllib3.connection.HTTPConnection object at 0x7feba8a077d0>: Failed to establish a new connection: [Errno 111] Connection refused'))
2023-08-09 11:39:50,705  ERROR       send_post.py  run  HTTPConnectionPool(host='0.0.0.0', port=9635): Max retries exceeded with url: /test (Caused by NewConnectionError('<urllib3.connection.HTTPConnection object at 0x7f7012984910>: Failed to establish a new connection: [Errno 111] Connection refused'))
2023-08-09 11:39:55,157  ERROR       send_post.py  run  HTTPConnectionPool(host='0.0.0.0', port=9635): Max retries exceeded with url: /test (Caused by NewConnectionError('<urllib3.connection.HTTPConnection object at 0x7f5ab502a350>: Failed to establish a new connection: [Errno 111] Connection refused'))
2023-08-09 11:39:55,612  ERROR       send_post.py  run  HTTPConnectionPool(host='0.0.0.0', port=9635): Max retries exceeded with url: /test (Caused by NewConnectionError('<urllib3.connection.HTTPConnection object at 0x7feba8a0d710>: Failed to establish a new connection: [Errno 111] Connection refused'))
2023-08-09 11:39:55,708  ERROR       send_post.py  run  HTTPConnectionPool(host='0.0.0.0', port=9635): Max retries exceeded with url: /test (Caused by NewConnectionError('<urllib3.connection.HTTPConnection object at 0x7f7012970550>: Failed to establish a new connection: [Errno 111] Connection refused'))
2023-08-09 11:40:00,160  ERROR       send_post.py  run  HTTPConnectionPool(host='0.0.0.0', port=9635): Max retries exceeded with url: /test (Caused by NewConnectionError('<urllib3.connection.HTTPConnection object at 0x7f5ab5028b90>: Failed to establish a new connection: [Errno 111] Connection refused'))
2023-08-09 11:40:00,616  ERROR       send_post.py  run  HTTPConnectionPool(host='0.0.0.0', port=9635): Max retries exceeded with url: /test (Caused by NewConnectionError('<urllib3.connection.HTTPConnection object at 0x7feba8a49850>: Failed to establish a new connection: [Errno 111] Connection refused'))
2023-08-09 11:40:00,711  ERROR       send_post.py  run  HTTPConnectionPool(host='0.0.0.0', port=9635): Max retries exceeded with url: /test (Caused by NewConnectionError('<urllib3.connection.HTTPConnection object at 0x7f701294d110>: Failed to establish a new connection: [Errno 111] Connection refused'))
2023-08-09 11:40:05,163  ERROR       send_post.py  run  HTTPConnectionPool(host='0.0.0.0', port=9635): Max retries exceeded with url: /test (Caused by NewConnectionError('<urllib3.connection.HTTPConnection object at 0x7f5ab5015b10>: Failed to establish a new connection: [Errno 111] Connection refused'))
2023-08-09 11:40:05,618  ERROR       send_post.py  run  HTTPConnectionPool(host='0.0.0.0', port=9635): Max retries exceeded with url: /test (Caused by NewConnectionError('<urllib3.connection.HTTPConnection object at 0x7feba8a0e3d0>: Failed to establish a new connection: [Errno 111] Connection refused'))
2023-08-09 11:40:05,699  ERROR       send_post.py  run  HTTPConnectionPool(host='0.0.0.0', port=9635): Max retries exceeded with url: /test (Caused by NewConnectionError('<urllib3.connection.HTTPConnection object at 0x7ffa9a3fa590>: Failed to establish a new connection: [Errno 111] Connection refused'))
2023-08-09 11:40:05,714  ERROR       send_post.py  run  HTTPConnectionPool(host='0.0.0.0', port=9635): Max retries exceeded with url: /test (Caused by NewConnectionError('<urllib3.connection.HTTPConnection object at 0x7f7012987490>: Failed to establish a new connection: [Errno 111] Connection refused'))
2023-08-09 11:40:10,166  ERROR       send_post.py  run  HTTPConnectionPool(host='0.0.0.0', port=9635): Max retries exceeded with url: /test (Caused by NewConnectionError('<urllib3.connection.HTTPConnection object at 0x7f5af36ef6d0>: Failed to establish a new connection: [Errno 111] Connection refused'))
2023-08-09 11:40:10,620  ERROR       send_post.py  run  HTTPConnectionPool(host='0.0.0.0', port=9635): Max retries exceeded with url: /test (Caused by NewConnectionError('<urllib3.connection.HTTPConnection object at 0x7feba8a36ad0>: Failed to establish a new connection: [Errno 111] Connection refused'))
2023-08-09 11:40:10,717  ERROR       send_post.py  run  HTTPConnectionPool(host='0.0.0.0', port=9635): Max retries exceeded with url: /test (Caused by NewConnectionError('<urllib3.connection.HTTPConnection object at 0x7f7012984e10>: Failed to establish a new connection: [Errno 111] Connection refused'))
2023-08-09 11:40:15,169  ERROR       send_post.py  run  HTTPConnectionPool(host='0.0.0.0', port=9635): Max retries exceeded with url: /test (Caused by NewConnectionError('<urllib3.connection.HTTPConnection object at 0x7f5ab502f110>: Failed to establish a new connection: [Errno 111] Connection refused'))
2023-08-09 11:40:15,622  ERROR       send_post.py  run  HTTPConnectionPool(host='0.0.0.0', port=9635): Max retries exceeded with url: /test (Caused by NewConnectionError('<urllib3.connection.HTTPConnection object at 0x7feba8a37650>: Failed to establish a new connection: [Errno 111] Connection refused'))
2023-08-09 11:40:15,720  ERROR       send_post.py  run  HTTPConnectionPool(host='0.0.0.0', port=9635): Max retries exceeded with url: /test (Caused by NewConnectionError('<urllib3.connection.HTTPConnection object at 0x7f701296d9d0>: Failed to establish a new connection: [Errno 111] Connection refused'))
2023-08-09 11:40:20,173  ERROR       send_post.py  run  HTTPConnectionPool(host='0.0.0.0', port=9635): Max retries exceeded with url: /test (Caused by NewConnectionError('<urllib3.connection.HTTPConnection object at 0x7f5ab5017750>: Failed to establish a new connection: [Errno 111] Connection refused'))
2023-08-09 11:40:20,625  ERROR       send_post.py  run  HTTPConnectionPool(host='0.0.0.0', port=9635): Max retries exceeded with url: /test (Caused by NewConnectionError('<urllib3.connection.HTTPConnection object at 0x7feba8a1ca50>: Failed to establish a new connection: [Errno 111] Connection refused'))
2023-08-09 11:40:20,723  ERROR       send_post.py  run  HTTPConnectionPool(host='0.0.0.0', port=9635): Max retries exceeded with url: /test (Caused by NewConnectionError('<urllib3.connection.HTTPConnection object at 0x7f701296e410>: Failed to establish a new connection: [Errno 111] Connection refused'))
2023-08-09 11:40:25,176  ERROR       send_post.py  run  HTTPConnectionPool(host='0.0.0.0', port=9635): Max retries exceeded with url: /test (Caused by NewConnectionError('<urllib3.connection.HTTPConnection object at 0x7f5ab4fdf7d0>: Failed to establish a new connection: [Errno 111] Connection refused'))
2023-08-09 11:40:25,628  ERROR       send_post.py  run  HTTPConnectionPool(host='0.0.0.0', port=9635): Max retries exceeded with url: /test (Caused by NewConnectionError('<urllib3.connection.HTTPConnection object at 0x7feba8a30410>: Failed to establish a new connection: [Errno 111] Connection refused'))
2023-08-09 11:40:25,726  ERROR       send_post.py  run  HTTPConnectionPool(host='0.0.0.0', port=9635): Max retries exceeded with url: /test (Caused by NewConnectionError('<urllib3.connection.HTTPConnection object at 0x7f701297c2d0>: Failed to establish a new connection: [Errno 111] Connection refused'))
2023-08-09 11:40:30,179  ERROR       send_post.py  run  HTTPConnectionPool(host='0.0.0.0', port=9635): Max retries exceeded with url: /test (Caused by NewConnectionError('<urllib3.connection.HTTPConnection object at 0x7f5ab5009a50>: Failed to establish a new connection: [Errno 111] Connection refused'))
2023-08-09 11:40:30,630  ERROR       send_post.py  run  HTTPConnectionPool(host='0.0.0.0', port=9635): Max retries exceeded with url: /test (Caused by NewConnectionError('<urllib3.connection.HTTPConnection object at 0x7feba8a4bc90>: Failed to establish a new connection: [Errno 111] Connection refused'))
2023-08-09 11:40:30,730  ERROR       send_post.py  run  HTTPConnectionPool(host='0.0.0.0', port=9635): Max retries exceeded with url: /test (Caused by NewConnectionError('<urllib3.connection.HTTPConnection object at 0x7f701294cad0>: Failed to establish a new connection: [Errno 111] Connection refused'))
2023-08-09 11:40:35,182  ERROR       send_post.py  run  HTTPConnectionPool(host='0.0.0.0', port=9635): Max retries exceeded with url: /test (Caused by NewConnectionError('<urllib3.connection.HTTPConnection object at 0x7f5ab502ef90>: Failed to establish a new connection: [Errno 111] Connection refused'))
2023-08-09 11:40:35,633  ERROR       send_post.py  run  HTTPConnectionPool(host='0.0.0.0', port=9635): Max retries exceeded with url: /test (Caused by NewConnectionError('<urllib3.connection.HTTPConnection object at 0x7feba8a4a290>: Failed to establish a new connection: [Errno 111] Connection refused'))
2023-08-09 11:40:35,733  ERROR       send_post.py  run  HTTPConnectionPool(host='0.0.0.0', port=9635): Max retries exceeded with url: /test (Caused by NewConnectionError('<urllib3.connection.HTTPConnection object at 0x7f701297c610>: Failed to establish a new connection: [Errno 111] Connection refused'))
2023-08-09 11:40:40,184  ERROR       send_post.py  run  HTTPConnectionPool(host='0.0.0.0', port=9635): Max retries exceeded with url: /test (Caused by NewConnectionError('<urllib3.connection.HTTPConnection object at 0x7f5ab5029250>: Failed to establish a new connection: [Errno 111] Connection refused'))
2023-08-09 11:40:40,635  ERROR       send_post.py  run  HTTPConnectionPool(host='0.0.0.0', port=9635): Max retries exceeded with url: /test (Caused by NewConnectionError('<urllib3.connection.HTTPConnection object at 0x7feba8a48310>: Failed to establish a new connection: [Errno 111] Connection refused'))
2023-08-09 11:40:40,735  ERROR       send_post.py  run  HTTPConnectionPool(host='0.0.0.0', port=9635): Max retries exceeded with url: /test (Caused by NewConnectionError('<urllib3.connection.HTTPConnection object at 0x7f701296cfd0>: Failed to establish a new connection: [Errno 111] Connection refused'))
2023-08-09 11:40:45,142  ERROR       send_post.py  run  HTTPConnectionPool(host='0.0.0.0', port=9635): Max retries exceeded with url: /test (Caused by NewConnectionError('<urllib3.connection.HTTPConnection object at 0x7f528a19ead0>: Failed to establish a new connection: [Errno 111] Connection refused'))
2023-08-09 11:40:45,186  ERROR       send_post.py  run  HTTPConnectionPool(host='0.0.0.0', port=9635): Max retries exceeded with url: /test (Caused by NewConnectionError('<urllib3.connection.HTTPConnection object at 0x7f5ab5029650>: Failed to establish a new connection: [Errno 111] Connection refused'))
2023-08-09 11:40:45,637  ERROR       send_post.py  run  HTTPConnectionPool(host='0.0.0.0', port=9635): Max retries exceeded with url: /test (Caused by NewConnectionError('<urllib3.connection.HTTPConnection object at 0x7feba8a328d0>: Failed to establish a new connection: [Errno 111] Connection refused'))
2023-08-09 11:40:45,737  ERROR       send_post.py  run  HTTPConnectionPool(host='0.0.0.0', port=9635): Max retries exceeded with url: /test (Caused by NewConnectionError('<urllib3.connection.HTTPConnection object at 0x7f701296d990>: Failed to establish a new connection: [Errno 111] Connection refused'))
2023-08-09 11:40:50,189  ERROR       send_post.py  run  HTTPConnectionPool(host='0.0.0.0', port=9635): Max retries exceeded with url: /test (Caused by NewConnectionError('<urllib3.connection.HTTPConnection object at 0x7f5ab500a150>: Failed to establish a new connection: [Errno 111] Connection refused'))
2023-08-09 11:40:50,639  ERROR       send_post.py  run  HTTPConnectionPool(host='0.0.0.0', port=9635): Max retries exceeded with url: /test (Caused by NewConnectionError('<urllib3.connection.HTTPConnection object at 0x7feba8a30490>: Failed to establish a new connection: [Errno 111] Connection refused'))
2023-08-09 11:40:50,738  ERROR       send_post.py  run  HTTPConnectionPool(host='0.0.0.0', port=9635): Max retries exceeded with url: /test (Caused by NewConnectionError('<urllib3.connection.HTTPConnection object at 0x7f7012985890>: Failed to establish a new connection: [Errno 111] Connection refused'))
2023-08-09 11:40:55,192  ERROR       send_post.py  run  HTTPConnectionPool(host='0.0.0.0', port=9635): Max retries exceeded with url: /test (Caused by NewConnectionError('<urllib3.connection.HTTPConnection object at 0x7f5ab500b2d0>: Failed to establish a new connection: [Errno 111] Connection refused'))
2023-08-09 11:40:55,642  ERROR       send_post.py  run  HTTPConnectionPool(host='0.0.0.0', port=9635): Max retries exceeded with url: /test (Caused by NewConnectionError('<urllib3.connection.HTTPConnection object at 0x7feba8a42e90>: Failed to establish a new connection: [Errno 111] Connection refused'))
2023-08-09 11:40:55,741  ERROR       send_post.py  run  HTTPConnectionPool(host='0.0.0.0', port=9635): Max retries exceeded with url: /test (Caused by NewConnectionError('<urllib3.connection.HTTPConnection object at 0x7f7012970250>: Failed to establish a new connection: [Errno 111] Connection refused'))
2023-08-09 11:41:00,196  ERROR       send_post.py  run  HTTPConnectionPool(host='0.0.0.0', port=9635): Max retries exceeded with url: /test (Caused by NewConnectionError('<urllib3.connection.HTTPConnection object at 0x7f5ab502a190>: Failed to establish a new connection: [Errno 111] Connection refused'))
2023-08-09 11:41:00,645  ERROR       send_post.py  run  HTTPConnectionPool(host='0.0.0.0', port=9635): Max retries exceeded with url: /test (Caused by NewConnectionError('<urllib3.connection.HTTPConnection object at 0x7feba8a36350>: Failed to establish a new connection: [Errno 111] Connection refused'))
2023-08-09 11:41:00,745  ERROR       send_post.py  run  HTTPConnectionPool(host='0.0.0.0', port=9635): Max retries exceeded with url: /test (Caused by NewConnectionError('<urllib3.connection.HTTPConnection object at 0x7f7012999d50>: Failed to establish a new connection: [Errno 111] Connection refused'))
2023-08-09 11:41:05,199  ERROR       send_post.py  run  HTTPConnectionPool(host='0.0.0.0', port=9635): Max retries exceeded with url: /test (Caused by NewConnectionError('<urllib3.connection.HTTPConnection object at 0x7f5ab4fdf3d0>: Failed to establish a new connection: [Errno 111] Connection refused'))
2023-08-09 11:41:05,648  ERROR       send_post.py  run  HTTPConnectionPool(host='0.0.0.0', port=9635): Max retries exceeded with url: /test (Caused by NewConnectionError('<urllib3.connection.HTTPConnection object at 0x7feba8a42710>: Failed to establish a new connection: [Errno 111] Connection refused'))
2023-08-09 11:41:05,748  ERROR       send_post.py  run  HTTPConnectionPool(host='0.0.0.0', port=9635): Max retries exceeded with url: /test (Caused by NewConnectionError('<urllib3.connection.HTTPConnection object at 0x7f7012985810>: Failed to establish a new connection: [Errno 111] Connection refused'))
2023-08-09 11:41:10,201  ERROR       send_post.py  run  HTTPConnectionPool(host='0.0.0.0', port=9635): Max retries exceeded with url: /test (Caused by NewConnectionError('<urllib3.connection.HTTPConnection object at 0x7f5ab502c650>: Failed to establish a new connection: [Errno 111] Connection refused'))
2023-08-09 11:41:10,651  ERROR       send_post.py  run  HTTPConnectionPool(host='0.0.0.0', port=9635): Max retries exceeded with url: /test (Caused by NewConnectionError('<urllib3.connection.HTTPConnection object at 0x7feba8a338d0>: Failed to establish a new connection: [Errno 111] Connection refused'))
2023-08-09 11:41:10,751  ERROR       send_post.py  run  HTTPConnectionPool(host='0.0.0.0', port=9635): Max retries exceeded with url: /test (Caused by NewConnectionError('<urllib3.connection.HTTPConnection object at 0x7f7012985190>: Failed to establish a new connection: [Errno 111] Connection refused'))
2023-08-09 11:41:15,204  ERROR       send_post.py  run  HTTPConnectionPool(host='0.0.0.0', port=9635): Max retries exceeded with url: /test (Caused by NewConnectionError('<urllib3.connection.HTTPConnection object at 0x7f5ab50177d0>: Failed to establish a new connection: [Errno 111] Connection refused'))
2023-08-09 11:41:15,654  ERROR       send_post.py  run  HTTPConnectionPool(host='0.0.0.0', port=9635): Max retries exceeded with url: /test (Caused by NewConnectionError('<urllib3.connection.HTTPConnection object at 0x7feba8a32b10>: Failed to establish a new connection: [Errno 111] Connection refused'))
2023-08-09 11:41:15,754  ERROR       send_post.py  run  HTTPConnectionPool(host='0.0.0.0', port=9635): Max retries exceeded with url: /test (Caused by NewConnectionError('<urllib3.connection.HTTPConnection object at 0x7f701296d890>: Failed to establish a new connection: [Errno 111] Connection refused'))
2023-08-09 11:41:20,208  ERROR       send_post.py  run  HTTPConnectionPool(host='0.0.0.0', port=9635): Max retries exceeded with url: /test (Caused by NewConnectionError('<urllib3.connection.HTTPConnection object at 0x7f5ab5039690>: Failed to establish a new connection: [Errno 111] Connection refused'))
2023-08-09 11:41:20,657  ERROR       send_post.py  run  HTTPConnectionPool(host='0.0.0.0', port=9635): Max retries exceeded with url: /test (Caused by NewConnectionError('<urllib3.connection.HTTPConnection object at 0x7feba8a48090>: Failed to establish a new connection: [Errno 111] Connection refused'))
2023-08-09 11:41:20,756  ERROR       send_post.py  run  HTTPConnectionPool(host='0.0.0.0', port=9635): Max retries exceeded with url: /test (Caused by NewConnectionError('<urllib3.connection.HTTPConnection object at 0x7f701296cc50>: Failed to establish a new connection: [Errno 111] Connection refused'))
2023-08-09 11:41:25,210  ERROR       send_post.py  run  HTTPConnectionPool(host='0.0.0.0', port=9635): Max retries exceeded with url: /test (Caused by NewConnectionError('<urllib3.connection.HTTPConnection object at 0x7f5af01bebd0>: Failed to establish a new connection: [Errno 111] Connection refused'))
2023-08-09 11:41:25,659  ERROR       send_post.py  run  HTTPConnectionPool(host='0.0.0.0', port=9635): Max retries exceeded with url: /test (Caused by NewConnectionError('<urllib3.connection.HTTPConnection object at 0x7feba89ea5d0>: Failed to establish a new connection: [Errno 111] Connection refused'))
2023-08-09 11:41:25,759  ERROR       send_post.py  run  HTTPConnectionPool(host='0.0.0.0', port=9635): Max retries exceeded with url: /test (Caused by NewConnectionError('<urllib3.connection.HTTPConnection object at 0x7f701297e8d0>: Failed to establish a new connection: [Errno 111] Connection refused'))
2023-08-09 11:41:30,213  ERROR       send_post.py  run  HTTPConnectionPool(host='0.0.0.0', port=9635): Max retries exceeded with url: /test (Caused by NewConnectionError('<urllib3.connection.HTTPConnection object at 0x7f5ab502ecd0>: Failed to establish a new connection: [Errno 111] Connection refused'))
2023-08-09 11:41:30,662  ERROR       send_post.py  run  HTTPConnectionPool(host='0.0.0.0', port=9635): Max retries exceeded with url: /test (Caused by NewConnectionError('<urllib3.connection.HTTPConnection object at 0x7feba8a34bd0>: Failed to establish a new connection: [Errno 111] Connection refused'))
2023-08-09 11:41:30,763  ERROR       send_post.py  run  HTTPConnectionPool(host='0.0.0.0', port=9635): Max retries exceeded with url: /test (Caused by NewConnectionError('<urllib3.connection.HTTPConnection object at 0x7f70129a01d0>: Failed to establish a new connection: [Errno 111] Connection refused'))
2023-08-09 11:41:35,216  ERROR       send_post.py  run  HTTPConnectionPool(host='0.0.0.0', port=9635): Max retries exceeded with url: /test (Caused by NewConnectionError('<urllib3.connection.HTTPConnection object at 0x7f5ab502d350>: Failed to establish a new connection: [Errno 111] Connection refused'))
2023-08-09 11:41:35,664  ERROR       send_post.py  run  HTTPConnectionPool(host='0.0.0.0', port=9635): Max retries exceeded with url: /test (Caused by NewConnectionError('<urllib3.connection.HTTPConnection object at 0x7feba8a4b610>: Failed to establish a new connection: [Errno 111] Connection refused'))
2023-08-09 11:41:35,765  ERROR       send_post.py  run  HTTPConnectionPool(host='0.0.0.0', port=9635): Max retries exceeded with url: /test (Caused by NewConnectionError('<urllib3.connection.HTTPConnection object at 0x7f701297ef50>: Failed to establish a new connection: [Errno 111] Connection refused'))
2023-08-09 11:41:40,219  ERROR       send_post.py  run  HTTPConnectionPool(host='0.0.0.0', port=9635): Max retries exceeded with url: /test (Caused by NewConnectionError('<urllib3.connection.HTTPConnection object at 0x7f5ab502a610>: Failed to establish a new connection: [Errno 111] Connection refused'))
2023-08-09 11:41:40,667  ERROR       send_post.py  run  HTTPConnectionPool(host='0.0.0.0', port=9635): Max retries exceeded with url: /test (Caused by NewConnectionError('<urllib3.connection.HTTPConnection object at 0x7feba8a48890>: Failed to establish a new connection: [Errno 111] Connection refused'))
2023-08-09 11:41:40,767  ERROR       send_post.py  run  HTTPConnectionPool(host='0.0.0.0', port=9635): Max retries exceeded with url: /test (Caused by NewConnectionError('<urllib3.connection.HTTPConnection object at 0x7f701296c450>: Failed to establish a new connection: [Errno 111] Connection refused'))
2023-08-09 11:41:45,221  ERROR       send_post.py  run  HTTPConnectionPool(host='0.0.0.0', port=9635): Max retries exceeded with url: /test (Caused by NewConnectionError('<urllib3.connection.HTTPConnection object at 0x7f5ab500b5d0>: Failed to establish a new connection: [Errno 111] Connection refused'))
2023-08-09 11:41:45,670  ERROR       send_post.py  run  HTTPConnectionPool(host='0.0.0.0', port=9635): Max retries exceeded with url: /test (Caused by NewConnectionError('<urllib3.connection.HTTPConnection object at 0x7feba8a30050>: Failed to establish a new connection: [Errno 111] Connection refused'))
2023-08-09 11:41:45,770  ERROR       send_post.py  run  HTTPConnectionPool(host='0.0.0.0', port=9635): Max retries exceeded with url: /test (Caused by NewConnectionError('<urllib3.connection.HTTPConnection object at 0x7f701296d790>: Failed to establish a new connection: [Errno 111] Connection refused'))
2023-08-09 11:41:50,225  ERROR       send_post.py  run  HTTPConnectionPool(host='0.0.0.0', port=9635): Max retries exceeded with url: /test (Caused by NewConnectionError('<urllib3.connection.HTTPConnection object at 0x7f5ab5038410>: Failed to establish a new connection: [Errno 111] Connection refused'))
2023-08-09 11:41:50,673  ERROR       send_post.py  run  HTTPConnectionPool(host='0.0.0.0', port=9635): Max retries exceeded with url: /test (Caused by NewConnectionError('<urllib3.connection.HTTPConnection object at 0x7feba8a32dd0>: Failed to establish a new connection: [Errno 111] Connection refused'))
2023-08-09 11:41:50,773  ERROR       send_post.py  run  HTTPConnectionPool(host='0.0.0.0', port=9635): Max retries exceeded with url: /test (Caused by NewConnectionError('<urllib3.connection.HTTPConnection object at 0x7f7012985350>: Failed to establish a new connection: [Errno 111] Connection refused'))
2023-08-09 11:41:55,228  ERROR       send_post.py  run  HTTPConnectionPool(host='0.0.0.0', port=9635): Max retries exceeded with url: /test (Caused by NewConnectionError('<urllib3.connection.HTTPConnection object at 0x7f5ab50285d0>: Failed to establish a new connection: [Errno 111] Connection refused'))
2023-08-09 11:41:55,676  ERROR       send_post.py  run  HTTPConnectionPool(host='0.0.0.0', port=9635): Max retries exceeded with url: /test (Caused by NewConnectionError('<urllib3.connection.HTTPConnection object at 0x7feba8a41a10>: Failed to establish a new connection: [Errno 111] Connection refused'))
2023-08-09 11:41:55,776  ERROR       send_post.py  run  HTTPConnectionPool(host='0.0.0.0', port=9635): Max retries exceeded with url: /test (Caused by NewConnectionError('<urllib3.connection.HTTPConnection object at 0x7f7012998fd0>: Failed to establish a new connection: [Errno 111] Connection refused'))
2023-08-09 11:42:00,231  ERROR       send_post.py  run  HTTPConnectionPool(host='0.0.0.0', port=9635): Max retries exceeded with url: /test (Caused by NewConnectionError('<urllib3.connection.HTTPConnection object at 0x7f5ab5028710>: Failed to establish a new connection: [Errno 111] Connection refused'))
2023-08-09 11:42:00,679  ERROR       send_post.py  run  HTTPConnectionPool(host='0.0.0.0', port=9635): Max retries exceeded with url: /test (Caused by NewConnectionError('<urllib3.connection.HTTPConnection object at 0x7feba8a1e990>: Failed to establish a new connection: [Errno 111] Connection refused'))
2023-08-09 11:42:00,779  ERROR       send_post.py  run  HTTPConnectionPool(host='0.0.0.0', port=9635): Max retries exceeded with url: /test (Caused by NewConnectionError('<urllib3.connection.HTTPConnection object at 0x7f70129a2610>: Failed to establish a new connection: [Errno 111] Connection refused'))
2023-08-09 11:42:05,234  ERROR       send_post.py  run  HTTPConnectionPool(host='0.0.0.0', port=9635): Max retries exceeded with url: /test (Caused by NewConnectionError('<urllib3.connection.HTTPConnection object at 0x7f5ab502f590>: Failed to establish a new connection: [Errno 111] Connection refused'))
2023-08-09 11:42:05,683  ERROR       send_post.py  run  HTTPConnectionPool(host='0.0.0.0', port=9635): Max retries exceeded with url: /test (Caused by NewConnectionError('<urllib3.connection.HTTPConnection object at 0x7feba8a41e10>: Failed to establish a new connection: [Errno 111] Connection refused'))
2023-08-09 11:42:05,782  ERROR       send_post.py  run  HTTPConnectionPool(host='0.0.0.0', port=9635): Max retries exceeded with url: /test (Caused by NewConnectionError('<urllib3.connection.HTTPConnection object at 0x7f7012984dd0>: Failed to establish a new connection: [Errno 111] Connection refused'))
2023-08-09 11:42:10,237  ERROR       send_post.py  run  HTTPConnectionPool(host='0.0.0.0', port=9635): Max retries exceeded with url: /test (Caused by NewConnectionError('<urllib3.connection.HTTPConnection object at 0x7f5ab4fde850>: Failed to establish a new connection: [Errno 111] Connection refused'))
2023-08-09 11:42:10,684  ERROR       send_post.py  run  HTTPConnectionPool(host='0.0.0.0', port=9635): Max retries exceeded with url: /test (Caused by NewConnectionError('<urllib3.connection.HTTPConnection object at 0x7feba8a32d10>: Failed to establish a new connection: [Errno 111] Connection refused'))
2023-08-09 11:42:10,785  ERROR       send_post.py  run  HTTPConnectionPool(host='0.0.0.0', port=9635): Max retries exceeded with url: /test (Caused by NewConnectionError('<urllib3.connection.HTTPConnection object at 0x7f7012926190>: Failed to establish a new connection: [Errno 111] Connection refused'))
2023-08-09 11:42:12,747  ERROR       send_post.py  run  HTTPConnectionPool(host='0.0.0.0', port=9635): Max retries exceeded with url: /test (Caused by NewConnectionError('<urllib3.connection.HTTPConnection object at 0x7febe88830a0>: Failed to establish a new connection: [Errno 111] Connection refused'))
2023-08-09 11:42:15,240  ERROR       send_post.py  run  HTTPConnectionPool(host='0.0.0.0', port=9635): Max retries exceeded with url: /test (Caused by NewConnectionError('<urllib3.connection.HTTPConnection object at 0x7f5ab500b210>: Failed to establish a new connection: [Errno 111] Connection refused'))
2023-08-09 11:42:15,687  ERROR       send_post.py  run  HTTPConnectionPool(host='0.0.0.0', port=9635): Max retries exceeded with url: /test (Caused by NewConnectionError('<urllib3.connection.HTTPConnection object at 0x7feba8a32b10>: Failed to establish a new connection: [Errno 111] Connection refused'))
2023-08-09 11:42:17,753  ERROR       send_post.py  run  HTTPConnectionPool(host='0.0.0.0', port=9635): Max retries exceeded with url: /test (Caused by NewConnectionError('<urllib3.connection.HTTPConnection object at 0x7febe88c4ac0>: Failed to establish a new connection: [Errno 111] Connection refused'))
2023-08-09 11:42:20,244  ERROR       send_post.py  run  HTTPConnectionPool(host='0.0.0.0', port=9635): Max retries exceeded with url: /test (Caused by NewConnectionError('<urllib3.connection.HTTPConnection object at 0x7f5ab503bad0>: Failed to establish a new connection: [Errno 111] Connection refused'))
2023-08-09 11:42:20,690  ERROR       send_post.py  run  HTTPConnectionPool(host='0.0.0.0', port=9635): Max retries exceeded with url: /test (Caused by NewConnectionError('<urllib3.connection.HTTPConnection object at 0x7feba8a48450>: Failed to establish a new connection: [Errno 111] Connection refused'))
2023-08-09 11:42:22,757  ERROR       send_post.py  run  HTTPConnectionPool(host='0.0.0.0', port=9635): Max retries exceeded with url: /test (Caused by NewConnectionError('<urllib3.connection.HTTPConnection object at 0x7febe88c5390>: Failed to establish a new connection: [Errno 111] Connection refused'))
2023-08-09 11:42:25,247  ERROR       send_post.py  run  HTTPConnectionPool(host='0.0.0.0', port=9635): Max retries exceeded with url: /test (Caused by NewConnectionError('<urllib3.connection.HTTPConnection object at 0x7f5ab4fdf8d0>: Failed to establish a new connection: [Errno 111] Connection refused'))
2023-08-09 11:42:25,693  ERROR       send_post.py  run  HTTPConnectionPool(host='0.0.0.0', port=9635): Max retries exceeded with url: /test (Caused by NewConnectionError('<urllib3.connection.HTTPConnection object at 0x7feba8a36250>: Failed to establish a new connection: [Errno 111] Connection refused'))
2023-08-09 11:42:30,249  ERROR       send_post.py  run  HTTPConnectionPool(host='0.0.0.0', port=9635): Max retries exceeded with url: /test (Caused by NewConnectionError('<urllib3.connection.HTTPConnection object at 0x7f5ab502fd10>: Failed to establish a new connection: [Errno 111] Connection refused'))
2023-08-09 11:42:30,696  ERROR       send_post.py  run  HTTPConnectionPool(host='0.0.0.0', port=9635): Max retries exceeded with url: /test (Caused by NewConnectionError('<urllib3.connection.HTTPConnection object at 0x7feba8a0e8d0>: Failed to establish a new connection: [Errno 111] Connection refused'))
2023-08-09 11:42:35,251  ERROR       send_post.py  run  HTTPConnectionPool(host='0.0.0.0', port=9635): Max retries exceeded with url: /test (Caused by NewConnectionError('<urllib3.connection.HTTPConnection object at 0x7f5ab502f210>: Failed to establish a new connection: [Errno 111] Connection refused'))
2023-08-09 11:42:35,698  ERROR       send_post.py  run  HTTPConnectionPool(host='0.0.0.0', port=9635): Max retries exceeded with url: /test (Caused by NewConnectionError('<urllib3.connection.HTTPConnection object at 0x7febe331b1d0>: Failed to establish a new connection: [Errno 111] Connection refused'))
2023-08-09 11:42:40,254  ERROR       send_post.py  run  HTTPConnectionPool(host='0.0.0.0', port=9635): Max retries exceeded with url: /test (Caused by NewConnectionError('<urllib3.connection.HTTPConnection object at 0x7f5ab50288d0>: Failed to establish a new connection: [Errno 111] Connection refused'))
2023-08-09 11:42:40,701  ERROR       send_post.py  run  HTTPConnectionPool(host='0.0.0.0', port=9635): Max retries exceeded with url: /test (Caused by NewConnectionError('<urllib3.connection.HTTPConnection object at 0x7feba8a488d0>: Failed to establish a new connection: [Errno 111] Connection refused'))
2023-08-09 11:42:45,257  ERROR       send_post.py  run  HTTPConnectionPool(host='0.0.0.0', port=9635): Max retries exceeded with url: /test (Caused by NewConnectionError('<urllib3.connection.HTTPConnection object at 0x7f5ab502a310>: Failed to establish a new connection: [Errno 111] Connection refused'))
2023-08-09 11:42:45,704  ERROR       send_post.py  run  HTTPConnectionPool(host='0.0.0.0', port=9635): Max retries exceeded with url: /test (Caused by NewConnectionError('<urllib3.connection.HTTPConnection object at 0x7feba8a31010>: Failed to establish a new connection: [Errno 111] Connection refused'))
2023-08-09 11:42:50,259  ERROR       send_post.py  run  HTTPConnectionPool(host='0.0.0.0', port=9635): Max retries exceeded with url: /test (Caused by NewConnectionError('<urllib3.connection.HTTPConnection object at 0x7f5ab5041f50>: Failed to establish a new connection: [Errno 111] Connection refused'))
2023-08-09 11:42:50,705  ERROR       send_post.py  run  HTTPConnectionPool(host='0.0.0.0', port=9635): Max retries exceeded with url: /test (Caused by NewConnectionError('<urllib3.connection.HTTPConnection object at 0x7feba8a30f90>: Failed to establish a new connection: [Errno 111] Connection refused'))
2023-08-09 11:42:55,261  ERROR       send_post.py  run  HTTPConnectionPool(host='0.0.0.0', port=9635): Max retries exceeded with url: /test (Caused by NewConnectionError('<urllib3.connection.HTTPConnection object at 0x7f5ab502a650>: Failed to establish a new connection: [Errno 111] Connection refused'))
2023-08-09 11:42:55,708  ERROR       send_post.py  run  HTTPConnectionPool(host='0.0.0.0', port=9635): Max retries exceeded with url: /test (Caused by NewConnectionError('<urllib3.connection.HTTPConnection object at 0x7feba8a43750>: Failed to establish a new connection: [Errno 111] Connection refused'))
2023-08-09 11:43:00,264  ERROR       send_post.py  run  HTTPConnectionPool(host='0.0.0.0', port=9635): Max retries exceeded with url: /test (Caused by NewConnectionError('<urllib3.connection.HTTPConnection object at 0x7f5af36a8f10>: Failed to establish a new connection: [Errno 111] Connection refused'))
2023-08-09 11:43:00,712  ERROR       send_post.py  run  HTTPConnectionPool(host='0.0.0.0', port=9635): Max retries exceeded with url: /test (Caused by NewConnectionError('<urllib3.connection.HTTPConnection object at 0x7feba8a0ee50>: Failed to establish a new connection: [Errno 111] Connection refused'))
2023-08-09 11:43:05,267  ERROR       send_post.py  run  HTTPConnectionPool(host='0.0.0.0', port=9635): Max retries exceeded with url: /test (Caused by NewConnectionError('<urllib3.connection.HTTPConnection object at 0x7f5ab502c950>: Failed to establish a new connection: [Errno 111] Connection refused'))
2023-08-09 11:43:05,714  ERROR       send_post.py  run  HTTPConnectionPool(host='0.0.0.0', port=9635): Max retries exceeded with url: /test (Caused by NewConnectionError('<urllib3.connection.HTTPConnection object at 0x7feba8a40a10>: Failed to establish a new connection: [Errno 111] Connection refused'))
2023-08-09 11:43:10,270  ERROR       send_post.py  run  HTTPConnectionPool(host='0.0.0.0', port=9635): Max retries exceeded with url: /test (Caused by NewConnectionError('<urllib3.connection.HTTPConnection object at 0x7f5ab502fa10>: Failed to establish a new connection: [Errno 111] Connection refused'))
2023-08-09 11:43:10,717  ERROR       send_post.py  run  HTTPConnectionPool(host='0.0.0.0', port=9635): Max retries exceeded with url: /test (Caused by NewConnectionError('<urllib3.connection.HTTPConnection object at 0x7feba8a33650>: Failed to establish a new connection: [Errno 111] Connection refused'))
2023-08-09 11:43:15,273  ERROR       send_post.py  run  HTTPConnectionPool(host='0.0.0.0', port=9635): Max retries exceeded with url: /test (Caused by NewConnectionError('<urllib3.connection.HTTPConnection object at 0x7f5ab5014950>: Failed to establish a new connection: [Errno 111] Connection refused'))
2023-08-09 11:43:15,720  ERROR       send_post.py  run  HTTPConnectionPool(host='0.0.0.0', port=9635): Max retries exceeded with url: /test (Caused by NewConnectionError('<urllib3.connection.HTTPConnection object at 0x7feba8a30310>: Failed to establish a new connection: [Errno 111] Connection refused'))
2023-08-09 11:43:20,277  ERROR       send_post.py  run  HTTPConnectionPool(host='0.0.0.0', port=9635): Max retries exceeded with url: /test (Caused by NewConnectionError('<urllib3.connection.HTTPConnection object at 0x7f5ab50543d0>: Failed to establish a new connection: [Errno 111] Connection refused'))
2023-08-09 11:43:20,723  ERROR       send_post.py  run  HTTPConnectionPool(host='0.0.0.0', port=9635): Max retries exceeded with url: /test (Caused by NewConnectionError('<urllib3.connection.HTTPConnection object at 0x7feba8a49510>: Failed to establish a new connection: [Errno 111] Connection refused'))
2023-08-09 11:43:25,279  ERROR       send_post.py  run  HTTPConnectionPool(host='0.0.0.0', port=9635): Max retries exceeded with url: /test (Caused by NewConnectionError('<urllib3.connection.HTTPConnection object at 0x7f5ab50425d0>: Failed to establish a new connection: [Errno 111] Connection refused'))
2023-08-09 11:43:25,726  ERROR       send_post.py  run  HTTPConnectionPool(host='0.0.0.0', port=9635): Max retries exceeded with url: /test (Caused by NewConnectionError('<urllib3.connection.HTTPConnection object at 0x7feba8a36250>: Failed to establish a new connection: [Errno 111] Connection refused'))
2023-08-09 13:22:42,848  ERROR       send_post.py  post_report  HTTPConnectionPool(host='localhost', port=8090): Read timed out. (read timeout=3)
2023-08-09 13:23:38,796  ERROR       send_post.py  post_report  HTTPConnectionPool(host='localhost', port=8090): Read timed out. (read timeout=3)
2023-08-09 13:24:38,848  ERROR       send_post.py  post_report  HTTPConnectionPool(host='localhost', port=8090): Read timed out. (read timeout=3)
2023-08-09 13:25:38,848  ERROR       send_post.py  post_report  HTTPConnectionPool(host='localhost', port=8090): Read timed out. (read timeout=3)
2023-08-09 13:26:38,824  ERROR       send_post.py  post_report  HTTPConnectionPool(host='localhost', port=8090): Read timed out. (read timeout=3)
2023-08-09 13:27:38,856  ERROR       send_post.py  post_report  HTTPConnectionPool(host='localhost', port=8090): Read timed out. (read timeout=3)
2023-08-09 13:28:38,805  ERROR       send_post.py  post_report  HTTPConnectionPool(host='localhost', port=8090): Read timed out. (read timeout=3)
2023-08-09 13:29:38,805  ERROR       send_post.py  post_report  HTTPConnectionPool(host='localhost', port=8090): Read timed out. (read timeout=3)
2023-08-09 13:30:38,832  ERROR       send_post.py  post_report  HTTPConnectionPool(host='localhost', port=8090): Read timed out. (read timeout=3)
2023-08-09 13:31:38,823  ERROR       send_post.py  post_report  HTTPConnectionPool(host='localhost', port=8090): Read timed out. (read timeout=3)
2023-08-09 13:32:38,828  ERROR       send_post.py  post_report  HTTPConnectionPool(host='localhost', port=8090): Read timed out. (read timeout=3)
2023-08-09 13:33:38,828  ERROR       send_post.py  post_report  HTTPConnectionPool(host='localhost', port=8090): Read timed out. (read timeout=3)
2023-08-09 13:34:38,833  ERROR       send_post.py  post_report  HTTPConnectionPool(host='localhost', port=8090): Read timed out. (read timeout=3)
2023-08-09 14:05:57,272  ERROR       send_post.py  post_report  HTTPConnectionPool(host='localhost', port=8090): Max retries exceeded with url: /api/v1/result (Caused by NewConnectionError('<urllib3.connection.HTTPConnection object at 0x7f7cb48c4be0>: Failed to establish a new connection: [Errno 111] Connection refused'))
2023-08-09 14:08:02,596  ERROR       send_post.py  post_report  HTTPConnectionPool(host='localhost', port=8090): Max retries exceeded with url: /api/v1/result (Caused by NewConnectionError('<urllib3.connection.HTTPConnection object at 0x7fba6f1d4850>: Failed to establish a new connection: [Errno 111] Connection refused'))
2023-08-09 14:08:05,799  ERROR       send_post.py  post_report  HTTPConnectionPool(host='localhost', port=8090): Max retries exceeded with url: /api/v1/result (Caused by NewConnectionError('<urllib3.connection.HTTPConnection object at 0x7f6cd7bd4850>: Failed to establish a new connection: [Errno 111] Connection refused'))
2023-08-09 14:08:08,092  ERROR       send_post.py  post_report  HTTPConnectionPool(host='localhost', port=8090): Max retries exceeded with url: /api/v1/result (Caused by NewConnectionError('<urllib3.connection.HTTPConnection object at 0x7f91729c4850>: Failed to establish a new connection: [Errno 111] Connection refused'))
2023-08-09 14:13:56,915  ERROR       send_post.py  post_report  HTTPConnectionPool(host='localhost', port=8090): Read timed out. (read timeout=3)
2023-08-09 14:14:06,835  ERROR       send_post.py  post_report  HTTPConnectionPool(host='localhost', port=8090): Read timed out. (read timeout=3)
2023-08-09 14:14:20,736  ERROR       send_post.py  post_report  HTTPConnectionPool(host='localhost', port=8090): Read timed out. (read timeout=3)
2023-08-09 14:16:53,936  ERROR       send_post.py  post_report  HTTPConnectionPool(host='localhost', port=8090): Read timed out. (read timeout=3)
2023-08-10 14:00:05,725  ERROR       send_post.py  post_report  HTTPConnectionPool(host='localhost', port=8090): Max retries exceeded with url: /api/v1/result (Caused by NewConnectionError('<urllib3.connection.HTTPConnection object at 0x7eff09dd48e0>: Failed to establish a new connection: [Errno 111] Connection refused'))
2023-08-10 14:00:06,094  ERROR       send_post.py  post_report  HTTPConnectionPool(host='localhost', port=8090): Max retries exceeded with url: /api/v1/result (Caused by NewConnectionError('<urllib3.connection.HTTPConnection object at 0x7eff09dd4c10>: Failed to establish a new connection: [Errno 111] Connection refused'))
2023-08-10 14:01:01,381  ERROR       send_post.py  post_report  HTTPConnectionPool(host='localhost', port=8090): Max retries exceeded with url: /api/v1/result (Caused by NewConnectionError('<urllib3.connection.HTTPConnection object at 0x7fb2d38c08e0>: Failed to establish a new connection: [Errno 111] Connection refused'))
2023-08-10 14:01:01,747  ERROR       send_post.py  post_report  HTTPConnectionPool(host='localhost', port=8090): Max retries exceeded with url: /api/v1/result (Caused by NewConnectionError('<urllib3.connection.HTTPConnection object at 0x7fb2d38c0c10>: Failed to establish a new connection: [Errno 111] Connection refused'))
2023-08-10 14:04:47,835  ERROR       send_post.py  post_report  HTTPConnectionPool(host='localhost', port=8090): Max retries exceeded with url: /api/v1/result (Caused by NewConnectionError('<urllib3.connection.HTTPConnection object at 0x7fee6b5c8a00>: Failed to establish a new connection: [Errno 111] Connection refused'))
2023-08-10 14:04:48,189  ERROR       send_post.py  post_report  HTTPConnectionPool(host='localhost', port=8090): Max retries exceeded with url: /api/v1/result (Caused by NewConnectionError('<urllib3.connection.HTTPConnection object at 0x7fee6b5c8d30>: Failed to establish a new connection: [Errno 111] Connection refused'))
2023-08-14 14:55:28,365  ERROR       send_post.py  post_report  HTTPConnectionPool(host='localhost', port=8090): Max retries exceeded with url: /api/v1/result (Caused by NewConnectionError('<urllib3.connection.HTTPConnection object at 0x7f169ba0e250>: Failed to establish a new connection: [Errno 111] Connection refused'))
2023-08-18 15:16:18,875  ERROR       send_post.py  run  HTTPConnectionPool(host='0.0.0.0', port=9636): Max retries exceeded with url: /test (Caused by NewConnectionError('<urllib3.connection.HTTPConnection object at 0x7f8c5e831270>: Failed to establish a new connection: [Errno 111] Connection refused'))
2023-08-18 15:16:23,883  ERROR       send_post.py  run  HTTPConnectionPool(host='0.0.0.0', port=9636): Max retries exceeded with url: /test (Caused by NewConnectionError('<urllib3.connection.HTTPConnection object at 0x7f8c5e832cb0>: Failed to establish a new connection: [Errno 111] Connection refused'))
2023-08-18 15:16:28,892  ERROR       send_post.py  run  HTTPConnectionPool(host='0.0.0.0', port=9636): Max retries exceeded with url: /test (Caused by NewConnectionError('<urllib3.connection.HTTPConnection object at 0x7f8c5e833520>: Failed to establish a new connection: [Errno 111] Connection refused'))
2023-08-18 15:16:33,903  ERROR       send_post.py  run  HTTPConnectionPool(host='0.0.0.0', port=9636): Max retries exceeded with url: /test (Caused by NewConnectionError('<urllib3.connection.HTTPConnection object at 0x7f8c5e833df0>: Failed to establish a new connection: [Errno 111] Connection refused'))
2023-08-18 15:16:38,915  ERROR       send_post.py  run  HTTPConnectionPool(host='0.0.0.0', port=9636): Max retries exceeded with url: /test (Caused by NewConnectionError('<urllib3.connection.HTTPConnection object at 0x7f8c5e833ac0>: Failed to establish a new connection: [Errno 111] Connection refused'))
2023-08-18 15:16:43,927  ERROR       send_post.py  run  HTTPConnectionPool(host='0.0.0.0', port=9636): Max retries exceeded with url: /test (Caused by NewConnectionError('<urllib3.connection.HTTPConnection object at 0x7f8c5e8331f0>: Failed to establish a new connection: [Errno 111] Connection refused'))
2023-08-18 15:16:48,935  ERROR       send_post.py  run  HTTPConnectionPool(host='0.0.0.0', port=9636): Max retries exceeded with url: /test (Caused by NewConnectionError('<urllib3.connection.HTTPConnection object at 0x7f8c5e832980>: Failed to establish a new connection: [Errno 111] Connection refused'))
2023-08-18 15:16:53,948  ERROR       send_post.py  run  HTTPConnectionPool(host='0.0.0.0', port=9636): Max retries exceeded with url: /test (Caused by NewConnectionError('<urllib3.connection.HTTPConnection object at 0x7f8c5e831870>: Failed to establish a new connection: [Errno 111] Connection refused'))
2023-08-18 15:16:58,961  ERROR       send_post.py  run  HTTPConnectionPool(host='0.0.0.0', port=9636): Max retries exceeded with url: /test (Caused by NewConnectionError('<urllib3.connection.HTTPConnection object at 0x7f8c5e124730>: Failed to establish a new connection: [Errno 111] Connection refused'))
2023-08-18 15:17:03,974  ERROR       send_post.py  run  HTTPConnectionPool(host='0.0.0.0', port=9636): Max retries exceeded with url: /test (Caused by NewConnectionError('<urllib3.connection.HTTPConnection object at 0x7f8c5e831930>: Failed to establish a new connection: [Errno 111] Connection refused'))
2023-08-18 15:17:08,983  ERROR       send_post.py  run  HTTPConnectionPool(host='0.0.0.0', port=9636): Max retries exceeded with url: /test (Caused by NewConnectionError('<urllib3.connection.HTTPConnection object at 0x7f8c5e832fb0>: Failed to establish a new connection: [Errno 111] Connection refused'))
2023-08-18 15:17:13,991  ERROR       send_post.py  run  HTTPConnectionPool(host='0.0.0.0', port=9636): Max retries exceeded with url: /test (Caused by NewConnectionError('<urllib3.connection.HTTPConnection object at 0x7f8c5e833880>: Failed to establish a new connection: [Errno 111] Connection refused'))
2023-08-18 15:17:19,004  ERROR       send_post.py  run  HTTPConnectionPool(host='0.0.0.0', port=9636): Max retries exceeded with url: /test (Caused by NewConnectionError('<urllib3.connection.HTTPConnection object at 0x7f8c5e833910>: Failed to establish a new connection: [Errno 111] Connection refused'))
2023-08-18 15:18:05,897  ERROR       send_post.py  run  HTTPConnectionPool(host='host.docker.internal', port=9636): Max retries exceeded with url: /test (Caused by NameResolutionError("<urllib3.connection.HTTPConnection object at 0x7fac7eb1d270>: Failed to resolve 'host.docker.internal' ([Errno -2] Name or service not known)"))
2023-08-18 15:18:11,070  ERROR       send_post.py  run  HTTPConnectionPool(host='host.docker.internal', port=9636): Max retries exceeded with url: /test (Caused by NameResolutionError("<urllib3.connection.HTTPConnection object at 0x7fac7eb1ecb0>: Failed to resolve 'host.docker.internal' ([Errno -2] Name or service not known)"))
2023-08-18 15:18:16,125  ERROR       send_post.py  run  HTTPConnectionPool(host='host.docker.internal', port=9636): Max retries exceeded with url: /test (Caused by NameResolutionError("<urllib3.connection.HTTPConnection object at 0x7fac7eb1f520>: Failed to resolve 'host.docker.internal' ([Errno -2] Name or service not known)"))
2023-08-18 15:18:21,222  ERROR       send_post.py  run  HTTPConnectionPool(host='host.docker.internal', port=9636): Max retries exceeded with url: /test (Caused by NameResolutionError("<urllib3.connection.HTTPConnection object at 0x7fac7eb1fdf0>: Failed to resolve 'host.docker.internal' ([Errno -2] Name or service not known)"))
2023-08-18 15:18:26,239  ERROR       send_post.py  run  HTTPConnectionPool(host='host.docker.internal', port=9636): Max retries exceeded with url: /test (Caused by NameResolutionError("<urllib3.connection.HTTPConnection object at 0x7fac7eb1fa00>: Failed to resolve 'host.docker.internal' ([Errno -2] Name or service not known)"))
2023-08-18 15:20:15,275  ERROR       send_post.py  post_report  HTTPConnectionPool(host='localhost', port=8090): Max retries exceeded with url: /api/v1/result (Caused by NewConnectionError('<urllib3.connection.HTTPConnection object at 0x7f32220569e0>: Failed to establish a new connection: [Errno 111] Connection refused'))
2023-08-18 15:20:15,627  ERROR       send_post.py  post_report  HTTPConnectionPool(host='localhost', port=8090): Max retries exceeded with url: /api/v1/result (Caused by NewConnectionError('<urllib3.connection.HTTPConnection object at 0x7f32220569e0>: Failed to establish a new connection: [Errno 111] Connection refused'))
