2023-06-05 18:31:25,212  ERROR       send_post.py  run  HTTPConnectionPool(host='0.0.0.0', port=9624): Max retries exceeded with url: /test (Caused by NewConnectionError('<urllib3.connection.HTTPConnection object at 0x7fcc491dfaf0>: Failed to establish a new connection: [Errno 111] Connection refused'))
2023-06-05 18:31:36,456  ERROR       send_post.py  main  scene is not correct
2023-06-06 10:53:54,332  ERROR       send_post.py  run_rtsp_gpu  frame_192.168.0.20 is not update
2023-06-06 10:53:59,338  ERROR       send_post.py  run_rtsp_gpu  frame_192.168.0.20 is not update
2023-06-06 10:54:04,344  ERROR       send_post.py  run_rtsp_gpu  frame_192.168.0.20 is not update
2023-06-06 10:54:09,351  ERROR       send_post.py  run_rtsp_gpu  frame_192.168.0.20 is not update
2023-06-06 10:54:14,354  ERROR       send_post.py  run_rtsp_gpu  frame_192.168.0.20 is not update
2023-06-09 18:48:21,968  ERROR       send_post.py  post_report  HTTPConnectionPool(host='localhost', port=8090): Max retries exceeded with url: /api/v1/result (Caused by NewConnectionError('<urllib3.connection.HTTPConnection object at 0x7f568fb742e0>: Failed to establish a new connection: [Errno 111] Connection refused'))
2023-06-09 18:49:36,859  ERROR       send_post.py  post_report  HTTPConnectionPool(host='localhost', port=8090): Max retries exceeded with url: /api/v1/result (Caused by NewConnectionError('<urllib3.connection.HTTPConnection object at 0x7f622d57a3d0>: Failed to establish a new connection: [Errno 111] Connection refused'))
2023-06-09 18:50:46,113  ERROR       send_post.py  post_report  HTTPConnectionPool(host='localhost', port=8090): Max retries exceeded with url: /api/v1/result (Caused by NewConnectionError('<urllib3.connection.HTTPConnection object at 0x7fef9633c3d0>: Failed to establish a new connection: [Errno 111] Connection refused'))
2023-06-12 15:13:41,360  ERROR       send_post.py  post_report  HTTPConnectionPool(host='localhost', port=8090): Max retries exceeded with url: /api/v1/result (Caused by NewConnectionError('<urllib3.connection.HTTPConnection object at 0x7fd500573190>: Failed to establish a new connection: [Errno 111] Connection refused'))
2023-06-12 15:13:41,386  ERROR       send_post.py  post_report  HTTPConnectionPool(host='localhost', port=8090): Max retries exceeded with url: /api/v1/result (Caused by NewConnectionError('<urllib3.connection.HTTPConnection object at 0x7fd500573bb0>: Failed to establish a new connection: [Errno 111] Connection refused'))
2023-06-12 15:13:41,415  ERROR       send_post.py  post_report  HTTPConnectionPool(host='localhost', port=8090): Max retries exceeded with url: /api/v1/result (Caused by NewConnectionError('<urllib3.connection.HTTPConnection object at 0x7fd500573100>: Failed to establish a new connection: [Errno 111] Connection refused'))
2023-06-12 15:13:41,442  ERROR       send_post.py  post_report  HTTPConnectionPool(host='localhost', port=8090): Max retries exceeded with url: /api/v1/result (Caused by NewConnectionError('<urllib3.connection.HTTPConnection object at 0x7fd5000f9610>: Failed to establish a new connection: [Errno 111] Connection refused'))
2023-06-12 15:13:41,468  ERROR       send_post.py  post_report  HTTPConnectionPool(host='localhost', port=8090): Max retries exceeded with url: /api/v1/result (Caused by NewConnectionError('<urllib3.connection.HTTPConnection object at 0x7fd5001040a0>: Failed to establish a new connection: [Errno 111] Connection refused'))
2023-06-12 15:13:41,495  ERROR       send_post.py  post_report  HTTPConnectionPool(host='localhost', port=8090): Max retries exceeded with url: /api/v1/result (Caused by NewConnectionError('<urllib3.connection.HTTPConnection object at 0x7fd500104a90>: Failed to establish a new connection: [Errno 111] Connection refused'))
2023-06-12 15:13:41,522  ERROR       send_post.py  post_report  HTTPConnectionPool(host='localhost', port=8090): Max retries exceeded with url: /api/v1/result (Caused by NewConnectionError('<urllib3.connection.HTTPConnection object at 0x7fd5000f91c0>: Failed to establish a new connection: [Errno 111] Connection refused'))
2023-06-12 15:13:41,549  ERROR       send_post.py  post_report  HTTPConnectionPool(host='localhost', port=8090): Max retries exceeded with url: /api/v1/result (Caused by NewConnectionError('<urllib3.connection.HTTPConnection object at 0x7fd50053ddf0>: Failed to establish a new connection: [Errno 111] Connection refused'))
2023-06-12 15:13:41,577  ERROR       send_post.py  post_report  HTTPConnectionPool(host='localhost', port=8090): Max retries exceeded with url: /api/v1/result (Caused by NewConnectionError('<urllib3.connection.HTTPConnection object at 0x7fd500573b20>: Failed to establish a new connection: [Errno 111] Connection refused'))
2023-06-12 15:13:41,616  ERROR       send_post.py  post_report  HTTPConnectionPool(host='localhost', port=8090): Max retries exceeded with url: /api/v1/result (Caused by NewConnectionError('<urllib3.connection.HTTPConnection object at 0x7fd500104c70>: Failed to establish a new connection: [Errno 111] Connection refused'))
2023-06-12 15:13:41,645  ERROR       send_post.py  post_report  HTTPConnectionPool(host='localhost', port=8090): Max retries exceeded with url: /api/v1/result (Caused by NewConnectionError('<urllib3.connection.HTTPConnection object at 0x7fd500573f40>: Failed to establish a new connection: [Errno 111] Connection refused'))
2023-06-12 15:13:41,672  ERROR       send_post.py  post_report  HTTPConnectionPool(host='localhost', port=8090): Max retries exceeded with url: /api/v1/result (Caused by NewConnectionError('<urllib3.connection.HTTPConnection object at 0x7fd5009638b0>: Failed to establish a new connection: [Errno 111] Connection refused'))
2023-06-12 15:13:41,699  ERROR       send_post.py  post_report  HTTPConnectionPool(host='localhost', port=8090): Max retries exceeded with url: /api/v1/result (Caused by NewConnectionError('<urllib3.connection.HTTPConnection object at 0x7fd5000f97f0>: Failed to establish a new connection: [Errno 111] Connection refused'))
2023-06-12 15:13:41,728  ERROR       send_post.py  post_report  HTTPConnectionPool(host='localhost', port=8090): Max retries exceeded with url: /api/v1/result (Caused by NewConnectionError('<urllib3.connection.HTTPConnection object at 0x7fd5001134c0>: Failed to establish a new connection: [Errno 111] Connection refused'))
2023-06-12 15:13:41,756  ERROR       send_post.py  post_report  HTTPConnectionPool(host='localhost', port=8090): Max retries exceeded with url: /api/v1/result (Caused by NewConnectionError('<urllib3.connection.HTTPConnection object at 0x7fd5000f96d0>: Failed to establish a new connection: [Errno 111] Connection refused'))
2023-06-12 15:14:57,917  ERROR       send_post.py  post_report  HTTPConnectionPool(host='localhost', port=8090): Max retries exceeded with url: /api/v1/result (Caused by NewConnectionError('<urllib3.connection.HTTPConnection object at 0x7f4111372190>: Failed to establish a new connection: [Errno 111] Connection refused'))
2023-06-12 15:14:57,944  ERROR       send_post.py  post_report  HTTPConnectionPool(host='localhost', port=8090): Max retries exceeded with url: /api/v1/result (Caused by NewConnectionError('<urllib3.connection.HTTPConnection object at 0x7f4111372bb0>: Failed to establish a new connection: [Errno 111] Connection refused'))
2023-06-12 15:14:57,971  ERROR       send_post.py  post_report  HTTPConnectionPool(host='localhost', port=8090): Max retries exceeded with url: /api/v1/result (Caused by NewConnectionError('<urllib3.connection.HTTPConnection object at 0x7f4111372100>: Failed to establish a new connection: [Errno 111] Connection refused'))
2023-06-12 15:14:57,999  ERROR       send_post.py  post_report  HTTPConnectionPool(host='localhost', port=8090): Max retries exceeded with url: /api/v1/result (Caused by NewConnectionError('<urllib3.connection.HTTPConnection object at 0x7f4110efa610>: Failed to establish a new connection: [Errno 111] Connection refused'))
2023-06-12 15:14:58,026  ERROR       send_post.py  post_report  HTTPConnectionPool(host='localhost', port=8090): Max retries exceeded with url: /api/v1/result (Caused by NewConnectionError('<urllib3.connection.HTTPConnection object at 0x7f4110f040a0>: Failed to establish a new connection: [Errno 111] Connection refused'))
2023-06-12 15:14:58,053  ERROR       send_post.py  post_report  HTTPConnectionPool(host='localhost', port=8090): Max retries exceeded with url: /api/v1/result (Caused by NewConnectionError('<urllib3.connection.HTTPConnection object at 0x7f4110f04a90>: Failed to establish a new connection: [Errno 111] Connection refused'))
2023-06-12 15:14:58,080  ERROR       send_post.py  post_report  HTTPConnectionPool(host='localhost', port=8090): Max retries exceeded with url: /api/v1/result (Caused by NewConnectionError('<urllib3.connection.HTTPConnection object at 0x7f4110efa3d0>: Failed to establish a new connection: [Errno 111] Connection refused'))
2023-06-12 15:14:58,110  ERROR       send_post.py  post_report  HTTPConnectionPool(host='localhost', port=8090): Max retries exceeded with url: /api/v1/result (Caused by NewConnectionError('<urllib3.connection.HTTPConnection object at 0x7f411133c610>: Failed to establish a new connection: [Errno 111] Connection refused'))
2023-06-12 15:14:58,136  ERROR       send_post.py  post_report  HTTPConnectionPool(host='localhost', port=8090): Max retries exceeded with url: /api/v1/result (Caused by NewConnectionError('<urllib3.connection.HTTPConnection object at 0x7f4111372b20>: Failed to establish a new connection: [Errno 111] Connection refused'))
2023-06-12 15:14:58,163  ERROR       send_post.py  post_report  HTTPConnectionPool(host='localhost', port=8090): Max retries exceeded with url: /api/v1/result (Caused by NewConnectionError('<urllib3.connection.HTTPConnection object at 0x7f4110f04c70>: Failed to establish a new connection: [Errno 111] Connection refused'))
2023-06-12 15:14:58,190  ERROR       send_post.py  post_report  HTTPConnectionPool(host='localhost', port=8090): Max retries exceeded with url: /api/v1/result (Caused by NewConnectionError('<urllib3.connection.HTTPConnection object at 0x7f4111372f40>: Failed to establish a new connection: [Errno 111] Connection refused'))
2023-06-12 15:14:58,220  ERROR       send_post.py  post_report  HTTPConnectionPool(host='localhost', port=8090): Max retries exceeded with url: /api/v1/result (Caused by NewConnectionError('<urllib3.connection.HTTPConnection object at 0x7f41117638b0>: Failed to establish a new connection: [Errno 111] Connection refused'))
2023-06-12 15:15:45,673  ERROR       send_post.py  post_report  HTTPConnectionPool(host='localhost', port=8090): Max retries exceeded with url: /api/v1/result (Caused by NewConnectionError('<urllib3.connection.HTTPConnection object at 0x7f2591972190>: Failed to establish a new connection: [Errno 111] Connection refused'))
2023-06-12 15:15:45,701  ERROR       send_post.py  post_report  HTTPConnectionPool(host='localhost', port=8090): Max retries exceeded with url: /api/v1/result (Caused by NewConnectionError('<urllib3.connection.HTTPConnection object at 0x7f2591972bb0>: Failed to establish a new connection: [Errno 111] Connection refused'))
2023-06-12 15:15:45,735  ERROR       send_post.py  post_report  HTTPConnectionPool(host='localhost', port=8090): Max retries exceeded with url: /api/v1/result (Caused by NewConnectionError('<urllib3.connection.HTTPConnection object at 0x7f2591972100>: Failed to establish a new connection: [Errno 111] Connection refused'))
2023-06-12 15:15:45,770  ERROR       send_post.py  post_report  HTTPConnectionPool(host='localhost', port=8090): Max retries exceeded with url: /api/v1/result (Caused by NewConnectionError('<urllib3.connection.HTTPConnection object at 0x7f25914fa610>: Failed to establish a new connection: [Errno 111] Connection refused'))
2023-06-12 15:15:45,802  ERROR       send_post.py  post_report  HTTPConnectionPool(host='localhost', port=8090): Max retries exceeded with url: /api/v1/result (Caused by NewConnectionError('<urllib3.connection.HTTPConnection object at 0x7f259150a0a0>: Failed to establish a new connection: [Errno 111] Connection refused'))
2023-06-12 15:15:45,835  ERROR       send_post.py  post_report  HTTPConnectionPool(host='localhost', port=8090): Max retries exceeded with url: /api/v1/result (Caused by NewConnectionError('<urllib3.connection.HTTPConnection object at 0x7f259150aa90>: Failed to establish a new connection: [Errno 111] Connection refused'))
2023-06-12 15:15:45,868  ERROR       send_post.py  post_report  HTTPConnectionPool(host='localhost', port=8090): Max retries exceeded with url: /api/v1/result (Caused by NewConnectionError('<urllib3.connection.HTTPConnection object at 0x7f25914fa400>: Failed to establish a new connection: [Errno 111] Connection refused'))
2023-06-12 15:15:45,897  ERROR       send_post.py  post_report  HTTPConnectionPool(host='localhost', port=8090): Max retries exceeded with url: /api/v1/result (Caused by NewConnectionError('<urllib3.connection.HTTPConnection object at 0x7f259193d610>: Failed to establish a new connection: [Errno 111] Connection refused'))
2023-06-12 15:15:45,931  ERROR       send_post.py  post_report  HTTPConnectionPool(host='localhost', port=8090): Max retries exceeded with url: /api/v1/result (Caused by NewConnectionError('<urllib3.connection.HTTPConnection object at 0x7f2591972b20>: Failed to establish a new connection: [Errno 111] Connection refused'))
2023-06-12 15:15:45,967  ERROR       send_post.py  post_report  HTTPConnectionPool(host='localhost', port=8090): Max retries exceeded with url: /api/v1/result (Caused by NewConnectionError('<urllib3.connection.HTTPConnection object at 0x7f259150ac70>: Failed to establish a new connection: [Errno 111] Connection refused'))
2023-06-12 15:15:46,002  ERROR       send_post.py  post_report  HTTPConnectionPool(host='localhost', port=8090): Max retries exceeded with url: /api/v1/result (Caused by NewConnectionError('<urllib3.connection.HTTPConnection object at 0x7f2591972f40>: Failed to establish a new connection: [Errno 111] Connection refused'))
2023-06-12 15:15:46,056  ERROR       send_post.py  post_report  HTTPConnectionPool(host='localhost', port=8090): Max retries exceeded with url: /api/v1/result (Caused by NewConnectionError('<urllib3.connection.HTTPConnection object at 0x7f2591d64b20>: Failed to establish a new connection: [Errno 111] Connection refused'))
2023-06-12 15:15:46,084  ERROR       send_post.py  post_report  HTTPConnectionPool(host='localhost', port=8090): Max retries exceeded with url: /api/v1/result (Caused by NewConnectionError('<urllib3.connection.HTTPConnection object at 0x7f25914fa7f0>: Failed to establish a new connection: [Errno 111] Connection refused'))
2023-06-12 15:15:46,114  ERROR       send_post.py  post_report  HTTPConnectionPool(host='localhost', port=8090): Max retries exceeded with url: /api/v1/result (Caused by NewConnectionError('<urllib3.connection.HTTPConnection object at 0x7f25915124c0>: Failed to establish a new connection: [Errno 111] Connection refused'))
2023-06-12 15:16:24,785  ERROR       send_post.py  post_report  HTTPConnectionPool(host='localhost', port=8090): Max retries exceeded with url: /api/v1/result (Caused by NewConnectionError('<urllib3.connection.HTTPConnection object at 0x7f7143d72190>: Failed to establish a new connection: [Errno 111] Connection refused'))
2023-06-12 15:16:24,813  ERROR       send_post.py  post_report  HTTPConnectionPool(host='localhost', port=8090): Max retries exceeded with url: /api/v1/result (Caused by NewConnectionError('<urllib3.connection.HTTPConnection object at 0x7f7143d72bb0>: Failed to establish a new connection: [Errno 111] Connection refused'))
2023-06-12 15:16:24,850  ERROR       send_post.py  post_report  HTTPConnectionPool(host='localhost', port=8090): Max retries exceeded with url: /api/v1/result (Caused by NewConnectionError('<urllib3.connection.HTTPConnection object at 0x7f7143d72100>: Failed to establish a new connection: [Errno 111] Connection refused'))
2023-06-12 15:16:24,886  ERROR       send_post.py  post_report  HTTPConnectionPool(host='localhost', port=8090): Max retries exceeded with url: /api/v1/result (Caused by NewConnectionError('<urllib3.connection.HTTPConnection object at 0x7f71438f9610>: Failed to establish a new connection: [Errno 111] Connection refused'))
2023-06-12 15:16:24,913  ERROR       send_post.py  post_report  HTTPConnectionPool(host='localhost', port=8090): Max retries exceeded with url: /api/v1/result (Caused by NewConnectionError('<urllib3.connection.HTTPConnection object at 0x7f71439040a0>: Failed to establish a new connection: [Errno 111] Connection refused'))
2023-06-12 15:16:24,940  ERROR       send_post.py  post_report  HTTPConnectionPool(host='localhost', port=8090): Max retries exceeded with url: /api/v1/result (Caused by NewConnectionError('<urllib3.connection.HTTPConnection object at 0x7f7143904a90>: Failed to establish a new connection: [Errno 111] Connection refused'))
2023-06-12 15:16:24,976  ERROR       send_post.py  post_report  HTTPConnectionPool(host='localhost', port=8090): Max retries exceeded with url: /api/v1/result (Caused by NewConnectionError('<urllib3.connection.HTTPConnection object at 0x7f71438f9400>: Failed to establish a new connection: [Errno 111] Connection refused'))
